Workbook
Name 과10: 과태료!$A$6
Name 과107: 과태료!$A$168
Name 과108: 과태료!$A$170
Name 과109: 과태료!$A$174
Name 과110: 과태료!$A$177
Name 과111: 과태료!$A$185
Name 과112: 과태료!$A$200
Name 과113: 과태료!$A$210
Name 과114: 과태료!$A$214
Name 과115: 과태료!$A$220
Name 과119: 과태료!$A$235
Name 과122: 과태료!$A$241
Name 과123: 과태료!$A$245
Name 과124: 과태료!$A$247
Name 과125: 과태료!$A$253
Name 과128: 과태료!$A$265
Name 과129: 과태료!$A$269
Name 과132: 과태료!$A$271
Name 과133: 과태료!$A$279
Name 과134: 과태료!$A$281
Name 과137: 과태료!$A$285
Name 과14: 과태료!$A$8
Name 과141: 과태료!$A$287
Name 과145: 과태료!$A$291
Name 과149: 과태료!$A$293
Name 과15: 과태료!$A$10
Name 과155: 과태료!$A$295
Name 과156: 과태료!$A$301
Name 과16: 과태료!$A$13
Name 과164: 과태료!$A$303
Name 과17: 과태료!$A$16
Name 과18: 과태료!$A$17
Name 과19: 과태료!$A$18
Name 과22: 과태료!$A$27
Name 과24: 과태료!$A$29
Name 과25: 과태료!$A$35
Name 과26: 과태료!$A$37
Name 과29: 과태료!$A$41
Name 과31: 과태료!$A$47
Name 과32: 과태료!$A$49
Name 과34: 과태료!$A$55
Name 과35: 과태료!$A$57
Name 과37: 과태료!$A$59
Name 과40: 과태료!$A$61
Name 과41: 과태료!$A$63
Name 과42: 과태료!$A$65
Name 과43: 과태료!$A$75
Name 과44: 과태료!$A$77
Name 과45: 과태료!$A$81
Name 과46: 과태료!$A$83
Name 과47: 과태료!$A$87
Name 과49: 과태료!$A$93
Name 과50: 과태료!$A$98
Name 과53: 과태료!$A$100
Name 과54: 과태료!$A$102
Name 과57: 과태료!$A$104
Name 과62: 과태료!$A$106
Name 과64: 과태료!$A$108
Name 과66: 과태료!$A$110
Name 과67: 과태료!$A$114

Sheet 직무목록
A1: 각종 안전활동의 법적 근거 | G1: 작성자 : | H1: 추연희 : 010-8618-8682 | J1: 시트이름변경 제어
G2: ******yh | H2: y2k365c@naver.com | J2: ※ 시트이름을 변경하면 일부 기능에 오류 발생
A3: 산업안전보건법 | C3: 법 위반시 과태료 | D3: 산업안전보건기준에 관한 규칙 | G3: 최초작성일 : 2022-8-16
A4: 구 분 | C4: 법 적 근 거 바로가기 | D4: 비 고
C5: 산업안전보건법, 건설기술진흥법 등
A6: 구성원의 의무 | B6: 사업주의 의무 | C6: =법5 -> 제5조(사업주 등의 의무)
B7: 근로자의 의무 | C7: =법6 -> 제6조(근로자의 의무)
A8: 관리자의선임 | B8: 안전보건관리책임자 | C8: =법15 -> 제15조(안전보건관리책임자)
B9: 관리감독자 | C9: =법16 -> 제16조(관리감독자)
B10: 안전관리자 | C10: =법17 -> 제17조(안전관리자)
B11: 보건관리자 | C11: =법18 -> 제18조(보건관리자)
B12: 안전보건관리담당자 | C12: =법19 -> 제19조(안전보건관리담당자) | D12: 안전관리자 선임 의무가 없는 현장의 안전관리 업무 수행자
B13: 산업보건의 | C13: =법22 -> 제22조(산업보건의) | D13: 보건관리자 선임시 해당 없음, 선임조건 보건관리자와 동일
B14: 명예산업안전감독관 | C14: =법23 -> 제23조(명예산업안전감독관)
A15: 조직의 구성 | B15: =노사협의체!B3 -> 산업안전보건위원회 | C15: =법24 -> 제24조(산업안전보건위원회) | D15: 요약 도표 바로가기
B16: =노사협의체!C3 -> 노사협의회 | C16: =노사협의체!AR10 -> 제4조(노사협의회의 설치) | D16: =노사협의체!AR9 -> 근로자참여 및 협력증진에 관한 법률
B17: =노사협의체!D3 -> 노사협의체 | C17: 제75조(안전 및 보건에 관한 협의체)
B18: =노사협의체!E3 -> 안전보건협의체 | C18: =법64 -> 제64조(도급에 따른 산업재해 예방조치)
A19: 규정 및 계획서 | B19: 안전보건관리규정 | C19: =법25 -> 제25조(안전보건관리규정의 작성) | D19: 본사작성
B20: 유해위험방지계획서 | C20: =법42 -> 제42조(유해위험방지계획서의 작성ㆍ제출 등) | D20: 지도.조언
B21: 공정안전보고서 | C21: =법44 -> 제44조(공정안전보고서의 작성ㆍ제출)
B22: 안전보건개선계획 | C22: =법49 -> 제49조(안전보건개선계획의 수립ㆍ시행 명령)
B23: 안전관리계획서 | C23: =안전관리계획!B10 -> 제62조(건설공사의 안전관리) | D23: 건설기술진흥법 : 지도.조언
A24: 안전점검 (외부기관) | B24: 자체안전점검 | C24: =안전점검!B47 -> 제22조(자체안전점검의 실시) | D24: 건설기술진흥법 : 외부기관
B25: 정기안전점검 | C25: =안전점검!B56 -> 제23조(정기안전점검의 실시) | D25: 건설기술진흥법 : 외부기관
B26: 정밀안전점검 | C26: =안전점검!B75 -> 제24조(정밀안전점검의 실시) | D26: 건설기술진흥법 : 외부기관
B27: 초기안전점검 | C27: =안전점검!B90 -> 제25조(초기점검의 실시) | D27: 건설기술진흥법 : 외부기관
A28: 안전교육 | B28: 정기교육 | C28: =법29 -> 제29조(근로자에 대한 안전보건교육)
B29: 특별교육 | C29: =법26 -> 제26조(안전보건관리규정의 작성ㆍ변경 절차)
B30: 신규채용자교육 | C30: =법26 -> 제26조(안전보건관리규정의 작성ㆍ변경 절차)
B31: 건설업기초 | C31: =법26 -> 제26조(안전보건관리규정의 작성ㆍ변경 절차)
A32: 근로환경 | B32: 위험성평가 | C32: =법36 -> 제36조(위험성평가의 실시) | D32: 최초평가, 정기평가, 수시평가
B33: 석면조사 | C33: =법119 -> 제119조(석면조사) | D33: 외부기관
B34: 작업환경측정 | C34: =법125 -> 제125조(작업환경측정) | D34: 외부기관
A35: 건강진단 | B35: 일반건강진단 | C35: =법129 -> 제129조(일반건강진단) | D35: 외부기관
B36: 특수건강진단 | C36: =법130 -> 제130조(특수건강진단 등) | D36: 외부기관
B37: 임시건강진단 | C37: =법131 -> 제131조(임시건강진단 명령 등) | D37: 외부기관
B38: 역학조사 | C38: =법141 -> 제141조(역학조사) | D38: 외부기관
A39: 계획서 점검표 | B39: 작업장 순회점검 | C39: =규칙80 -> 제80조(도급사업 시의 안전ㆍ보건조치 등)
B40: 합동점검 | C40: =규칙82 -> 제82조(도급사업의 합동 안전ㆍ보건점검)
...

Sheet 법령순서
A1: 산업안전보건법 목차
K2: Click Me~!
A3: 메인화면 | E3: 산업안전보건기준에 관한 규칙 목차
A4: 구 분 | B4: 바로가기 | E4: 본 문 목 록 | F4: 과태료 | G4: 주체 | H4: 건설업 해당 주요내용 | I4: 비고
B5: 제1장 총칙
A6: 총 칙 | D6: 제1조 | E6: 목적 | K6: ▼아래로
D7: 제2조 | E7: 정의
D8: 제3조 | E8: 적용 범위
A9: 의무.책무 | D9: 제4조 | E9: 정부의 책무
D10: 의2 | E10: 지방자치단체의 책무
D11: 의3 | E11: 지방자치단체의 산업재해 예방 활동 등
D12: 제5조 | E12: 사업주 등의 의무
D13: 제6조 | E13: 근로자의 의무
A14: 산재예방 | D14: 제7조 | E14: 산업재해 예방에 관한 기본계획의 수립ㆍ공표
D15: 제8조 | E15: 협조 요청 등
D16: 제9조 | E16: 산업재해 예방 통합정보시스템 구축ㆍ운영 등
D17: 제10조 | E17: 산업재해 발생건수 등의 공표 | F17: ● | G17: 고용노동부장관 | H17: 관리 대상 사업장 | I17: 장관 자료요청, 사업주 자료제공
D18: 제11조 | E18: 산업재해 예방시설의 설치ㆍ운영
D19: 제12조 | E19: 산업재해 예방의 재원
D20: 제13조 | E20: 기술 또는 작업환경에 관한 표준
B21: 제2장 안전보건관리체제 등
C22: 제1절 안전보건관리체제
A23: 조직 및 선임 | D23: 제14조 | E23: 이사회 보고 및 승인 등 | F23: ● | G23: 상법상 모든 회사 | H23: 시공능력 1000위 이내
D24: 제15조 | E24: 안전보건관리책임자 | F24: ● | G24: 현장대리인 | H24: 직무내용
D25: 제16조 | E25: 관리감독자 | F25: ● | G25: 공사담당자 | H25: 직무내용
D26: 제17조 | E26: 안전관리자 | F26: ● | G26: 배치기준 | H26: 직무내용 | I26: 겸직범위
D27: 제18조 | E27: 보건관리자 | F27: ● | G27: 배치기준 | H27: 직무내용
D28: 제19조 | E28: 안전보건관리담당자 | F28: ● | G28: 공사담당자 | H28: 직무내용
D29: 제20조 | E29: 안전관리자 등의 지도ㆍ조언
D30: 제21조 | E30: 안전관리전문기관 등 | K30: ▼아래로
D31: 제22조 | E31: 산업보건의 | F31: ● | G31: 배치기준 | H31: 직무내용
D32: 제23조 | E32: 명예산업안전감독관 | G32: 위촉기준(자격) | H32: 직무내용 | K32: ▲위로
D33: 제24조 | E33: 산업안전보건위원회 | F33: ● | G33: 구성 및 운영 | H33: 120억(토150억)이상 | I33: 분기마다 회의 실시
C34: 제2절 안전보건관리규정
A35: 안전보건 관리규정 | D35: 제25조 | E35: 조 안전보건관리규정의 작성 | F35: ● | G35: 사업주,현장대리인 | H35: 구성 및 운영
D36: 제26조 | E36: 조 안전보건관리규정의 작성ㆍ변경 절차 | F36: ● | G36: 사업주,현장대리인
D37: 제27조 | E37: 조 안전보건관리규정의 준수
D38: 제28조 | E38: 조 다른 법률의 준용
B39: 제3장 안전보건교육
A40: 안전교육 | D40: 제29조 | E40: 근로자에 대한 안전보건교육 | F40: ● | G40: 현장대리인 | H40: 정기,신규,특별,변경 | I40: 규칙 별표 5 참조
...

Sheet 산업안전보건법
A1: 산업안전보건법 | V1: 산업안전보건법 시행령 | AQ1: 산업안전보건법 시행규칙
A3: 법령순서 | G3: 1장 | J3: 2장 | K3: 3장 | L3: 4장 | M3: 5장 | N3: 6장 | O3: 7장 | P3: 8장 | Q3: 9장 | R3: 10장 | S3: 11장 | T3: 12장 | W3: 메인화면 | AN3: 과태료 | AX3: 산업안전보건기준에 관한 규칙
A4: 제1장 총칙 | V4: 제1장 총칙 | AQ4: 제1장 총칙
C6: 제1조(목적) | W6: 제1조(목적) | AR6: 제1조(목적)
D7: ○ 산업 안전 및 보건에 관한 기준 확립과 명확한 책임 소재 규정 | X7: ○ 이 영은 법에서 위임된 사항과 그 시행에 필요한 사항을 규정함을 목적으로 한다. | AS7: ○ 이 규칙은 법 및 시행령에서 위임된 사항과 그 시행에 필요한 사항을 규정함을 목적으로 한다.
D8: ○ 산업재해 예방 및 쾌적한 작업환경을 조성
D9: ○ 노무를 제공하는 사람의 안전 및 보건을 유지ㆍ증진
C11: 제2조(정의) | AR11: 제2조(정의)
D12: ○ 용어의 정의 | AS12: ○ 이 규칙에서 사용하는 용어의 뜻은 이 규칙에 특별한 규정이 없으면 법, 시행령 및 「산업안전
E13: 1. 산업재해 : 노무를 제공하는 사람이 업무에 관계되는 건설물ㆍ설비ㆍ원재료ㆍ가스ㆍ | AT13: 보건기준에 관한 규칙」(이하 “안전보건규칙”이라 한다)에서 정하는 바에 따른다.
F14: 증기ㆍ분진 등에 의하거나 작업 또는 그 밖의 업무로 인하여 사망,부상,질병에 걸리는 것
E15: 2. 중대재해 : 산업재해 중 사망 등 재해 정도가 심하거나 다수의 재해자가 발생한 경우로서 | AR15: 제3조(중대재해의 범위)
F16: 고용노동부령(3)으로 정하는 재해 | AS16: ○ 법 제2조제2호에서 “고용노동부령으로 정하는 재해”란 다음 각 호의 하나에 해당하는 재해
E17: 3. 근로자 : 「근로기준법」 제2조제1항제1호에 따른 근로자 | V17: ■ 근로기준법 | AT17: 1. 사망자가 1명 이상 발생한 재해
E18: 4. 사업주 : 근로자를 사용하여 사업을 하는 자 | W18: 제2조(정의) | AT18: 2. 3개월 이상의 요양이 필요한 부상자가 동시에 2명 이상 발생한 재해
E19: 5. 근로자대표 : 근로자의 과반수로 조직된 노동조합이 있는 경우에는 그 노동조합을, 근로자의 | X19: ① 이 법에서 사용하는 용어의 뜻은 다음과 같다. | AT19: 3. 부상자 또는 직업성 질병자가 동시에 10명 이상 발생한 재해 | BH19: 중대재해의 정의
F20: 과반수로 조직된 노동조합이 없는 경우에는 근로자의 과반수를 대표하는 자 | Y20: 1. “근로자”란 직업의 종류와 관계없이 임금을 목적으로 사업이나 사업장에 근로를 제공하는
E21: 6. 도급 : 명칭에 관계없이 물건의 제조ㆍ건설ㆍ수리 또는 서비스의 제공, 그 밖의 업무를 타인 | Z21: 사람을 말한다.
F22: 에게 맡기는 계약
E23: 7. 도급인 : 물건의 제조ㆍ건설ㆍ수리 또는 서비스의 제공, 그 밖의 업무를 도급하는 사업주 | W23: ※ 도급, 수급, 관계수급, 발주자 정리 | AI23: 도급인, 발주자, 수급인, 관계수급인 정리
F24: (건설공사발주자는 제외 제조업,서비스업 분야의 발주자) | X24: ○ 도급인 : 물건의 제조,수리 또는 서비스 사업을 하는 대표
E25: 8. 수급인 : 도급인으로부터 물건의 제조ㆍ건설ㆍ수리 또는 서비스의 제공, 그 밖의 업무를 | X25: ○ 건설공사발주자 : 건설부지와 자금을 조달하는 건축주(발주자)
F26: 도급받은 사업주 | K26: (도급인,건설공사발주자,건축주 로부터 도급받은 자 = 원도급자) | Y26: ▶ 건설분야는 발주자, 제조.서비스 분야는 도급인?
E27: 9. 관계수급인 : 도급이 여러 단계에 걸쳐 체결된 경우에 각 단계별로 도급받은 사업주 전부 | X27: ○ 수급인 : 발주자(도급인)이 기획한 사업을 도급받아 시공(제조)을 주도하는 종합건설사 대표
F28: (수급인으로부터 도급받은 전문분야의 시공을 주도하는 자 = 하도급업자) | X28: ○ 관계수급인 : 수급인으로부터 하도급계약을 체결한 전문건설사 대표
E29: 10. 건설공사발주자 : 건설공사를 도급하는 자로서 건설공사의 시공을 주도하여 총괄ㆍ관리 | Y29: ▶ 각 단계별로 도급받은 사업주 전부 : 수급인을 포함?
F30: 하지 아니하는 자(도급하는자, 건축주). 다만, 도급받은 건설공사를 다시 도급하는 자
F31: (수급인)는 제외
E32: 11. 건설공사 : 다음 각 목의 어느 하나에 해당하는 공사
F33: 가. 「건설산업기본법」 제2조제4호에 따른 건설공사 | Q33: 건설공사의 범위 | V33: ■ 건설산업기본법
F34: 나. 「전기공사업법」 제2조제1호에 따른 전기공사 | W34: 제2조(정의)
F35: 다. 「정보통신공사업법」 제2조제2호에 따른 정보통신공사 | X35: 4. “건설공사”란 토목공사, 건축공사, 산업설비공사, 조경공사, 환경시설공사, 그 밖에 명칭과 관계
F36: 라. 「소방시설공사업법」에 따른 소방시설공사 | Y36: 없이 시설물을 설치ㆍ유지ㆍ보수하는공사(시설물을 설치하기 위한 부지조성공사를 포함한다) 및
F37: 마. 「문화재수리 등에 관한 법률」에 따른 문화재수리공사 | Y37: 기계설비나 그 밖의 구조물의 설치 및 해체공사 등을 말한다. 다만, 다음 각 목의 어느 하나에
E38: 12. 안전보건진단 : 산업재해를 예방하기 위하여 잠재적 위험성을 발견하고 그 개선대책을 | Y38: 해당하는 공사는 포함하지 아니한다.
F39: 수립할 목적으로 조사ㆍ평가하는 것
E40: 13. 작업환경측정 : 작업환경 실태를 파악하기 위하여 해당 근로자 또는 작업장에 대하여 사업
F41: 주가 유해인자에 대한 측정계획을 수립한 후 시료를 채취하고 분석ㆍ평가하는 것
C43: 제3조(적용 범위)
D44: ○ 이 법은 모든 사업에 적용한다. 다만 유해ㆍ위험의 정도, 사업의 종류, 사업장의 상시근로자 | W44: 제2조(적용범위 등)
...

Sheet 과태료
A1: 「산업안전보건법」위반 시 주요 과태료 부과 기준 | M1: 메인화면
J2: Click Me~! | N2: 별표26 행정처분까지 정리하여 파일 완성
A3: 「산업안전보건법 시행령 별표35」 | H3: [5년간 누적관리] | J3: 필독~! | M3: 산업안전보건기준
A4: 위 반 내 용 | C4: 법 조 문 (법 제175조) | D4: 세 부 내 용 | F4: 과 태 료(만원)
F5: 1차위반 | G5: 2차위반 | H5: 3차이상
A6: 1 | B6: 제10조(산업재해 발생건수 등의 공표) | C6: 제4항제1호 | D6: 1) | E6: 고용노동부장관이 제출 요청한 관계수급인에 관한 자료를 | F6: 1000 | G6: 1000 | H6: 1000
B7: 제3항 (자료 제출 의무) 위반 | E7: 정당한 사유없이 제출하지 않거나 거짓 제출 한 경우
A8: 2 | B8: 제14조(이사회 보고 및 승인 등) | C8: 제4항제2호 | D8: 1) | E8: 안전 및 보건에 관한 계획을 이사회에 보고하지 않거나 | F8: 1000 | G8: 1000 | H8: 1000
B9: 제1항 (안전,보건계획의 보고/승인 의무) 위반 | E9: 승인을 받지 않은 경우
A10: 3 | B10: 제15조(안전보건관리책임자) | D10: 1) | E10: 안전보건관리자를 선임하지 않은 경우 | F10: 500 | G10: 500 | H10: 500
B11: 제1항 (관리책임자에게 총괄 업무 지원) 위반 | C11: 제5항제1호 | D11: 2) | E11: 안전보건관리책임자로 하여금 업무를 총괄하여 관리하도록 | F11: 300 | G11: 400 | H11: 500
E12: 하지 않은 경우
A13: 4 | B13: 제16조(관리감독자) | D13: 1) | E13: 관리감독자로 하여금 산업 안전 및 보건에 관한 업무를
B14: 제1항 (관리감독자에게 안전.보건 업무 지원)위반 | C14: 제5항제1호 | E14: 수행하도록 하지 않은 경우 | F14: 300 | G14: 400 | H14: 500
E15: ※ 선임 규정은 없음-지휘계통의 1인을 임의 지정
A16: 5 | B16: 제17조(안전관리자) | D16: 1) | E16: 안전관리자를 선임하지 않은 경우
B17: 제18조(보건관리자) | D17: 2) | E17: 보건관리자를 선임하지 않은 경우 | F17: 500 | G17: 500 | H17: 500
B18: 제19조(안전보건관리담당자) | D18: 3) | E18: 안전보건관리담당자를 선임하지 않은 경우
B19: (관리자,담당자 지정 의무)위반 | C19: 제5항제1호 | D19: 4) | E19: 선임된 안전관리자로 하여금 안전관리자의
B20: (관리자,담당자의 업무 지원)위반 | D20: 5) | E20: 선임된 보건관리자로 하여금 보건관리자의 | F20: 300 | G20: 400 | H20: 500
D21: 6) | E21: 선임된 안전보건관리담당자로 하여금 언전보건관리담당자의
E22: 업무를 수행하도록 하지 않은 경우
A23: 6 | B23: 제17조제3항, 제18조제3항 | C23: 제4항제1호 | D23: 1) | E23: 안전(보건)관리자에게 담당업무만을 전담하도록 하지 | F23: 200 | G23: 300 | H23: 500
B24: (해당 업무만 전담) 위반 | E24: 않은 경우
A25: 7 | B25: 제17조제4항, 제18조제4항, 제19조제3항 | C25: 제4항제2호 | D25: 1) | E25: 안전(보건)관리자의 증원 명령 미이행시 | F25: 500 | G25: 500 | H25: 500
B26: (관계자의 교체,증원 명령)불이행 | D26: 2) | E26: 안전(보견)관리자의 교체 명령 미이행시
A27: =MAX($A$6:A26)+1 -> 8 | B27: 제22조(산업보건의) | C27: 제4항제1호 | D27: 1) | E27: 산업보건의를 선임하지 않은 경우 | F27: 300 | G27: 400 | H27: 500
B28: 제1항(산업보건의 선임 의무) 위반
A29: =MAX($A$6:A28)+1 -> 9 | B29: 제24조(산업안전보건위원회) | D29: 1) | E29: 산업안전보건위원회를 구성하지 않은 경우 | F29: 500 | G29: 500 | H29: 500
B30: 제1항(위원회의 구성.운영 의무)위반 | C30: 제5항제1호 | E30: (노사협의체를 구성한 경우는 제외)
D31: 2) | E31: 제37조를 위반하여 산업안전보건위원회(노사협의체 포함) | F31: 50 | G31: 250 | H31: 500
E32: 의 정기회의를 개최하지 않은 경우(1회당)
A33: =MAX($A$6:A32)+1 -> 10 | B33: 제4항(위원회가 심의.의결사항 성실이행) 위반 | C33: 제5항제1호 | D33: 1) | E33: 사업주가 성실하게 이행하지 않은 경우 | F33: 50 | G33: 250 | H33: 500
D34: 2) | E34: 근로자가 성살하게 이행하지 않은 경우 | F34: 10 | G34: 20 | H34: 30
B35: 제25조(안전보건관리규정의 작성) | C35: 제5항제1호 | D35: 1) | E35: 안전보건관리 규정을 작성하지 않은 경우 | F35: 150 | G35: 300 | H35: 500
B36: 제1항(규정 작성 의무)위반
A37: =MAX($A$6:A36)+1 -> 11 | B37: 제26조(안전보건관리규정의 작성ㆍ변경 절차) | D37: 1) | E37: 안전보건관리규정의 작성(변경)할 때 산업안전보건위원회의
B38: (작성ㆍ변경시 심의ㆍ의결 또는 근로자 대표 | C38: 제5항제2호 | E38: 심의ㆍ의결을 거치지 아니한 경우 | F38: 50 | G38: 250 | H38: 500
B39: 동의) 절차 위반 | D39: 2) | E39: 산업안전보건위원회가 구성되지 않은 경우 근로자 대표의
E40: 동의를 받지 않은 경우
...

Sheet 보건기준
A1: 산업안전보건기준에 관한 규칙 | L1: 메인화면 | M1: 산안법 | N1: 과태료
A3: 편장절관 | G3: 바로가기 | H3: 제 목 | J3: 비 고
A4: 제1편 총칙
B5: 제1장 통칙
F6: 제1조 목적 | G6: 제1조 | H6: 목적
F7: 제2조 정의 | G7: 제2조 | H7: 정의
B8: 제2장 작업장
F9: 제3조 전도의 방지 | G9: 제3조 | H9: 전도의 방지
F10: 제4조 작업장의 청결 | G10: 제4조 | H10: 작업장의 청결
F11: 제4조의2 분진의 흩날림 방지 | G11: 제4조 | H11: 의2 분진의 흩날림 방지
F12: 제5조 오염된 바닥의 세척 등 | G12: 제5조 | H12: 오염된 바닥의 세척 등
F13: 제6조 오물의 처리 등 | G13: 제6조 | H13: 오물의 처리 등
F14: 제7조 채광 및 조명 | G14: 제7조 | H14: 채광 및 조명
F15: 제8조 조도 | G15: 제8조 | H15: 조도
F16: 제9조 작업발판 등 | G16: 제9조 | H16: 작업발판 등
F17: 제10조 작업장의 창문 | G17: 제10조 | H17: 작업장의 창문
F18: 제11조 작업장의 출입구 | G18: 제11조 | H18: 작업장의 출입구
F19: 제12조 동력으로 작동되는 문의 설치 조건 | G19: 제12조 | H19: 동력으로 작동되는 문의 설치 조건
F20: 제13조 안전난간의 구조 및 설치요건 | G20: 제13조 | H20: 안전난간의 구조 및 설치요건
F21: 제14조 낙하물에 의한 위험의 방지 | G21: 제14조 | H21: 낙하물에 의한 위험의 방지
F22: 제15조 투하설비 등 | G22: 제15조 | H22: 투하설비 등 | L22: 작업계획서의 법적 근거
F23: 제16조 위험물 등의 보관 | G23: 제16조 | H23: 위험물 등의 보관
F24: 제17조 비상구의 설치 | G24: 제17조 | H24: 비상구의 설치
F25: 제18조 비상구 등의 유지 | G25: 제18조 | H25: 비상구 등의 유지 | L25: 양중기,양화장치는 화물이 적재된 상태를 운전 중으로 본다.
F26: 제19조 경보용 설비 등 | G26: 제19조 | H26: 경보용 설비 등
F27: 제20조 출입의 금지 등 | G27: 제20조 | H27: 출입의 금지 등
B28: 제3장 통로
F29: 제21조 통로의 조명 | G29: 제21조 | H29: 통로의 조명
F30: 제22조 통로의 설치 | G30: 제22조 | H30: 통로의 설치
F31: 제23조 가설통로의 구조 | G31: 제23조 | H31: 가설통로의 구조
F32: 제24조 사다리식 통로 등의 구조 | G32: 제24조 | H32: 사다리식 통로 등의 구조
F33: 제25조 갱내통로 등의 위험 방지 | G33: 제25조 | H33: 갱내통로 등의 위험 방지
F34: 제26조 계단의 강도 | G34: 제26조 | H34: 계단의 강도
F35: 제27조 계단의 폭 | G35: 제27조 | H35: 계단의 폭
F36: 제28조 계단참의 높이 | G36: 제28조 | H36: 계단참의 높이
F37: 제29조 천장의 높이 | G37: 제29조 | H37: 천장의 높이
F38: 제30조 계단의 난간 | G38: 제30조 | H38: 계단의 난간
B39: 제4장 보호구
F40: 제31조 보호구의 제한적 사용 | G40: 제31조 | H40: 보호구의 제한적 사용
F41: 제32조 보호구의 지급 등 | G41: 제32조 | H41: 보호구의 지급 등
...

Sheet 기준상세
A1: 산업안전보건기준에 관한 규칙 | V1: 2022년 10월 18일 개정안 반영
R2: 바로가기 | S2: 메인화면 | T2: 산안법 | U2: 과태료
A3: 제1편 총칙
A7: 제1장 통칙
C8: 제1조(목적)
D9: 이 규칙은「산업안전보건법」에서 위임한 산업안전보건기준에 관한 사항과 그 시행에 필요한 사항을 규정함을 목적으로 한다.
C11: 제2조(용어의 정의)
D12: 용어의 뜻은 이 규칙에 특별한 규정이 없으면 「산업안전보건법」,「시행령」및「시행규칙」에서 정하는 바에 따른다.
A16: 제2장 작업장
C17: 제3조(전도의 방지)
D18: ① 사업주는 근로자가 작업장에서 넘어지거나 미끄러지는 등의 위험이 없도록 작업장 바닥 등을 안전하고 청결한 상태로 유지하여야
E19: 한다.
D20: ② 사업주는 제품, 자재, 부재 등이 넘어지지 않도록 붙들어 지탱하게 하는 등 안전 조치를 하여야 한다. 다만, 근로자가 접근하지 못하
E21: 도록 조치한 경우에는 그러하지 아니하다.
R22: 목차1쪽
C23: 제4조(작업장의 청결)
D24: 사업주는 근로자가 작업하는 장소를 항상 청결하게 유지ㆍ관리하여야 하며, 폐기물은 정해진 장소에만 버려야 한다.
C26: 제4조의2(분진의 흩날림 방지)
D27: 사업주는 분진이 심하게 흩날리는 작업장에 대하여 물을 뿌리는 등 분진이 흩날리는 것을 방지하기 위하여 필요한 조치를 하여야 한다.
C29: 제5조(오염된 바닥의 세척 등)
D30: ① 사업주는 인체에 해로운 물질, 부패하기 쉬운 물질 또는 악취가 나는 물질 등에 의하여 오염될 우려가 있는 작업장의 바닥이나 벽을
E31: 수시로 세척하고 소독하여야 한다.
D32: ② 사업주는 제1항에 따른 세척 및 소독을 하는 경우에 물이나 그 밖의 액체를 다량으로 사용함으로써 습기가 찰 우려가 있는 작업장의
E33: 바닥이나 벽은 불침투성 재료로 칠하고 배수에 편리한 구조로 하여야 한다.
C35: 제6조(오물의 처리 등)
D36: ① 사업주는 해당 작업장에서 배출하거나 폐기하는 오물을 일정한 장소에서 노출되지 않도록 처리하고, 병원체로 인하여 오염될 우려
E37: 가 있는 바닥ㆍ벽 및 용기 등을 수시로 소독하여야 한다.
D38: ② 사업주는 폐기물을 소각 등의 방법으로 처리하려는 경우 해당 근로자가 다이옥신 등 유해물질에 노출되지 않도록 작업공정 개선,
E39: 개인보호구 지급ㆍ착용 등 적절한 조치를 하여야 한다.
D40: ③ 근로자는 제2항에 따라 지급된 개인보호구를 사업주의 지시에 따라 착용하여야 한다.
C42: 제7조(채광 및 조명)
D43: 사업주는 근로자가 작업하는 장소에 채광 및 조명을 하는 경우 명암의 차이가 심하지 않고 눈이 부시지 않은 방법으로 하여야 한다.
C45: 제8조(조도)
D46: 사업주는 근로자가 상시 작업하는 장소의 작업면 조도를 다음 각 호의 기준에 맞도록 하여야 한다.
E47: 다만, 갱내 작업장과 감광재료를 취급하는 작업장은 그러하지 아니하다.
E48: 1. 초정밀작업: 750럭스(lux) 이상 | L48: 3. 보통작업: 150럭스 이상
E49: 2. 정밀작업: 300럭스 이상 | L49: 4. 그 밖의 작업: 75럭스 이상
C51: 제9조(작업발판 등)
D52: 사업주는 선반ㆍ롤러기 등 기계ㆍ설비의 작업 또는 조작 부분이 그 작업에 종사하는 근로자의 키 등 신체조건에 비하여 지나치게 높거
E53: 나 낮은 경우 안전하고 적당한 높이의 작업발판을 설치하거나 그 기계ㆍ설비를 적정 작업높이로 조절하여야 한다.
...

Sheet 관리자선임
A1: 건설업의 안전관리 조직 구성
J2: 정리중
B4: 구 분 | C4: 대상사업장 | D4: 배치인원 | E4: 자격 | F4: 직무 | G4: 선임/해임 | H4: 법적근거 | I4: 건설기술진흥법
B5: 안전보건 | C5: 20억 이상 사업장 | D5: 1명 | E5: 사업장을 실질적으로 | F5: 법 제15조제1항 | H5: 법 제15조
B6: 관리책임자 | E6: 총괄 관리하는 사람
B7: 관리책임자 | C7: 모든 사업장 | D7: 무제한 | E7: 근로자를 지휘.감독하는 | F7: 영 제15조제1항 | H7: 법 제16조 | I7: 안전관리책임자
B8: 감독자 | E8: 직위에 있는 사람 | I8: 안전관리담당자
C9: 50억이상 사업장 | D9: 1명 | E9: 산업안전지도사 이상
C10: 800억 이상 사업장 | D10: 2명 | E10: 산업안전산업기사 이상
C11: 1500억이상 사업장(+700) | D11: 3명 | E11: 건설안전산업기사 이상
C12: 2200억이상 사업장(+700) | D12: 4명 | E12: 4년재 관련학과 학위자
C13: 3000억이상 사업장(+800) | D13: 5명 | E13: 그 외 | G13: 교체 증원 사유
B14: 안전관리자 | C14: 3900억이상 사업장(+900) | D14: 6명 | E14: 시행령 제17조 별표 4 | F14: 시행령 제18조 | G14: 시행규칙 제12조 | H14: 법 제17조
C15: 4900억이상 사업장(+1000) | D15: 7명
C16: 6000억이상 사업장(+1100) | D16: 8명
C17: 7200억이상 사업장(+1200) | D17: 9명
C18: 8500억이상 사업장(+1300) | D18: 10명
C19: 1조원이상시(+3천억마다) | D19: 11명
C20: 시행령 제16조 별표 3
C21: 800억 이상 사업장 | D21: 1명 | E21: 산업보건지도사 이상
C22: 2400억 이상 사업장 | D22: 2명 | E22: 의사 및 간호사
C23: 3800억 이상 사업장(+1400) | D23: 3명 | E23: 산업위생관리산업기사 이상
B24: 보건관리자 | C24: 5200억 이상 사업장(+1400) | D24: 4명 | E24: 대기환경산업기사 이상 | F24: 시행령 제22조 | H24: 법 제18조
C25: ※ 1,400억 증액시 마다 1명 | E25: 그 외
C26: ※ 상근자 600명마다 1명 | E26: 시행령 제21조 별표 6
C27: 시행령 제20조 별표 5
C28: 상시근로자 20명이상 50명 | E28: 안전관리,보건관리자 | F28: 안전,보건관리자의 직무
B29: 안전보건 | C29: 미만 사업장 | E29: 관련교육 이수자 | F29: 전문기관에 위탁 가능
B30: 관리담당자 | C30: (건설업 해당사항 없음) | D30: 1명 | E30: 시행령 제24조제2항 | F30: 시행령 제25조 | H30: 법 제19조
C31: (안전,보건관리자 선임 사업
C32: 장 해당 없음)
C33: 보건관리자 선임 대상사업장 중 | E33: 의사법에 의한 의사
B34: 산업보건의 | C34: 상시근로자 50명 이상인 경우 | D34: 1명 | E34: 시행령 제30조 | F34: 시행령 제31조 | H34: 법 제22조
C35: 보건근로자가 의사인 경우 제외
C36: 외부에서 위촉 가능
B37: 명예산업 | C37: 고용노동부장관이 필요하다고 | D37: 1명 | E37: 시행령 제32조제1항 | F37: 시행령 제32조제2항 | G37: 시행령 제32조 제1항 | H37: 법 제23조
B38: 안전감독관 | C38: 판단하는 경우(임기2년,연임가) | G38: 시행령 제33조
C39: 도급인의 20억이상 사업장
B40: 안전보건 | C40: 에서 관계수급인의 | D40: 1명 | E40: 도급인이 선임한 | F40: 시행령 제53조 | H40: 법 제62조 | I40: 안전총괄책임자
B41: 총괄책임자 | C41: 근로자가 작업하는 경우 | E41: 안전보건관리책임자
...

Sheet 노사협의체
C1: 메인화면 | D1: 산안법 | E1: 과태료
A2: 구분 | B2: 농업,어업,제조업,서비스업 | D2: 건설업 | H2: 안전보건 협의체 | T2: 산업안전보건위원회 | AF2: 노사협의체 | AR2: 노사협의회
B3: 산업안전보건위원회 | C3: 노사협의회 | D3: 노사협의체 | E3: 안전보건협의체 | H3: ※ 도급 하도급 관계가 성립되는 모든 건설현장은 | T3: ※ 일정 규모 이상의 모든 사업장에서는 | AF3: ※ 건설공사 120억 이상, 토목공사 150억 이상의 현장에서는 | AR3: ※ 상시근로자 30인 이상의 사업장에서는
A4: 법률 | B4: 산안법 | C4: 근로자 참여 및 협력 | D4: 산안법 | E4: 산안법 | H4: ※ 매월 1회 안전보건협의체 회의 실시 | T4: ※ 산업안전보건 위원회를 설치하여 분기별 1회 회의 실시 | AF4: ※ 노사협의체를 구성하고 2개월마다 회의 실시 | AR4: ※ 노사협의회를 설치하고 매 분기마다 정기적으로 회의 실시
A5: 근거 | B5: 제24조제1항 | C5: 증진에 관한 법률 | D5: 제75조제1항 | E5: 제64조제1항1호 | H5: ※ 2개월마다 합동 안전.보건 점검 실시 | T5: ※ 노사협의체를 구성한 경우 산업안전보건위원회 활동을 한 것으로 본다. | AF5: ※ 노사협의체를 구성한 경우 산업안전보건위원회,노사협의회는 구성한 것으로 본다. | AR5: ※ 타 기구와 별도조직으로 반드시 설치해야함
B6: 근로자와 사용자가 함께 | C6: 근로자와 사용자가 참여 | D6: 근로자와 사용자가 함께 | E6: 도급인과 관계수급인이 | H6: ※ 2일에 1회 이상 작업장 순회점검 | AF6: ※ 의무사항은 아니지만 건설현장에서 노사협의체 구성시 안전보건협의체, 산업안전
A7: 입법 | B7: 산업안전보건에 관한 중 | C7: 와 협력을 통하여 근로 | D7: 산업안전보건에 관한 중 | E7: 함께 산업안전보건에 | H7: ※ 노사협의체를 구성한 경우 안전보건협의체를 구성한 것으로 본다. | AG7: 보건위원회를 설치한 것으로 갈음하므로 구성하는 것이 좋을 것임
A8: 취지 | B8: 요사항을 심의.의결하는 | C8: 자의 복지증진과 기업의 | D8: 요사항을 심의.의결하는 | E8: 관한 중요사항을
B9: 의결 기관 | C9: 건전한 발전을 도모하는 | D9: 의결 기관 | E9: 협의하기 위한 | H9: 산업안전보건법 | T9: 산업안전보건법 | AF9: 산업안전보건법 | AR9: 근로자참여 및 협력증진에 관한 법률
C10: 협의기구 | E10: 협의기구 | H10: 제64조(도급에 따른 산업재해 예방조치) | T10: 제24조(산업안전보건위원회) | AF10: 제75조(안전 및 보건에 관한 협의체 등의 구성ㆍ운영에 관한 특례) | AR10: 제4조(노사협의회의 설치)
B11: 상시근로자 100인 이상 | I11: ① 도급인은 관계수급인 근로자가 도급인의 사업장에서 작업을 하는 경우 다음 각 호의 | T11: ① 사업주는 사업장의 안전 및 보건에 관한 중요 사항을 심의ㆍ의결하기 위하여 사업장에 | AF11: ① 대통령령으로 정하는 규모의 건설공사의 건설공사도급인은 해당 건설공사 현장에 근로 | AS11: ① 노사협의회는 근로조건에 대한 결정권이 있는 사업이나 사업장단위로 설치하여야 한다.
A12: 설치 | B12: 유해업종 상근자 50인 이상 | C12: 상시근로자 30인 이상의 | D12: 건설공사 120억 이상 | E12: 도급인의 사업장에서 | J12: 사항을 이행하여야 한다. | U12: 근로자위원과 사용자위원이 같은 수로 구성되는 산업안전보건위원회를 구성ㆍ운영 | AG12: 자위원과 사용자위원이 같은 수로 구성되는 안전 및 보건에 관한 협의체(이하 “노사협의 | AT12: 다만, 상시 30명 미만의 근로자를 사용하는 사업이나 사업장은 그러하지 아니하다
B13: 건설공사 120억 이상 | C13: 모든 직종 모든 사업장 | D13: 토목공사 150억 이상 | E13: 작업하는 관계수급인 | J13: 1. 도급인과 수급인을 구성원으로 하는 안전 및 보건에 관한 협의체의 구성 및 운영 | U13: 하여야 한다. | AG13: 체”라 한다)를 대통령령으로 정하는 바에 따라 구성ㆍ운영할 수 있다. | AS13: ② 하나의 사업에 지역을 달리하는 사업장이 있을 경우에는 그 사업장에도 설치할 수 있다.
A14: 대상 | B14: 토목공사 150억 이상 | E14: 발생시 | J14: 2. 작업장 순회점검 | AF14: ② 건설공사도급인이 제1항에 따라 노사협의체를 구성ㆍ운영하는 경우에는 산업안전보건
B15: 농,어,서비스 300인 이상 | J15: 3. 관계수급인이 근로자에게 하는 제29조제1항부터 제3항까지의 규정에 따른 안전보건 | AG15: 위원회 및 제64조제1항제1호에 따른 안전 및 보건에 관한 협의체를 각각 구성ㆍ운영하는 | AR15: 제6조(협의회의 구성)
A16: 실시주기 | B16: 분기 | C16: 분기 | D16: 2개월 | E16: 매월 | K16: 교육을 위한 장소 및 자료의 제공 등 지원 | AG16: 것으로 본다. | AS16: ① 협의회는 근로자와 사용자를 대표하는 같은 수의 위원으로 구성하되, 각 3명 이상 10명
B17: 가. 사용자위원 | C17: 가. 회사측 | D17: 가. 사용자위원 | E17: 가. 도급인측 | J17: 4. 관계수급인이 근로자에게 하는 제29조제3항에 따른 안전보건교육의 실시 확인 | T17: 산업안전보건법 시행령 | AF17: ③ 제1항에 따라 노사협의체를 구성ㆍ운영하는 건설공사도급인은 제24조제2항 각 호의 사 | AT17: 이하로 한다.
B18: 1. 대표자 | C18: 1. 3~10인 | D18: 1. 대표자 | E18: 1. 대표자 | J18: 5. 다음 각 목의 어느 하나의 경우에 대비한 경보체계 운영과 대피방법 등 훈련 | T18: 제34조(산업안전보건위원회 구성 대상) | AG18: 항에 대하여 노사협의체의 심의ㆍ의결을 거쳐야 한다. 이 경우 노사협의체에서 의결되지 | AS18: ② 근로자를 대표하는 위원은 근로자가 선출하되, 근로자의 과반수로 조직된 노동조합이
B19: 2. 안전관리자 | D19: 2. 안전관리자 | E19: 2. 안전관리자 | K19: 가. 작업 장소에서 발파작업을 하는 경우 | U19: 산업안전보건위원회를 구성해야 할 사업의 종류 및 사업장의 상시근로자 수는 별표 9 | AG19: 아니한 사항의 처리방법은 대통령령으로 정한다. | AT19: 있는 경우에는 노동조합의 대표자와 그 노동조합이 위촉하는 자로 한다.
A20: 구성 | B20: 3. 보건관리자 등 | D20: 3. 보건관리자 | E20: 3. 보건관리자 등 | K20: 나. 작업 장소에서 화재ㆍ폭발, 토사ㆍ구축물 등의 붕괴 또는 지진 등이 발생한 경우 | U20: 와 같다. | AF20: ④ 노사협의체는 대통령령으로 정하는 바에 따라 회의를 개최하고 그 결과를 회의록으로 | AS20: ③ 사용자를 대표하는 위원은 해당 사업이나 사업장의 대표자와 그 대표자가 위촉하는 자
D21: 4. 하도급사 대표 | J21: 6. 위생시설 등 고용노동부령으로 정하는 시설의 설치 등을 위하여 필요한 장소의 제공 | U21: ※ 약식정리 제조업, 광산업 등 상시 근로자 50명이상, 농어업,서비스업 300명이상 | AG21: 작성하여 보존하여야 한다. | AT21: 로 한다.
A22: 인원 | D22: (20억 이상) 등 | K22: 또는 도급인이 설치한 위생시설 이용의 협조 | V22: 건설업 공사금액 120억이상(토목공사업 150억 이상) | AF22: ⑤ 노사협의체는 산업재해 예방 및 산업재해가 발생한 경우의 대피방법 등 고용노동부령
B23: 나. 근로자위원 | C23: 나. 근로자측 | D23: 나. 근로자위원 | E23: 나. 수급인측 | J23: 7. 같은 장소에서 이루어지는 도급인과 관계수급인 등의 작업에 있어서 관계수급인 등의 | AG23: 으로 정하는 사항에 대하여 협의하여야 한다. | AR23: 제12조(회의)
B24: 1. 근로자대표 | C24: 1. 3~10인 | D24: 1. 근로자대표 | E24: 1. 사업주 | K24: 작업시기ㆍ내용, 안전조치 및 보건조치 등의 확인 | T24: 제35조(산업안전보건위원회의 구성) | AF24: ⑥ 노사협의체를 구성ㆍ운영하는 건설공사도급인ㆍ근로자 및 관계수급인ㆍ근로자는 | AS24: ① 협의회는 3개월마다 정기적으로 회의를 개최하여야 한다.
B25: 2. 명예산업안전감독관 | D25: 2. 명예산업안전감독관 | E25: 2. 책임자 | J25: 8. 제7호에 따른 확인 결과 관계수급인 등의 작업 혼재로 인하여 화재ㆍ폭발 등 대통령 | U25: ① 산업안전보건위원회의 근로자위원은 다음 각 호의 사람으로 구성한다. | AG25: 제3항에 따라 노사협의체가 심의ㆍ의결한 사항을 성실하게 이행하여야 한다. | AS25: ② 협의회는 필요에 따라 임시회의를 개최할 수 있다.
D26: 3. 하도급 근로자대표 | E26: 3. 근로자 등 | K26: 령으로 정하는 위험이 발생할 우려가 있는 경우 관계수급인 등의 작업시기ㆍ내용 | V26: 1. 근로자대표 | AF26: ⑦ 노사협의체에 관하여는 제24조제5항 및 제6항을 준용한다. 이 경우 “산업안전보건위
D27: (20억 이상) 등 | K27: 등의 조정 | V27: 2. 명예산업안전감독관이 위촉되어 있는 사업장의 경우 근로자대표가 지명하는 | AG27: 원회”는 “노사협의체”로 본다. | AR27: 제19조(회의록 비치)
A28: 점검 | B28: 필요 | C28: 필요 | D28: 합동점검,순회점검 | E28: 필요 | I28: ② 제1항에 따른 도급인은 고용노동부령으로 정하는 바에 따라 자신의 근로자 및 관계 | W28: 1명 이상의 명예산업안전감독 | AS28: ① 협의회는 다음 각 호의 사항을 기록한 회의록을 작성하여 갖추어 두어야 한다.
B29: 1. 노사협의체를 구성 및 운영하는 경우 산업안전보건위원회와 안전보건협의체 갈음 가능(법제75조제2항) | J29: 수급인 근로자와 함께 정기적으로 또는 수시로 작업장의 안전 및 보건에 관한 점검을 | V29: 3. 근로자대표가 지명하는 9명 이내의 해당 사업장의 근로자 | AT29: 1. 개최 일시 및 장소
A30: 특기 | B30: 2. 노사협의회는 타 기관과 갈음 불가 | J30: 하여야 한다. | U30: ② 산업안전보건위원회의 사용자위원은 다음 각 호의 사람으로 구성한다. | AT30: 2. 출석 위원
A31: 사항 | B31: 3. 법은 건설업과 제조업으로 구분하지 않음. 다만, 건설업종에서는 120억 미만시 안전보건협의체, | I31: ③ 제1항에 따른 안전 및 보건에 관한 협의체 구성 및 운영, 작업장 순회점검, 안전보건교육 | V31: 1. 해당 사업의 대표자 | AT31: 3. 협의 내용 및 의결된 사항
B32: 120억 이상의 현장에서는 노사협의체만 운영해도 적법 | J32: 지원, 그 밖에 필요한 사항은 고용노동부령으로 정한다. | V32: 2. 안전관리자 1명 | AT32: 4. 그 밖의 토의사항
B33: 4. 보건의가 선임된경우 사용자 위원 등록, 20억이하의 관계수급인도 의결을 거쳐 위원등록 가능 | V33: 3. 보건관리자 1명 - 해당시 | AF33: 산업안전보건법 시행령 | AS33: ② 제1항에 따른 회의록은 작성한 날부터 3년간 보존하여야 한다.
A34: 대표자 : 현장대리인 | V34: 4. 산업보건의 - 선임된 경우 | AF34: 제63조 (노사협의체의 설치 대상)
A35: 근로자대표 : 작업반장 등 | V35: 5. 해당 사업의 대표자가 지명하는 9명 이내의 해당 사업장 부서의 장 | AG35: “대통령령으로 정하는 규모의 건설공사”란 공사금액이 120억원이상인 건설공사를 말한다.
H36: 산업안전보건법 시행령 | AH36: ( 토목공사업은 150억원)
H37: 제79조(협의체의 구성 및 운영) | T37: 제36조(산업안전보건위원회의 위원장) | AR37: 근로자참여 및 협력증진에 관한 법률 시행령
I38: ① 법 제64조제1항제1호에 따른 안전 및 보건에 관한 협의체는 도급인 및 그의 수급인 전원 | U38: 산업안전보건위원회의 위원장은 위원 중에서 호선(互選)한다. | AF38: 제64조 (노사협의체의 구성) | AR38: 제3조(근로자위원의 선출)
J39: 으로 구성해야 한다. | U39: 이 경우 근로자위원과 사용자위원 중 각 1명을 공동위원장으로 선출할 수 있다. | AG39: ① 노사협의체는 다음 각 호에 따라 근로자위원과 사용자위원으로 구성한다. | AS39: ① 법 제6조제2항 및 제4항에 따라 근로자의 과반수로 구성된 노동조합이 조직되어 있지
I40: ② 협의체는 다음 각 호의 사항을 협의해야 한다. | AH40: 1. 근로자위원 | AT40: 아니한 사업 또는 사업장의 근로자위원은 근로자의 직접ㆍ비밀ㆍ무기명투표로 선출
...

Sheet 교육시간
A1: ■산업안전보건법 시행규칙 [별표 4] | O1: 메인화면 | P1: 산안법 | Q1: 과태료
A2: 안전보건교육 교육과정별 교육시간(제26조제1항 등 관련)
A4: 1. 근로자 안전보건교육(제26조제1항, 제28조제1항 관련)
A5: 교육과정 | B5: 교육대상 | E5: 교육시간 | H5: 산업안전보건법
A6: 가. 정기교육 | B6: 사무직 종사 근로자 | E6: 매분기 3시간 이상 | H6: 제29조(근로자에 대한 안전보건교육)
B7: 사무직 종사 근로자 | C7: 판매업무에 직접종사하는 근로자 | E7: 매분기 3시간 이상 | I7: ① 사업주는 소속 근로자에게 고용노동부령으로 정하는 바에 따라 정기적으로 안전보건교육을 하여야 한다.
B8: 외의 근로자 | C8: 판매업무에 직접종사하는 근로자 외의 근로자 | E8: 매분기 6시간 이상 | I8: ② 사업주는 근로자를 채용할 때와 작업내용을 변경할 때에는 그 근로자에게 고용노동부령으로 정하는 바에 따라
B9: 관리감독자 지위에 있는 사람 | E9: 연간 16시간 이상 | J9: 해당 작업에 필요한 안전보건교육을 하여야 한다. 다만, 제31조제1항에 따른 안전보건교육을 이수한 건설
A10: 나. 채용 시 교육 | B10: 일용근로자 | E10: 1시간 이상 | J10: 일용근로자를 채용하는 경우에는 그러하지 아니하다.
B11: 일용근로자를 제외한 근로자 | E11: 8시간 이상 | I11: ③ 사업주는 근로자를 유해하거나 위험한 작업에 채용하거나 그 작업으로 작업내용을 변경할 때에는 제2항에 따른
A12: 다. 작업내용 | B12: 일용근로자 | E12: 1시간 이상 | J12: 안전보건교육 외에 고용노동부령으로 정하는 바에 따라 유해하거나 위험한 작업에 필요한 안전보건교육을
A13: 변경 시 교육 | B13: 일용근로자를 제외한 근로자 | E13: 2시간 이상 | J13: 추가로 하여야 한다.
A14: 라. 특별교육 | B14: 별표5 제1호라목의 어느 하나에 해당하는 작업자 | E14: 2시간 이상 | I14: ④ 사업주는 제1항부터 제3항까지의 규정에 따른 안전보건교육을 제33조에 따라 고용노동부장관에게 등록한
B15: 별표5 제1호라목 제39조 타워크레인 신호작업에 종사하는 작업자 | E15: 8시간 이상 | J15: 안전보건교육기관에 위탁할 수 있다.
A16: 마. 건설업 기초 안전,보건교육 | C16: 건설 일용근로자 | E16: 4시간 이상
A18: 2. 안전보건관리책임자 등에 대한 교육(제29조제2항 관련) | H18: 산업안전보건법 시행규칙
A19: 교육대상 | C19: 교 육 시 간 | E19: 비 고 | H19: 제26조(교육시간 및 교육내용)
C20: 신 규 교 육 | D20: 보 수 교 육 | I20: ① 법 제29조제1항부터 제3항까지의 규정에 따라 사업주가 근로자에게 실시해야 하는 안전보건교육의 교육시간은
A21: 가. 안전보건관리책임자 | C21: 6시간 이상 | D21: 6시간 이상 | J21: 별표 4와 같고, 교육내용은 별표 5와 같다. 이 경우 사업주가 법 제29조제3항에 따른 유해하거나 위험한 작업에
A22: 나. 안전보건관리담당자 | C22: - | D22: 8시간 이상 | J22: 필요한 특별안전보건교육을 실시한 때에는 해당 근로자에 대하여 법 제29조제2항에 따라 채용랄 때 해야 하는
A23: 다. 안전관리자,보건관리자 | C23: 34시간이상 | D23: 24시간이상 | J23: 채용 시 교육 및 작업내용을 변경할 때 해야 하는 작업내용 변경 교육을 실시한 것으로 본다.
A24: 안전.보건관리 전문기관 종사자) | C24: 선임 후 3개월이내 | D24: 2년 이전 90일 이내 | I24: ② 제1항에 따른 교육을 실시하기 위한 교육방법과 그 밖에 교육에 필요한 사항은 고용노동부장관이 정하여 고시한다. | V24: 고시 : 안전보건교육규정 참조
I25: ③ 사업주가 법 제29조제1항부터 제3항까지의 규정에 따른 안전보건교육을 자체적으로 실시하는 경우에 교육을 할
A26: 3. 안전보건교육 미실시 과태료 | J26: 수 있는 사람은 다음 각 호의 어느 하나에 해당하는 사람으로 한다.
A27: 구 분 | C27: 1차 | D27: 2차 | E27: 3차 | J27: 1. 다음 각 목의 어느 하나에 해당하는 사람
A28: 근로자 정기교육 미실시(1명당) | C28: 10만원 | D28: 20만원 | E28: 50만원 | K28: 가. 법 제15조제1항에 따른 안전보건관리책임자
A29: 관리감독자 정기요육미실시 | C29: 50만원 | D29: 250만원 | E29: 500만원 | K29: 나. 법 제16조제1항에 따른 관리감독자
A30: 채용시교육, 작업내용 변경교육 미실시 | C30: 10만원 | D30: 20만원 | E30: 50만원 | K30: 다. 법 제17조제1항에 따른 안전관리자
A31: 특별안전보건교육 미실시 | C31: 50만원 | D31: 100만원 | E31: 150만원 | K31: 라. 법 제18조제1항에 따른 보건관리자
A32: 건설업기초안전보건교육 미실시 | C32: 10만원 | D32: 20만원 | E32: 50만원 | K32: 마. 법 제19조제1항에 따른 안전보건관리담당자
A33: 안전보건관리 책임자 | C33: 500만원 | D33: 500만원 | E33: 500만원 | K33: 바. 법 제22조제1항에 따른 산업보건의
A34: 안전관리자, 보건관리자 | C34: 500만원 | D34: 500만원 | E34: 500만원 | J34: 2. 공단에서 실시하는 해당 분야의 강사요원 교육과정을 이수한 사람
A35: ※ 5년 이내에 교육 미실시한 경우 누적관리 됩니다. | J35: 3. 법 제142조에 따른 산업안전지도사 또는 산업보건지도사(이하 “지도사”라 한다)
J36: 4. 산업안전보건에 관하여 학식과 경험이 있는 사람으로서 고용노동부장관이 정하는 기준에 해당하는 사람

Sheet 교육내용
A1: ■ 산업안전보건법 시행규칙 [별표 5] | M1: 메인화면 | N1: 산안법 | O1: 과태료
A2: 안전보건교육 교육대상별 교육내용(제26조제1항 등 관련)
A4: 1. 근로자 안전보건교육(제26조제1항 관련)
A5: 가. 근로자 정기교육
A6: 교육내용
A7: ○ 산업안전 및 사고 예방에 관한 사항
A8: ○ 산업보건 및 직업병 예방에 관한 사항
A9: ○ 건강증진 및 질병 예방에 관한 사항
A10: ○ 유해·위험 작업환경 관리에 관한 사항
A11: ○ 산업안전보건법령 및 산업재해보상보험 제도에 관한 사항
A12: ○ 직무스트레스 예방 및 관리에 관한 사항
A13: ○ 직장 내 괴롭힘, 고객의 폭언 등으로 인한 건강장해 예방 및 관리에 관한 사항
A15: 나. 관리감독자 정기교육
... A45: 라. 특별교육 대상 작업별 교육
A46: 작업명 | E46: 교육내용
A47: <공통내용>
A48: 제1호부터 제39호까지의 작업 | E48: 다목과 같은 내용
A49: <개별내용>
A50: 1. 고압실 내 작업(잠함공법이나 | E50: ○ 고기압 장해의 인체에 미치는 영향에 관한 사항
A51: 그 밖의 압기공법으로 대기압을 | E51: ○ 작업의 시간·작업 방법 및 절차에 관한 사항
A52: 넘는 기압인 작업실 또는 수갱 내 | E52: ○ 압기공법에 관한 기초지식 및 보호구 착용에 관한 사항
A53: 부에서 하는 작업만 해당한다) | E53: ○ 이상 발생 시 응급조치에 관한 사항
E54: ○ 그 밖에 안전·보건관리에 필요한 사항
A55: 2. 아세틸렌 용접장치 또는 가스 | E55: ○ 용접 흄, 분진 및 유해광선 등의 유해성에 관한 사항
A56: 집합 용접장치를 사용하는 금속 | E56: ○ 가스용접기, 압력조정기, 호스 및 취관두(불꽃이 나오는 용접기의 앞부분) 등의 기기점검에 관한 사항
A57: 의 용접·용단 또는 가열작업(발생 | E57: ○ 작업방법·순서 및 응급처치에 관한 사항
A58: 기·도관 등에 의하여 구성되는 용 | E58: ○ 안전기 및 보호구 취급에 관한 사항
A59: 접장치만 해당한다) | E59: ○ 화재예방 및 초기대응에 관한사항
E60: ○ 그 밖에 안전·보건관리에 필요한 사항
A61: 3. 밀폐된 장소(탱크 내 또는 환 | E61: ○ 작업순서, 안전작업방법 및 수칙에 관한 사항
A62: 기가 극히 불량한 좁은 장소 | E62: ○ 환기설비에 관한 사항
A63: 를 말한다)에서 하는 용접작 | E63: ○ 전격 방지 및 보호구 착용에 관한 사항
A64: 업 또는 습한 장소에서 하는 | E64: ○ 질식 시 응급조치에 관한 사항
A65: 전기용접 작업 | E65: ○ 작업환경 점검에 관한 사항
E66: ○ 그 밖에 안전·보건관리에 필요한 사항
A67: 4. 폭발성·물반응성·자기반응성· | E67: ○ 폭발성·물반응성·자기반응성·자기발열성 물질, 자연발화성 액체·고체 및 인화성 액체의 성질이나 상태에 관한 사항
A68: 자기발열성 물질, 자연발화 | E68: ○ 폭발 한계점, 발화점 및 인화점 등에 관한 사항
A69: 성 액체·고체 및 인화성 액 | E69: ○ 취급방법 및 안전수칙에 관한 사항
A70: 체의 제조 또는 취급작업(시 | E70: ○ 이상 발견 시의 응급처치 및 대피 요령에 관한 사항
A71: 험연구를 위한 취급작업은 | E71: ○ 화기·정전기·충격 및 자연발화 등의 위험방지에 관한 사항
...

Sheet 진흥법과태료
A1: 「건설기술진흥법」위반 시 주요 과태료 부과 기준 | M1: 메인화면
J2: Click Me~! | N2: 별표26 행정처분까지 정리하여 파일 완성
A3: 「건설기술진흥법 시행령 별표11」 | H3: [3년간 누적관리] | J3: 필독~! | M3: 산업안전보건기준
A4: 위 반 내 용 | C4: 법 조 문 (법 제91조) | D4: 세 부 내 용 | F4: 과 태 료(만원)
F5: 1차위반 | G5: 2차위반 | H5: 3차이상
A6: 1) | B6: =진20 -> 제20조(건설기술인의 육성) | C6: 제3항제1호 | D6: 1) | E6: 교육ㆍ훈련을 정당한 사유 없이 받지 않은 경우 | F6: 50 | G6: 50 | H6: 50
B7: 제2항(기술인의 교육ㆍ훈련 의무)를 위반한 경우 | K7: 제1장 총칙
B8: 제3항(교육ㆍ훈련 경비 부담 의무)를 위반한 경우 | C8: 제3항제2호 | D8: 2) | E8: 경비를 부담하지 않은 경우 | F8: 50 | G8: 50 | H8: 50
D9: 3) | E9: 경비부담을 이유로 건설기술인에게 불이익을 준 경우 | L9: 제1조(목적)
A10: 2) | B10: =진21 -> 제21조(건설기술인의 신고) | C10: 제3항제3호 | D10: 1) | E10: 자료를 제출하지 않은 경우 | F10: 150 | G10: 225 | H10: 300 | M10: 이 법은 건설기술의 연구ㆍ개발을 촉진하여 건설기술 수준을 향상시키고 이를 바탕으로 관련 산업을 진흥하여 건설공사가 적정하게 시행되도록 함과 아울러 건설공사의 품질을 높이고 안전을 확보함으로써 공공복리의 증진과 국민경제의 발전에 이바지함을 목적으로 한다.
B11: 제3항(경력 확인자료 제출 의무)를 위반한 경우 | D11: 2) | E11: 거짓으로 자료를 제출한 경우
A12: 3) | B12: =진222 -> 제22조의2(건설기술인의 업무수행 등) | C12: 제2항제1호 | D12: 1) | E12: 설계 및 시방에 없는 부당한 요구를 한 경우 | F12: 300 | G12: 500 | H12: 1000 | L12: 제2조(정의)
B13: 제2항(부당한 작업지시 금지 의무)를 위반한 경우 | D13: 2) | E13: 부당한 요구를 응하지 않은 건설기술인에게 불이익을 준 경우 | M13: 이 법에서 사용하는 용어의 뜻은 다음과 같다.
A14: 4) | B14: =진24 -> 제24조(건설기술인의 업무정지 등) | C14: 제3항제4호 | D14: 1) | E14: 건설기술경력증을 반납하지 않은 경우 | F14: 50 | G14: 50 | H14: 50 | M14: 1. “건설공사”란 「건설산업기본법」 제2조제4호에 따른 건설공사를 말한다.
B15: 제4항(건설기술경력증 반납 규정)을 위반한 경우 | M15: 2. “건설기술”이란 다음 각 목의 사항에 관한 기술을 말한다. 다만, 「산업안전보건법」에서 근로자의 안전에 관하여 따로 정하고 있는 사항은 제외한다.
A16: 5) | B16: =진26 -> 제26조(건설엔지니어링업의 등록 등) | D16: 1) | E16: 변경등록을 하지 않거나 거짓으로 변경등록을 한 경우 | M16: 가. 건설공사에 관한 계획ㆍ조사(지반조사 포함)ㆍ설계(「건축사법」 제2조제3호에 따른 설계 제외)ㆍ시공ㆍ감리ㆍ시험ㆍ평가ㆍ측량(해양조사 포함)ㆍ자문ㆍ지도ㆍ품질관리ㆍ안전점검 및 안전성 검토
B17: 제3항(변경사항 수정 등록 의무)를 위반한 경우 | D17: 가. | E17: 변경등록 지연기간이 1개월 미만인 경우 | F17: 10 | G17: 10 | H17: 10 | M17: 나. 시설물의 운영ㆍ검사ㆍ안전점검ㆍ정밀안전진단ㆍ유지ㆍ관리ㆍ보수ㆍ보강 및 철거
C18: 제3항제5호 | D18: 나. | E18: 변경등록 지연기간이 1개월 이상 3개월 미만인 경우 | F18: 30 | G18: 30 | H18: 30 | M18: 다. 건설공사에 필요한 물자의 구매와 조달
D19: 다. | E19: 지연기간이 3개월 이상이거나 변경등록을 하지 않은 경우 | F19: 50 | G19: 50 | H19: 50 | M19: 라. 건설장비의 시운전
D20: 라. | E20: 변경등록을 거짓으로 한 경우 | F20: 200 | G20: 200 | H20: 200 | M20: 마. 건설사업관리
B21: 제4항(휴업,폐업신고 의무)를 위반한 경우 | D21: 2) | E21: 휴업 또는 폐업 신고를 하지 않은 경우 | M21: 바. 그 밖에 건설공사에 관한 사항으로서 대통령령으로 정하는 사항
C22: 제3항제6호 | D22: 가. | E22: 변경등록 지연기간이 1개월 미만인 경우 | F22: 10 | G22: 10 | H22: 10 | M22: 3. “건설엔지니어링”이란 다른 사람의 위탁을 받아 건설기술에 관한 업무를 수행하는 것을 말한다. 다만, 건설공사의 시공 및 시설물의 보수ㆍ철거 업무는 제외한다.
D23: 다. | E23: 변경등록 지연기간이 1개월 이상 3개월 미만인 경우 | F23: 30 | G23: 30 | H23: 30 | M23: 4. “건설사업관리”란 「건설산업기본법」 제2조제8호에 따른 건설사업관리를 말한다.
D24: 다. | E24: 지연기간이 3개월 이상이거나 변경등록을 하지 않은 경우 | F24: 50 | G24: 50 | H24: 50 | M24: 5. “감리”란 건설공사가 관계 법령이나 기준, 설계도서 또는 그 밖의 관계 서류 등에 따라 적정하게 시행될 수 있도록 관리하거나 시공관리ㆍ품질관리ㆍ안전관리 등에 대한 기술지도를 하는 건설사업관리 업무를 말한다.
A25: 6) | B25: =진29 -> 제29조(건설엔지니어링사업자의 영업 양도 등) | D25: 1) | E25: 영업 양도 또는 합병 신고를 하지 않은 경우 | M25: 6. “발주청”이란 건설공사 또는 건설엔지니어링을 발주하는 국가, 지방자치단체, 「공공기관의 운영에 관한 법률」 제5조에 따른 공기업ㆍ준정부기관, 「지방공기업법」에 따른 지방공사ㆍ지방공단, 그 밖에 대통령령으로 정하는 기관의 장을 말한다.
B26: 제1항(영업 양도 및 합병 신고 의무)를 위반한 경우 | C26: 제3항제7호 | D26: 가. | E26: 신고 지연기간이 1개월 미만인 경우 | F26: 100 | G26: 100 | H26: 100 | M26: 7. “건설사업자”란 「건설산업기본법」 제2조제7호에 따른 건설사업자를 말한다.
D27: 다. | E27: 신고 지연기간이 1개월 이상 3개월 미만인 경우 | F27: 200 | G27: 200 | H27: 200 | M27: 8. “건설기술인”이란 「국가기술자격법」 등 관계 법률에 따른 건설공사 또는 건설엔지니어링에 관한 자격, 학력 또는 경력을 가진 사람으로서 대통령령으로 정하는 사람을 말한다.
D28: 다. | E28: 신고 지연기간이 3개월 이상이거나 신고를 하지 않은 경우 | F28: 300 | G28: 300 | H28: 300 | M28: 9. “건설엔지니어링사업자”란 건설엔지니어링을 영업의 수단으로 하려는 자로서 제26조에 따라 등록한 자를 말한다.
A29: 7) | B29: =진31 -> 제31조(건설엔지니어링사업자의 등록취소 등) | C29: 제3항제8호 | D29: 1) | E29: 영업정지기간에 건설엔지니어링 업무를 수행한 경우 | F29: 300 | G29: 300 | H29: 300 | M29: 10. “건설사고”란 건설공사를 시행하면서 대통령령으로 정하는 규모 이상의 인명피해나 재산피해가 발생한 사고를 말한다.
B30: 제1항,제2항(영업정지)를 위반한 경우 | M30: 11. “지반조사”란 건설공사 대상 지역의 지질구조 및 지반상태, 토질 등에 관한 정보를 획득할 목적으로 수행하는 일련의 행위를 말한다.
B31: 제3항(영업정지기간 중 상호변경)를 위반한 경우 | D31: 2) | E31: 영업정지기간에 상호를 바꾸어 건설공사를 수주한 경우 | M31: 12. “무선안전장비”란 「전파법」 제2조제1항제5호에 따른 무선설비 및 같은 법 제2조제1항제5호의2에 따른 무선통신을 이용하여 건설사고의 위험을 낮추는 기능을 갖춘 장비를 말한다.
C32: 제3항제9호 | D32: 가. | E32: 수주 건수가 1건인 경우 | F32: 50 | G32: 50 | H32: 50
D33: 다. | E33: 수주 건수가 2건 이상인 경우 | F33: 100 | G33: 100 | H33: 100 | L33: 제3조(건설기술진흥 기본계획)
A34: 8) | B34: =MID(진33,1,23) -> 제33조(등록취소처분 등을 받은 건설엔지니 | D34: 1) | E34: 등록취소처분 등을 받은 사실과 그 내용을 해당 건설 | M34: ① 국토교통부장관은 건설기술의 연구ㆍ개발을 촉진하고 그 성과를 효율적으로 이용하며 관련 산업의 진흥을 도모하기 위하여 건설기술진흥 기본계획을 5년마다 수립하여야 한다.
B35: =MID(진33,24,23) -> 어링사업자의 업무 계속) | C35: 제3항제10호 | E35: 엔지니어링의 발주자에게 통지하지 않은 경우 | F35: 300 | G35: 300 | H35: 300 | M35: ② 기본계획에는 다음 각 호의 사항이 포함되어야 한다.
B36: 제1항(등록취소처분 통지 의무)를 위반한 경우 | M36: 1. 건설기술 진흥의 기본목표 및 추진방향
A37: 9) | B37: =진38 -> 제38조(건설엔지니어링사업자의 지도ㆍ감독 등) | C37: 제3항제11호 | D37: 1) | E37: 지도ㆍ감독을 위하여 필요한 업무의 보고를 하지 않거나 | F37: 100 | G37: 150 | H37: 200 | M37: 2. 건설기술의 개발 촉진 및 활용을 위한 시책
B38: 제2항(감독기관에 자료제출 의무)를 위반한 경우 | E38: 관계 자료를 제출하지 않은 경우 | M38: 3. 건설기술에 관한 정보 관리
A39: 10) | B39: =진392 -> 제39조의2(시공단계의 건설사업관리계획 등) | C39: 제1항제1호 | D39: 1) | E39: 건설사업관리계획을 수립하지 않은 경우 | F39: 1000 | G39: 1500 | H39: 2000 | M39: 4. 건설기술인력의 수급ㆍ활용 및 기술능력의 향상
B40: 제1항(건설사업관리계획수립 의무)를 위반한 경우 | M40: 5. 건설기술연구기관의 육성
...

Sheet 안전관리계획
P1: 메인화면 | Q1: 산안법 | R1: 과태료
B2: 안전관리계획서
C4: ※ 진흥법 시행령 제98조,제101조의2로 정하는 규모의 건설공사는 안전관리계획서를 작성하여야 한다.
C5: ※ 유해위험방지계획서 제출대상 현장의 경우 유해위험방지계획서와 안전관리계획서를 통합 작성할 수 있다.
B8: 건설기술진흥법
B10: 제62조(건설공사의 안전관리)
C11: ① 건설사업자와 주택건설등록업자는 대통령령으로 정하는 건설공사를 시행하는 경우 안전점검 및 안전관리조직 등 건설공사의
D12: 안전관리계획(이하 “안전관리계획”이라 한다)을 수립하고, 착공 전에 이를 발주자에게 제출하여 승인을 받아야 한다.
D13: 이 경우 발주청이 아닌 발주자는 미리 안전관리계획의 사본을 인ㆍ허가기관의 장에게 제출하여 승인을 받아야 한다.
B16: 건설기술진흥법 시행령
B18: 제98조(안전관리계획의 수립)
C19: ① 법 제62조제1항에 따른 안전관리계획을 수립해야 하는 건설공사는 다음 각 호와 같다.
D20: 이 경우 원자력시설공사는 제외하며, 해당 건설공사가 「산업안전보건법」 제42조에 따른 유해위험방지계획을 수립해야 하는
D21: 건설공사에 해당하는 경우에는 해당 계획과 안전관리계획을 통합하여 작성할 수 있다.
D22: 1. 「시설물의 안전 및 유지관리에 관한 특별법」 제7조제1호 및 제2호에 따른 1종시설물 및 2종시설물의 건설공사
E23: (같은 법 제2조제11호에 따른 유지관리를 위한 건설공사는 제외한다)
D24: 2. 지하 10미터 이상을 굴착하는 건설공사. 이 경우 굴착 깊이 산정 시 집수정(물저장고), 엘리베이터 피트 및 정화조 등의
E25: 굴착 부분은 제외하며, 토지에 높낮이 차가 있는 경우 굴착 깊이의 산정방법은 「건축법 시행령」 제119조제2항을 따른다.
D26: 3. 폭발물을 사용하는 건설공사로서 20미터 안에 시설물이 있거나 100미터 안에 사육하는 가축이 있어 해당 건설공사로
E27: 인한 영향을 받을 것이 예상되는 건설공사
D28: 4. 10층 이상 16층 미만인 건축물의 건설공사
D29: 4의2. 다음 각 목의 리모델링 또는 해체공사
E30: 가. 10층 이상인 건축물의 리모델링 또는 해체공사
E31: 나. 「주택법」 제2조제25호다목에 따른 수직증축형 리모델링
D32: 5. 「건설기계관리법」 제3조에 따라 등록된 다음 각 목의 어느 하나에 해당하는 건설기계가 사용되는 건설공사
E33: 가. 천공기(높이가 10미터 이상인 것만 해당한다)
E34: 나. 항타 및 항발기
E35: 다. 타워크레인
D36: 5의2. 제101조의2제1항 각 호의 가설구조물을 사용하는 건설공사
D37: 6. 제1호부터 제4호까지, 제4호의2, 제5호 및 제5호의2의 건설공사 외의 건설공사로서 다음 각 목의 어느 하나에 해당하는 공사
E38: 가. 발주자가 안전관리가 특히 필요하다고 인정하는 건설공사
E39: 나. 해당 지방자치단체의 조례로 정하는 건설공사 중에서 인ㆍ허가기관의 장이 안전관리가 특히 필요하다고 인정하는 건설공사
B41: 제101조의2(가설구조물의 구조적 안전성 확인)
C42: ① 법 제62조제11항에 따라 건설사업자 또는 주택건설등록업자가 같은 항에 따른 관계전문가로부터 구조적 안전성을
D43: 확인받아야 하는 가설구조물은 다음 각 호와 같다.
D44: 1. 높이가 31미터 이상인 비계
D45: 1의2. 브라켓(bracket) 비계
D46: 2. 작업발판 일체형 거푸집 또는 높이가 5미터 이상인 거푸집 및 동바리
D47: 3. 터널의 지보공(支保工) 또는 높이가 2미터 이상인 흙막이 지보공
D48: 4. 동력을 이용하여 움직이는 가설구조물
...

Sheet 안전점검
BF1: 메인화면 | BG1: 산안법 | BH1: 과태료
B2: 안전점검
D3: ※ 법적근거 : 안전관리계획서 -건설기술 진흥법 시행령 제98조(안전관리계획의 수립) 참조
B6: 건설기술진흥법
B7: 제62조(건설공사의 안전관리)
C8: ① 건설사업자와 주택건설등록업자는 대통령령으로 정하는 건설공사를 시행하는 경우 안전점검 및 안전관리조직 등 | AV8: (안전관리계획서- 시행령 제98조 참조)
D9: 건설공사의 안전관리계획을 수립하고, 착공 전에 이를 발주자에게 제출하여 승인을 받아야 한다.
C10: ② 제1항에 따라 안전관리계획을 제출받은 발주청 또는 인ㆍ허가기관의 장은 안전관리계획의 내용을 검토하여 그 결과를
D11: 건설사업자와 주택건설등록업자에게 통보하여야 한다.
C12: ③ 발주청 또는 인ㆍ허가기관의 장은 제1항에 따라 제출받아 승인한 안전관리계획서 사본과 제2항에 따른 검토결과를
D13: 국토교통부장관에게 제출하여야 한다.
C14: ④ 건설사업자와 주택건설등록업자는 안전관리계획에 따라 안전점검을 하여야 한다. 이 경우 대통령령으로 정하는 안전점검에 | AV14: (시행령 제100조의2 참조-미첨부)
D15: 대해서는 발주자가 대통령령으로 정하는 바에 따라 안전점검을 수행할 기관을 지정하여 그 업무를 수행하여야 한다. | AV15: (안전관리계획서- 시행령 제98조 참조)
C16: ⑤ 건설사업자와 주택건설등록업자는 제4항에 따라 실시한 안전점검 결과를 국토교통부장관에게 제출하여야 한다.
C17: ⑥ 안전관리계획의 수립 기준, 제출ㆍ승인의 방법 및 절차, 안전점검의 시기ㆍ방법 및 안전점검 대가(代價) 등에 필요한
D18: 사항은 대통령령으로 정한다. | AV18: (안전관리계획서- 시행령 제98조 참조)
C19: ⑦ 건설사업자나 주택건설등록업자는 안전관리계획을 수립하였던 건설공사를 준공하였을 때에는 대통령령으로 정하는 방법 | AV19: (시행령 제100조 참조-미첨부)
D20: 및 절차에 따라 안전점검에 관한 종합보고서(이하 “종합보고서”라 한다)를 작성하여 발주청에게 제출하여야 한다.
C21: ⑧ 제7항에 따라 종합보고서를 받은 발주청 또는 인ㆍ허가기관의 장은 대통령령으로 정하는 바에 따라 종합보고서를
D22: 국토교통부장관에게 제출하여야 한다.
C23: ⑨ 국토교통부장관, 발주청 및 인ㆍ허가기관의 장은 제7항 및 제8항에 따라 받은 종합보고서를 대통령령으로 정하는 바에 따라
D24: 보존ㆍ관리하여야 한다.
C25: ⑪ 건설사업자 또는 주택건설등록업자는 동바리, 거푸집, 비계 등 가설구조물 설치를 위한 공사를 할 때 대통령령으로 정하는 바에
D26: 따라 가설구조물의 구조적 안전성을 확인하기에 적합한 분야의 기술사에게 확인을 받아야 한다.
C27: ⑫ 관계전문가는 가설구조물이 안전에 지장이 없도록 가설구조물의 구조적 안전성을 확인하여야 한다.
C28: ⑬ 국토교통부장관은 건설공사의 안전을 확보하기 위하여 건설공사에 참여하는 다음 각 호의 자가 갖추어야 하는 안전관리체계와
D29: 수행하여야 하는 안전관리 업무 등을 정하여 고시하여야 한다. | AV29: 건설공사 안전관리 업무수행 지침
B34: 건설공사 안전관리 업무수행 지침
B35: 제21조(안전점검의 실시시기)
C36: ① 시공자는 자체안전점검 및 정기안전점검의 실시시기 및 횟수를 다음 각 호의 기준에 따라 안전점검
D37: 계획에 반영하고 그에 따라 안전점검을 실시하여야 한다.
D38: 1. 자체안전점검 : 건설공사의 공사기간동안 매일 공종별 실시
D39: 2. 정기안전점검 : 별표 1의 정기안전점검 실시시기를 기준으로 실시. 다만, 발주자는 안전관리계획의
E40: 내용을 검토할 때 건설공사의 규모, 기간, 현장여건에 따라 점검시기 및 횟수를 조정할 수 있다.
C41: ② 정밀안전점검은 정기안전점검결과 건설공사의 물리적·기능적 결함 등이 발견되어 보수·보강 등의
D42: 조치를 취하기 위하여 필요한 경우에 실시한다.
C43: ③ 초기점검은 영 제98조제1항제1호에 따른 건설공사를 준공하기 전에 실시한다.
C44: ④ 공사재개 전 안전점검은 영 제98조제1항에 따른 건설공사를 시행하는 도중 그 공사의 중단으로 1년 이상
D45: 방치된 시설물이 있는 경우 그 공사를 재개하기 전에 실시한다.
B47: 제22조(자체안전점검의 실시)
...

Sheet 건산법과태료
A1: 「건설산업기본법」위반 시 주요 과태료 부과 기준 | M1: 메인화면
J2: Click Me~! | N2: 별표26 행정처분까지 정리하여 파일 완성
A3: 「건설기술진흥법 시행령 별표 7」 | H3: [1년간 누적관리] | J3: 필독~!
A4: 위 반 내 용 | C4: 법 조 문 | D4: 세 부 내 용 | F4: 과 태 료(만원) | M4: 산업안전보건기준
E5: 좀더 디테일하게 위반내용 정리필요 | F5: 1차위반 | G5: 2차위반 | H5: 3차이상
A6: 1 | B6: 제9조의2(등록증의 발급 등) | C6: 제100조 | D6: 1) | E6: 기재사항이 변경된 후 30일이내에 국토교통부 장관에게 | F6: 30 | G6: 50 | H6: 50 | J6: 건설산업기본법
B7: 제2항(기재사항 변경신청 의무)를 위반한 경우 | C7: 제1호 | E7: 기재사항의 변경신청을 하지 않은 경우
A8: 2 | B8: 제9조의3(건설업의 교육) | C8: 제99조 | D8: 1) | E8: 국토교통부장관이 실시하는 교육을 이수하지 않은 경우 | F8: 100 | G8: 100 | H8: 100 | J8: 제2장 총칙
B9: 제1항(건설업 윤리교육 등 이수 의무) 위반 | C9: 제12호 | E9: (건설업 윤리교육 및 실무관련 교육) | J9: 제1조(목적)
A10: 3 | B10: 제14조(영업정지처분 등을 받은 후 계속 공사) | C10: 제1호 | D10: 1) | E10: 처분내용을 발주자에게 통지하지 않은 경우 | F10: 300 | G10: 500 | H10: 500 | K10: 이 법은 건설공사의 조사, 설계, 시공, 감리, 유지관리, 기술관리 등에 관한 기본적인 사항과 건설업의 등록 및 건설공사의 도급 등에 필요한 사항을 정함으로써 건설공사의 적정한 시공과 건설산업의 건전한 발전을 도모함을 목적으로 한다.
B11: 제2항(처분내용의 통지 의무)를 위반한 경우 | E11: (영업정지, 등록말소, 폐업 등)
A12: 4 | B12: 제22조(건설공사에 관한 도급계약의 원칙) | D12: 1) | E12: 도급계약을 계약서로 체결하지 않은 경우 | F12: 150 | G12: 150 | H12: 150 | J12: 제2조(정의)
B13: 제2항(도급계약 체결 및 계약서에 필수사항 기재 | C13: 제2호 | K13: 이 법에서 사용하는 용어의 뜻은 다음과 같다.
B14: 의무)를 위반한 경우 | D14: 2) | E14: 도급계약시 필수사항을 명시하지 않고 계약한 경우 | F14: 50 | G14: 50 | H14: 50 | K14: 1. “건설산업”이란 건설업과 건설용역업을 말한다.
B15: 제6항(건설공사 대장 작성 및 통보 의무)를 위반한 | C15: 제3호 | D15: 1) | E15: 건설공사대장 기재사항을 해당공사 완료일까지 발주자에게 | F15: 100 | G15: 200 | H15: 400 | K15: 2. “건설업”이란 건설공사를 하는 업(業)을 말한다.
B16: 경우 | E16: 통보하지 않거나 거짓으로 통보한 경우 | K16: 3. “건설용역업”이란 건설공사에 관한 조사, 설계, 감리, 사업관리, 유지관리 등 건설공사와 관련된 용역(이하 “건설용역”이라 한다)을 하는 업(業)을 말한다.
B17: 제8항(공동도급 약정서 통보 의무)를 위반한 경우 | C17: 제3호의2 | D17: 1) | E17: 통보를 하지 않거나 통보기한을 위반한 경우 | F17: 100 | G17: 200 | H17: 300 | K17: 4. “건설공사”란 토목공사, 건축공사, 산업설비공사, 조경공사, 환경시설공사, 그 밖에 명칭과 관계없이 시설물을 설치ㆍ유지ㆍ보수하는공사(시설물을 설치하기 위한 부지조성공사를 포함한다) 및 기계설비나 그 밖의 구조물의 설치 및 해체공사 등을 말한다. 다만, 다음 각 목의 어느 하나에 해당하는 공사는 포함하지 아니한다.
A18: 5 | B18: 제22조의2(공사대금지급의 보증 등) | C18: 제3호의3 | D18: 1) | E18: 공사대금의 지급보증, 담보의 제공 또는 보험료등의 지급을 | F18: 100 | G18: 200 | H18: 300 | K18: 가. 「전기공사업법」에 따른 전기공사
B19: 제2항(보증이행 의무) | E19: 정당한 사유 없이 이행하지 않은 경우 | K19: 나. 「정보통신공사업법」에 따른 정보통신공사
A20: 6 | B20: 제25조(수급인 등의 자격 제한) | C20: 제14호 | D20: 1) | E20: 벌점기준을 초과한 경우 | F20: 300 | G20: 300 | H20: 300 | K20: 다. 「소방시설공사업법」에 따른 소방시설공사
B21: 제5항(벌점 관리) | K21: 라. 「문화재 수리 등에 관한 법률」에 따른 문화재 수리공사
A22: 7 | B22: 제28조의2(건설공사의 직접 시공) | C22: 제4호 | D22: 1) | E22: 직접시공계획을 통보하지 않은 경우 | F22: 100 | G22: 150 | H22: 150 | K22: 5. “종합공사”란 종합적인 계획, 관리 및 조정을 하면서 시설물을 시공하는 건설공사를 말한다.
B23: 제2항(직접시공계획서 제출 의무)를 위반한 경우 | K23: 6. “전문공사”란 시설물의 일부 또는 전문 분야에 관한 건설공사를 말한다.
A24: 8 | B24: 제29조(건설공사의 하도급 제한) | C24: 제5호 | D24: 1) | E24: 재하도급 사항이 발생한 경우 재하도급 계약 내용을 | F24: 100 | G24: 150 | H24: 150 | K24: 7. “건설사업자”란 이 법 또는 다른 법률에 따라 등록 등을 하고 건설업을 하는 자를 말한다.
B25: 제6항(재하도급의 일부 허용) | E25: 발주자에게 통보를 하지 않은 경우 | K25: 8. “건설사업관리”란 건설공사에 관한 기획, 타당성 조사, 분석, 설계, 조달, 계약, 시공관리, 감리, 평가 또는 사후관리 등에 관한 관리를 수행하는 것을 말한다.
A26: 9 | B26: 제29조의2(건설공사의 하도급관리) | C26: 제98조의2 | D26: 1) | E26: 관리의무를 이행하지 않은 경우 | F26: 500 | G26: 1000 | H26: 1500 | K26: 9. “시공책임형 건설사업관리”란 종합공사를 시공하는 업종을 등록한 건설사업자가 건설공사에 대하여 시공 이전 단계에서 건설사업관리 업무를 수행하고 아울러 시공 단계에서 발주자와 시공 및 건설사업관리에 대한 별도의 계약을 통하여 종합적인 계획, 관리 및 조정을 하면서 미리 정한 공사 금액과 공사기간 내에 시설물을 시공하는 것을 말한다.
B27: 제1항(수급인의 하수급인 관리 의무)를 위반한 경우 | C27: 제1호 | E27: (하수급인의 영업정지 등 행정처분 위반행위를 묵인한 경우) | K27: 10. “발주자”란 건설공사를 건설사업자에게 도급하는 자를 말한다. 다만, 수급인으로서 도급받은 건설공사를 하도급하는 자는 제외한다.
C28: 제99조 | D28: 2) | E28: 관리의무를 이행하지 않은 경우 | K28: 11. “도급”이란 원도급, 하도급, 위탁 등 명칭과 관계없이 건설공사를 완성할 것을 약정하고, 상대방이 그 공사의 결과에 대하여 대가를 지급할 것을 약정하는 계약을 말한다.
E29: (하수급인의 영업정지 등 행정처분을 받은 경우 하수급인 | F29: 100 | G29: 150 | H29: 150 | K29: 12. “하도급”이란 도급받은 건설공사의 전부 또는 일부를 다시 도급하기 위하여 수급인이 제3자와 체결하는 계약을 말한다.
C30: 제6호 | E30: 의 현장배치기술자의 소속 확인 미이행 등) | K30: 13. “수급인”이란 발주자로부터 건설공사를 도급받은 건설사업자를 말하고, 하도급의 경우 하도급하는 건설사업자를 포함한다.
A31: =MAX(A$6:A30)+1 -> 10 | B31: 제31조의2(하도급계획의제출) | C31: 제7호 | D31: 1) | E31: 하도급계획서를 정당한 사유 없이 이행하지 않은 경우 | F31: 300 | G31: 300 | H31: 300 | K31: 14. “하수급인”이란 수급인으로부터 건설공사를 하도급받은 자를 말한다.
B32: 제1항(하도급게획서 제출 의무) 불이행 | K32: 15. “건설기술인”이란 관계 법령에 따라 건설공사에 관한 기술이나 기능을 가졌다고 인정된 사람을 말한다.
A33: =MAX(A$6:A32)+1 -> 11 | B33: 제31조의3(하도급공사 계약자료 등의 공개) | C33: 제7호의2 | D33: 1) | E33: 하도급공사와 관련된 사항을 알리지 않거나 정당한 사유 | F33: 100 | G33: 200 | H33: 300
B34: 제2항(하도급 수의계약시 사전 통보 의무) 위반 | E34: 없이 알린 내용과 다르게 계약을 체결한 경우 | J34: 제3조(기본이념)
A35: =MAX(A$6:A34)+1 -> 12 | B35: 제34조(하도급대금의 지급 등) | C35: 제8호 | D35: 1) | E35: 도급대금 등을 지급하지 아니하여 법 제81조제4호에 따라 | F35: 300 | G35: 500 | H35: 500 | K35: 이 법은 건설산업이 설계, 감리, 시공, 사업관리, 유지관리 등의 분야에 걸쳐 국제경쟁력을 갖출 수 있도록 이를 균형 있게 발전시킴으로써 국민경제와 국민의 생활안전에 이바지함을 기본이념으로 한다.
B36: 제1항(기성수령후 15일 이내 지급 의무) 위반시 | E36: 시정명령을 받고 이에 따르지 않은 경우
A37: =MAX(A$6:A36)+1 -> 13 | B37: 제36조의2(추가.변경공사에 대한 서면 확인 등) | C37: 제13호 | D37: 1) | E37: 추가ㆍ변경공사에 대하여 서면으로 요구하지 않은 경우 | F37: 100 | G37: 100 | H37: 100 | J37: 제4조(다른 법률과의 관계)
B38: 제1항(추가,변경공사 요구 의무) | K38: 건설산업에 관하여 다른 법률에서 정하고 있는 경우를 제외하고는 이 법을 적용한다. 다만, 건설공사의 범위와 건설업 등록에 관한 사항에 대하여는 다른 법률의 규정에도 불구하고 이 법을 우선 적용하고, 건설용역업에 대하여는 제6조 및 제26조와 제8장(제69조부터 제79조까지, 제79조의2 및 제80조)을 적용한다.
A39: =MAX(A$6:A38)+1 -> 14 | B39: 제40조(건설기술인의 배치) | C39: 제100조 | D39: 1) | E39: 건설기술인이 건설공사의 현장을 사전 승인 없이 | F39: 50 | G39: 50 | H39: 50
B40: 제2항(현장기술자의 현장이탈 금지) 를 위반한 경우 | C40: 제2호 | E40: 이탈한 경우 | J40: 제5조(외국 건설사업자에 대한 기준의 설정)
...
