Workbook
Name __?Crite: #REF!
Name __?Criteria: #REF!
Name ____AA1: #REF!
Name ____qw1: #REF!
Name ____qw2: #REF!
Name ____qw3: #REF!
Name ____qw4: #REF!
Name ____qw5: #REF!
Name ____qw6: #REF!
Name ____qww1: #REF!
Name ____qww2: #REF!
Name ____qww3: #REF!
Name ____qww5: #REF!
Name ____qww6: #REF!
Name ____qww7: #REF!
Name ____qww8: #REF!
Name ____qww9: #REF!
Name ____ST1: #N/A
Name ___A100000: #N/A
Name ___A66000: #N/A
Name ___A67000: #N/A
Name ___A68000: #N/A
Name ___A80000: #N/A
Name ___C100000: #REF!
Name ___SH2: #N/A
Name ___SH3: #N/A
Name ___ST1: #N/A
Name ___zz1: #N/A
Name __A100000: #N/A
Name __A66000: #N/A
Name __A67000: #N/A
Name __A68000: #N/A
Name __A80000: #N/A
Name __AA1: #REF!
Name __C100000: #REF!
Name __CDT2: #REF!
Name __DAN1: #REF!
Name __DAN10: #REF!
Name __DAN100: #REF!
Name __DAN101: #REF!
Name __DAN102: #REF!
Name __DAN103: #REF!
Name __DAN104: #REF!
Name __DAN105: #REF!
Name __DAN106: #REF!
Name __DAN107: #REF!
Name __DAN108: #REF!
Name __DAN109: #REF!
Name __DAN11: #REF!
Name __DAN110: #REF!
Name __DAN111: #REF!
Name __DAN112: #REF!
Name __DAN113: #REF!
Name __DAN114: #REF!
Name __DAN115: #REF!
Name __DAN116: #REF!
Name __DAN117: #REF!
Name __DAN118: #REF!
Name __DAN119: #REF!
Name __DAN12: #REF!

Sheet 1. 현장별 인원현황
C3: 순번 | D3: 현장명 | E3: 이름 | F3: 나이 | G3: 주민등록번호 | H3: 성별 | I3: 직책 | J3: 직급 | K3: 단가/급여 | L3: 연락처 | M3: 시/도 | N3: 시,군,구 | O3: 경력 | P3: 주요경력 | Q3: 평가등급 | S3: 자격증 / 경력수첩 보유현황 | W3: 당사 근무이력 (직전현장) | AA3: 타사 근무이력 (직전현장) | AM3: S
Q4: 기능 | R4: 안전 | S4: 전기 | T4: 통신 | U4: 소방 | V4: 안전 | W4: 건설사 | X4: 현장명 | Y4: 용도 | Z4: 비고 | AA4: 건설사 | AB4: 현장명 | AC4: 타회사명 | AD4: 용도 | AE4: 비고 | AM4: A
B6: 24018 | C6: =ROW()-5 -> 1 | D6: =IFERROR(" "&VLOOKUP(B6,현장리스트!$B:$C,2,0),"-") -> [1.DL건설] 전도관구역 주택재개발 정비사업조합(01공구) | E6: 강민 | F6: =IFERROR(DATEDIF(MID(G6,1,2)&"-"&MID(G6,3,2)&"-"&MID(G6,5,2),TODAY(),"y")&"세","") -> 37세 | G6: 880409-1170112 | H6: =IF(G6="","",IF(LEN(G6)<14,"에러",IF(LEN(G6)<14,"에러",IF(ISODD(MID(G6,8,1)),"남","여")))) -> 남 | I6: 공무 | J6: 과장 | K6: 4500000 | L6: 010-9316-4142 | M6: 인천 | N6: 미추홀구 | O6: 4년 | P6: APT/오피스텔 | Q6: =VLOOKUP(C6,'2-1. 인사고과표(기능)'!B:AS,44,0) -> S | R6: =VLOOKUP(C6,'2-2. 인사고과표(안전)'!B:AO,40,0) -> S | AA6: DL E&C | AB6: 문정 힐스테이트 e편한세상 | AC6: 세원전설 | AD6: APT/오피스텔 | AM6: 초급
B7: 24018 | C7: =ROW()-5 -> 2 | D7: =IFERROR(" "&VLOOKUP(B7,현장리스트!$B:$C,2,0),"-") -> [1.DL건설] 전도관구역 주택재개발 정비사업조합(01공구) | E7: 오재욱 | F7: =IFERROR(DATEDIF(MID(G7,1,2)&"-"&MID(G7,3,2)&"-"&MID(G7,5,2),TODAY(),"y")&"세","") -> 32세 | G7: 930413-1157015 | H7: =IF(G7="","",IF(LEN(G7)<14,"에러",IF(LEN(G7)<14,"에러",IF(ISODD(MID(G7,8,1)),"남","여")))) -> 남 | I7: 안전관리자 | J7: 대리 | K7: 3800000 | L7: 010-3133-5930 | M7: 인천 | N7: 서구 | O7: 3년 | P7: APT/오피스텔 | Q7: =VLOOKUP(C7,'2-1. 인사고과표(기능)'!B:AS,44,0) -> A | R7: =VLOOKUP(C7,'2-2. 인사고과표(안전)'!B:AO,40,0) -> S | U7: 중급 | V7: 기사 | W7: 대우건설 | X7: 인천 경서3구역 오피스텔 신축공사 전기설비공사(1공구) | Y7: APT/오피스텔
B8: 24018 | C8: =ROW()-5 -> 3 | D8: =IFERROR(" "&VLOOKUP(B8,현장리스트!$B:$C,2,0),"-") -> [1.DL건설] 전도관구역 주택재개발 정비사업조합(01공구) | E8: 조경호 | F8: =IFERROR(DATEDIF(MID(G8,1,2)&"-"&MID(G8,3,2)&"-"&MID(G8,5,2),TODAY(),"y")&"세","") -> 57세 | G8: 680402-1645912 | H8: =IF(G8="","",IF(LEN(G8)<14,"에러",IF(LEN(G8)<14,"에러",IF(ISODD(MID(G8,8,1)),"남","여")))) -> 남 | I8: 공사 | J8: 차장 | K8: 230000 | L8: 010-3686-8154 | M8: 경기 | N8: 고양 | O8: 35년 | P8: APT/오피스텔 | Q8: =VLOOKUP(C8,'2-1. 인사고과표(기능)'!B:AS,44,0) -> S | R8: =VLOOKUP(C8,'2-2. 인사고과표(안전)'!B:AO,40,0) -> S | W8: 시티건설 | X8: 남악오룡 36BL 시티프라디움 신축공사(전기,통신공사) | Y8: APT/오피스텔
B9: 24018 | C9: =ROW()-5 -> 4 | D9: =IFERROR(" "&VLOOKUP(B9,현장리스트!$B:$C,2,0),"-") -> [1.DL건설] 전도관구역 주택재개발 정비사업조합(01공구) | E9: 남춘섭 | F9: =IFERROR(DATEDIF(MID(G9,1,2)&"-"&MID(G9,3,2)&"-"&MID(G9,5,2),TODAY(),"y")&"세","") -> 62세 | G9: 630504-1347624 | H9: =IF(G9="","",IF(LEN(G9)<14,"에러",IF(LEN(G9)<14,"에러",IF(ISODD(MID(G9,8,1)),"남","여")))) -> 남 | I9: 공사 | J9: 과장 | K9: 5000000 | L9: 010-4353-1100 | M9: 인천 | N9: 계양구 | O9: 30년 | P9: APT/오피스텔 | Q9: =VLOOKUP(C9,'2-1. 인사고과표(기능)'!B:AS,44,0) -> S | R9: =VLOOKUP(C9,'2-2. 인사고과표(안전)'!B:AO,40,0) -> S | W9: DL건설 | X9: E편한세상 주안 에듀서밋 (인천우진주택재건축) | Y9: APT/오피스텔
B10: 24018 | C10: =ROW()-5 -> 5 | D10: =IFERROR(" "&VLOOKUP(B10,현장리스트!$B:$C,2,0),"-") -> [1.DL건설] 전도관구역 주택재개발 정비사업조합(01공구) | E10: 김옥수 | F10: =IFERROR(DATEDIF(MID(G10,1,2)&"-"&MID(G10,3,2)&"-"&MID(G10,5,2),TODAY(),"y")&"세","") -> 57세 | G10: 690128-1536612 | H10: =IF(G10="","",IF(LEN(G10)<14,"에러",IF(LEN(G10)<14,"에러",IF(ISODD(MID(G10,8,1)),"남","여")))) -> 남 | I10: 기능공 | J10: 전공 | K10: 200000 | L10: 010-9375-6729 | M10: 경기 | N10: 부천 | O10: 15년 | P10: APT/오피스텔 | Q10: =VLOOKUP(C10,'2-1. 인사고과표(기능)'!B:AS,44,0) -> S | R10: =VLOOKUP(C10,'2-2. 인사고과표(안전)'!B:AO,40,0) -> S | W10: DL건설 | X10: E편한세상 주안 에듀서밋 (인천우진주택재건축) | Y10: APT/오피스텔
B11: 24018 | C11: =ROW()-5 -> 6 | D11: =IFERROR(" "&VLOOKUP(B11,현장리스트!$B:$C,2,0),"-") -> [1.DL건설] 전도관구역 주택재개발 정비사업조합(01공구) | E11: 박예만 | F11: =IFERROR(DATEDIF(MID(G11,1,2)&"-"&MID(G11,3,2)&"-"&MID(G11,5,2),TODAY(),"y")&"세","") -> 37세 | G11: 881220-1156015 | H11: =IF(G11="","",IF(LEN(G11)<14,"에러",IF(LEN(G11)<14,"에러",IF(ISODD(MID(G11,8,1)),"남","여")))) -> 남 | I11: 기능공 | J11: 전공 | K11: 170000 | L11: 010-2400-8866 | M11: 인천 | N11: 동구 | O11: 2년 | P11: APT/오피스텔 | Q11: =VLOOKUP(C11,'2-1. 인사고과표(기능)'!B:AS,44,0) -> A | R11: =VLOOKUP(C11,'2-2. 인사고과표(안전)'!B:AO,40,0) -> S | W11: 두산건설 | X11: 여의구역 본계약 전기공사 | Y11: APT/오피스텔
B12: 24018 | C12: =ROW()-5 -> 7 | D12: =IFERROR(" "&VLOOKUP(B12,현장리스트!$B:$C,2,0),"-") -> [1.DL건설] 전도관구역 주택재개발 정비사업조합(01공구) | E12: 유동민 | F12: =IFERROR(DATEDIF(MID(G12,1,2)&"-"&MID(G12,3,2)&"-"&MID(G12,5,2),TODAY(),"y")&"세","") -> 54세 | G12: 710711-1148119 | H12: =IF(G12="","",IF(LEN(G12)<14,"에러",IF(LEN(G12)<14,"에러",IF(ISODD(MID(G12,8,1)),"남","여")))) -> 남 | I12: 기능공 | J12: 전공 | K12: 210000 | L12: 010-9558-2660 | M12: 인천 | N12: 연수구 | O12: 15년 | P12: APT/오피스텔 | Q12: =VLOOKUP(C12,'2-1. 인사고과표(기능)'!B:AS,44,0) -> S | R12: =VLOOKUP(C12,'2-2. 인사고과표(안전)'!B:AO,40,0) -> S | W12: 금호건설 | X12: 홍천 금호어울림 더퍼스트 | Y12: APT/오피스텔
B13: 24018 | C13: =ROW()-5 -> 8 | D13: =IFERROR(" "&VLOOKUP(B13,현장리스트!$B:$C,2,0),"-") -> [1.DL건설] 전도관구역 주택재개발 정비사업조합(01공구) | E13: 윤효상 | F13: =IFERROR(DATEDIF(MID(G13,1,2)&"-"&MID(G13,3,2)&"-"&MID(G13,5,2),TODAY(),"y")&"세","") -> 56세 | G13: 700311-1168319 | H13: =IF(G13="","",IF(LEN(G13)<14,"에러",IF(LEN(G13)<14,"에러",IF(ISODD(MID(G13,8,1)),"남","여")))) -> 남 | I13: 기능공 | J13: 전공 | K13: 200000 | L13: 010-5354-1747 | M13: 서울 | N13: 구로구 | O13: 15년 | P13: APT/오피스텔 | Q13: =VLOOKUP(C13,'2-1. 인사고과표(기능)'!B:AS,44,0) -> A | R13: =VLOOKUP(C13,'2-2. 인사고과표(안전)'!B:AO,40,0) -> S
B14: 24018 | C14: =ROW()-5 -> 9 | D14: =IFERROR(" "&VLOOKUP(B14,현장리스트!$B:$C,2,0),"-") -> [1.DL건설] 전도관구역 주택재개발 정비사업조합(01공구) | E14: 이봉운 | F14: =IFERROR(DATEDIF(MID(G14,1,2)&"-"&MID(G14,3,2)&"-"&MID(G14,5,2),TODAY(),"y")&"세","") -> 44세 | G14: 810409-5141094 | H14: =IF(G14="","",IF(LEN(G14)<14,"에러",IF(LEN(G14)<14,"에러",IF(ISODD(MID(G14,8,1)),"남","여")))) -> 남 | I14: 기능공 | J14: 전공 | K14: 170000 | L14: 010-8480-2777 | M14: 인천 | N14: 연수구 | O14: 5년 | P14: APT/오피스텔 | Q14: =VLOOKUP(C14,'2-1. 인사고과표(기능)'!B:AS,44,0) -> A | R14: =VLOOKUP(C14,'2-2. 인사고과표(안전)'!B:AO,40,0) -> S | W14: DL건설 | X14: E편한세상 주안 에듀서밋 (인천우진주택재건축) | Y14: APT/오피스텔
B15: 24018 | C15: =ROW()-5 -> 10 | D15: =IFERROR(" "&VLOOKUP(B15,현장리스트!$B:$C,2,0),"-") -> [1.DL건설] 전도관구역 주택재개발 정비사업조합(01공구) | E15: 이상열 | F15: =IFERROR(DATEDIF(MID(G15,1,2)&"-"&MID(G15,3,2)&"-"&MID(G15,5,2),TODAY(),"y")&"세","") -> 53세 | G15: 720902-1052520 | H15: =IF(G15="","",IF(LEN(G15)<14,"에러",IF(LEN(G15)<14,"에러",IF(ISODD(MID(G15,8,1)),"남","여")))) -> 남 | I15: 기능공 | J15: 전공 | K15: 220000 | L15: 010-3123-0472 | M15: 인천 | N15: 부평구 | O15: 30년 | P15: APT/오피스텔 | Q15: =VLOOKUP(C15,'2-1. 인사고과표(기능)'!B:AS,44,0) -> S | R15: =VLOOKUP(C15,'2-2. 인사고과표(안전)'!B:AO,40,0) -> S | W15: 대우건설 | X15: 천안성성2지구 A1BL 공동주택 | Y15: APT/오피스텔
B16: 24018 | C16: =ROW()-5 -> 11 | D16: =IFERROR(" "&VLOOKUP(B16,현장리스트!$B:$C,2,0),"-") -> [1.DL건설] 전도관구역 주택재개발 정비사업조합(01공구) | E16: 이후승 | F16: =IFERROR(DATEDIF(MID(G16,1,2)&"-"&MID(G16,3,2)&"-"&MID(G16,5,2),TODAY(),"y")&"세","") -> 27세 | G16: 980727-1156212 | H16: =IF(G16="","",IF(LEN(G16)<14,"에러",IF(LEN(G16)<14,"에러",IF(ISODD(MID(G16,8,1)),"남","여")))) -> 남 | I16: 기능공 | J16: 전공 | K16: 200000 | L16: 010-7567-0472 | M16: 인천 | N16: 부평구 | O16: 7년 | P16: APT/오피스텔 | Q16: =VLOOKUP(C16,'2-1. 인사고과표(기능)'!B:AS,44,0) -> S | R16: =VLOOKUP(C16,'2-2. 인사고과표(안전)'!B:AO,40,0) -> S | W16: 대우건설 | X16: 천안성성2지구 A1BL 공동주택 | Y16: APT/오피스텔
B17: 24018 | C17: =ROW()-5 -> 12 | D17: =IFERROR(" "&VLOOKUP(B17,현장리스트!$B:$C,2,0),"-") -> [1.DL건설] 전도관구역 주택재개발 정비사업조합(01공구) | E17: 조해제 | F17: =IFERROR(DATEDIF(MID(G17,1,2)&"-"&MID(G17,3,2)&"-"&MID(G17,5,2),TODAY(),"y")&"세","") -> 62세 | G17: 630709-5101492 | H17: =IF(G17="","",IF(LEN(G17)<14,"에러",IF(LEN(G17)<14,"에러",IF(ISODD(MID(G17,8,1)),"남","여")))) -> 남 | I17: 기능공 | J17: 전공 | K17: 190000 | L17: 010-3903-1295 | M17: 서울 | N17: 영등포구 | O17: 20년 | P17: APT/오피스텔 | Q17: =VLOOKUP(C17,'2-1. 인사고과표(기능)'!B:AS,44,0) -> S | R17: =VLOOKUP(C17,'2-2. 인사고과표(안전)'!B:AO,40,0) -> S | W17: 대우건설 | X17: 인천 경서3구역 오피스텔 신축공사 전기설비공사(1공구) | Y17: APT/오피스텔
B18: 23013 | C18: =ROW()-5 -> 13 | D18: =IFERROR(" "&VLOOKUP(B18,현장리스트!$B:$C,2,0),"-") -> [1.대우건설] 고양향동 지원1BL 지식산업센터 신축공사 | E18: 홍병수 | F18: =IFERROR(DATEDIF(MID(G18,1,2)&"-"&MID(G18,3,2)&"-"&MID(G18,5,2),TODAY(),"y")&"세","") -> 44세 | G18: 810521-1047111 | H18: =IF(G18="","",IF(LEN(G18)<14,"에러",IF(LEN(G18)<14,"에러",IF(ISODD(MID(G18,8,1)),"남","여")))) -> 남 | I18: 공무 | J18: 과장 | K18: 4900000 | L18: 010-4599-6589 | M18: 서울 | N18: 마포구 | O18: 10 | P18: 일반건축물 | Q18: =VLOOKUP(C18,'2-1. 인사고과표(기능)'!B:AS,44,0) -> S | R18: =VLOOKUP(C18,'2-2. 인사고과표(안전)'!B:AO,40,0) -> S | W18: 은성산업 | X18: 부천 춘의동 지식산업센터 | Y18: 일반건축물 | Z18: 지식산업센터
B19: 23013 | C19: =ROW()-5 -> 14 | D19: =IFERROR(" "&VLOOKUP(B19,현장리스트!$B:$C,2,0),"-") -> [1.대우건설] 고양향동 지원1BL 지식산업센터 신축공사 | E19: 남치원 | F19: =IFERROR(DATEDIF(MID(G19,1,2)&"-"&MID(G19,3,2)&"-"&MID(G19,5,2),TODAY(),"y")&"세","") -> 63세 | G19: 630129-1634417 | H19: =IF(G19="","",IF(LEN(G19)<14,"에러",IF(LEN(G19)<14,"에러",IF(ISODD(MID(G19,8,1)),"남","여")))) -> 남 | I19: 공사 | J19: 차장 | K19: 5300000 | L19: 010-3994-8327 | M19: 인천 | N19: 서구 | O19: 40 | P19: 일반건축물 | Q19: =VLOOKUP(C19,'2-1. 인사고과표(기능)'!B:AS,44,0) -> S | R19: =VLOOKUP(C19,'2-2. 인사고과표(안전)'!B:AO,40,0) -> S | W19: 은성산업 | X19: 부천 춘의동 지식산업센터 | Y19: 일반건축물 | Z19: 지식산업센터
B20: 23013 | C20: =ROW()-5 -> 15 | D20: =IFERROR(" "&VLOOKUP(B20,현장리스트!$B:$C,2,0),"-") -> [1.대우건설] 고양향동 지원1BL 지식산업센터 신축공사 | E20: 문대준 | F20: =IFERROR(DATEDIF(MID(G20,1,2)&"-"&MID(G20,3,2)&"-"&MID(G20,5,2),TODAY(),"y")&"세","") -> 58세 | G20: 671117-1522229 | H20: =IF(G20="","",IF(LEN(G20)<14,"에러",IF(LEN(G20)<14,"에러",IF(ISODD(MID(G20,8,1)),"남","여")))) -> 남 | I20: 공사 | J20: 차장 | K20: 200000 | L20: 010-4708-2293 | M20: 인천 | N20: 부평구 | O20: 21 | P20: 일반건축물 | Q20: =VLOOKUP(C20,'2-1. 인사고과표(기능)'!B:AS,44,0) -> S | R20: =VLOOKUP(C20,'2-2. 인사고과표(안전)'!B:AO,40,0) -> S | AA20: KCC | AB20: KCC 원창동 물류센터 | AC20: 웹센 | AD20: 물류센터
B21: 23013 | C21: =ROW()-5 -> 16 | D21: =IFERROR(" "&VLOOKUP(B21,현장리스트!$B:$C,2,0),"-") -> [1.대우건설] 고양향동 지원1BL 지식산업센터 신축공사 | E21: 김인철 | F21: =IFERROR(DATEDIF(MID(G21,1,2)&"-"&MID(G21,3,2)&"-"&MID(G21,5,2),TODAY(),"y")&"세","") -> 68세 | G21: 570409-1543810 | H21: =IF(G21="","",IF(LEN(G21)<14,"에러",IF(LEN(G21)<14,"에러",IF(ISODD(MID(G21,8,1)),"남","여")))) -> 남 | I21: 기능공 | J21: 전공 | K21: 190000 | L21: 010-8764-8688 | M21: 서울 | N21: 관악구 | O21: 25 | P21: 일반건축물 | Q21: =VLOOKUP(C21,'2-1. 인사고과표(기능)'!B:AS,44,0) -> S | R21: =VLOOKUP(C21,'2-2. 인사고과표(안전)'!B:AO,40,0) -> S | W21: 은성산업 | X21: 부천 춘의동 지식산업센터 | Y21: 일반건축물 | Z21: 지식산업센터
B22: 23013 | C22: =ROW()-5 -> 17 | D22: =IFERROR(" "&VLOOKUP(B22,현장리스트!$B:$C,2,0),"-") -> [1.대우건설] 고양향동 지원1BL 지식산업센터 신축공사 | E22: 엄관영 | F22: =IFERROR(DATEDIF(MID(G22,1,2)&"-"&MID(G22,3,2)&"-"&MID(G22,5,2),TODAY(),"y")&"세","") -> 64세 | G22: 620121-1382427 | H22: =IF(G22="","",IF(LEN(G22)<14,"에러",IF(LEN(G22)<14,"에러",IF(ISODD(MID(G22,8,1)),"남","여")))) -> 남 | I22: 기능공 | J22: 전공 | K22: 190000 | L22: 010-7531-4578 | M22: 인천 | N22: 서구 | O22: 9 | P22: 일반건축물 | Q22: =VLOOKUP(C22,'2-1. 인사고과표(기능)'!B:AS,44,0) -> A | R22: =VLOOKUP(C22,'2-2. 인사고과표(안전)'!B:AO,40,0) -> S | W22: 은성산업 | X22: 부천 춘의동 지식산업센터 | Y22: 일반건축물 | Z22: 지식산업센터
B23: 25032 | C23: =ROW()-5 -> 18 | D23: =IFERROR(" "&VLOOKUP(B23,현장리스트!$B:$C,2,0),"-") -> [1.대우건설] 인천검단 신도시 AA28BL 공동주택 신축공사 | E23: 윤홍식 | F23: =IFERROR(DATEDIF(MID(G23,1,2)&"-"&MID(G23,3,2)&"-"&MID(G23,5,2),TODAY(),"y")&"세","") -> 49세 | G23: 760916-1155410 | H23: =IF(G23="","",IF(LEN(G23)<14,"에러",IF(LEN(G23)<14,"에러",IF(ISODD(MID(G23,8,1)),"남","여")))) -> 남 | I23: 공무 | J23: 차장 | K23: 5800000 | L23: 010-3307-7684 | M23: 인천 | N23: 부평구 | P23: APT/오피스텔 | Q23: =VLOOKUP(C23,'2-1. 인사고과표(기능)'!B:AS,44,0) -> S | R23: =VLOOKUP(C23,'2-2. 인사고과표(안전)'!B:AO,40,0) -> S | U23: 특급 | W23: 대우건설 | X23: 태봉공원푸르지오파크몬트신축공사 | Y23: APT/오피스텔
B24: 25032 | C24: =ROW()-5 -> 19 | D24: =IFERROR(" "&VLOOKUP(B24,현장리스트!$B:$C,2,0),"-") -> [1.대우건설] 인천검단 신도시 AA28BL 공동주택 신축공사 | E24: 김지호 | F24: =IFERROR(DATEDIF(MID(G24,1,2)&"-"&MID(G24,3,2)&"-"&MID(G24,5,2),TODAY(),"y")&"세","") -> 31세 | G24: 940407-1059517 | H24: =IF(G24="","",IF(LEN(G24)<14,"에러",IF(LEN(G24)<14,"에러",IF(ISODD(MID(G24,8,1)),"남","여")))) -> 남 | I24: 안전관리자 | J24: 대리 | K24: 3500000 | L24: 010-7631-2416 | M24: 인천 | N24: 부평구 | O24: 2 | P24: APT/오피스텔 | Q24: =VLOOKUP(C24,'2-1. 인사고과표(기능)'!B:AS,44,0) -> A | R24: =VLOOKUP(C24,'2-2. 인사고과표(안전)'!B:AO,40,0) -> S | AA24: 롯데건설 | AB24: 인천검단신도시101역세권개발사업C1,RC1BL | AC24: ㈜오에스엘이엔지 | AD24: APT/오피스텔
B25: 25032 | C25: =ROW()-5 -> 20 | D25: =IFERROR(" "&VLOOKUP(B25,현장리스트!$B:$C,2,0),"-") -> [1.대우건설] 인천검단 신도시 AA28BL 공동주택 신축공사 | E25: 차성철 | F25: =IFERROR(DATEDIF(MID(G25,1,2)&"-"&MID(G25,3,2)&"-"&MID(G25,5,2),TODAY(),"y")&"세","") -> 51세 | G25: 750102-1661925 | H25: =IF(G25="","",IF(LEN(G25)<14,"에러",IF(LEN(G25)<14,"에러",IF(ISODD(MID(G25,8,1)),"남","여")))) -> 남 | I25: 기능공 | J25: 전공 | K25: 210000 | L25: 010-9436-2796 | M25: 전주 | N25: 완산구 | O25: 30년 | P25: APT/오피스텔 | Q25: =VLOOKUP(C25,'2-1. 인사고과표(기능)'!B:AS,44,0) -> S | R25: =VLOOKUP(C25,'2-2. 인사고과표(안전)'!B:AO,40,0) -> S | W25: 대광건영 | X25: 양주 대광로제비앙신축공사 | Y25: APT/오피스텔
B26: 25032 | C26: =ROW()-5 -> 21 | D26: =IFERROR(" "&VLOOKUP(B26,현장리스트!$B:$C,2,0),"-") -> [1.대우건설] 인천검단 신도시 AA28BL 공동주택 신축공사 | E26: 박상걸 | F26: =IFERROR(DATEDIF(MID(G26,1,2)&"-"&MID(G26,3,2)&"-"&MID(G26,5,2),TODAY(),"y")&"세","") -> 46세 | G26: 790719-1253718 | H26: =IF(G26="","",IF(LEN(G26)<14,"에러",IF(LEN(G26)<14,"에러",IF(ISODD(MID(G26,8,1)),"남","여")))) -> 남 | I26: 기능공 | J26: 전공 | K26: 200000 | L26: 010-4166-6227 | M26: 인천 | N26: 서구 | O26: 20년 | P26: APT/오피스텔 | Q26: =VLOOKUP(C26,'2-1. 인사고과표(기능)'!B:AS,44,0) -> A | R26: =VLOOKUP(C26,'2-2. 인사고과표(안전)'!B:AO,40,0) -> S | AA26: 경남기업 | AB26: 파주운정3 공동주택신축공사 | AC26: 세창전기 | AD26: APT/오피스텔
B27: 25032 | C27: =ROW()-5 -> 22 | D27: =IFERROR(" "&VLOOKUP(B27,현장리스트!$B:$C,2,0),"-") -> [1.대우건설] 인천검단 신도시 AA28BL 공동주택 신축공사 | E27: 이세열 | F27: =IFERROR(DATEDIF(MID(G27,1,2)&"-"&MID(G27,3,2)&"-"&MID(G27,5,2),TODAY(),"y")&"세","") -> 42세 | G27: 830409-1085215 | H27: =IF(G27="","",IF(LEN(G27)<14,"에러",IF(LEN(G27)<14,"에러",IF(ISODD(MID(G27,8,1)),"남","여")))) -> 남 | I27: 기능공 | J27: 전공 | K27: 200000 | L27: 010-8945-8220 | M27: 서울 | N27: 강서구 | O27: 20년 | P27: APT/오피스텔 | Q27: =VLOOKUP(C27,'2-1. 인사고과표(기능)'!B:AS,44,0) -> S | R27: =VLOOKUP(C27,'2-2. 인사고과표(안전)'!B:AO,40,0) -> S | W27: 대우건설 | X27: 태봉공원푸르지오파크몬트신축공사 | Y27: APT/오피스텔
B28: 25032 | C28: =ROW()-5 -> 23 | D28: =IFERROR(" "&VLOOKUP(B28,현장리스트!$B:$C,2,0),"-") -> [1.대우건설] 인천검단 신도시 AA28BL 공동주택 신축공사 | E28: 한성필 | F28: =IFERROR(DATEDIF(MID(G28,1,2)&"-"&MID(G28,3,2)&"-"&MID(G28,5,2),TODAY(),"y")&"세","") -> 53세 | G28: 730319-7547410 | H28: =IF(G28="","",IF(LEN(G28)<14,"에러",IF(LEN(G28)<14,"에러",IF(ISODD(MID(G28,8,1)),"남","여")))) -> 남 | I28: 기능공 | J28: 전공 | K28: 200000 | L28: 010-2063-9779 | M28: 부산 | N28: 해운대구 | O28: 25년 | P28: APT/오피스텔 | Q28: =VLOOKUP(C28,'2-1. 인사고과표(기능)'!B:AS,44,0) -> S | R28: =VLOOKUP(C28,'2-2. 인사고과표(안전)'!B:AO,40,0) -> S | AA28: 현대엔지니어링 | AB28: 힐스테이트 신축공사 | AC28: 부신전력 | AD28: APT/오피스텔
B29: 24033 | C29: =ROW()-5 -> 24 | D29: =IFERROR(" "&VLOOKUP(B29,현장리스트!$B:$C,2,0),"-") -> [1.대우건설] 장위6구역 주택재개발 정비사업아파트 신축공사 | E29: 강지성 | F29: =IFERROR(DATEDIF(MID(G29,1,2)&"-"&MID(G29,3,2)&"-"&MID(G29,5,2),TODAY(),"y")&"세","") -> 50세 | G29: 760210-1025317 | H29: =IF(G29="","",IF(LEN(G29)<14,"에러",IF(LEN(G29)<14,"에러",IF(ISODD(MID(G29,8,1)),"남","여")))) -> 남 | I29: 공무 | J29: 차장 | K29: 6500000 | L29: 010-2735-8627 | M29: 서울 | N29: 강동구 | O29: 20 | P29: APT/오피스텔 | Q29: =VLOOKUP(C29,'2-1. 인사고과표(기능)'!B:AS,44,0) -> A | R29: =VLOOKUP(C29,'2-2. 인사고과표(안전)'!B:AO,40,0) | S29: 기사 | U29: 특급 | W29: 대우건설 | X29: 장위6구역 아파트 신축공사 | Y29: APT/오피스텔 | AA29: 현대건설
B30: 24033 | C30: =ROW()-5 -> 25 | D30: =IFERROR(" "&VLOOKUP(B30,현장리스트!$B:$C,2,0),"-") -> [1.대우건설] 장위6구역 주택재개발 정비사업아파트 신축공사 | E30: 이시우 | F30: =IFERROR(DATEDIF(MID(G30,1,2)&"-"&MID(G30,3,2)&"-"&MID(G30,5,2),TODAY(),"y")&"세","") -> 24세 | G30: 011103-3478210 | H30: =IF(G30="","",IF(LEN(G30)<14,"에러",IF(LEN(G30)<14,"에러",IF(ISODD(MID(G30,8,1)),"남","여")))) -> 남 | I30: 공무 | J30: 대리 | K30: 3700000 | L30: 010-3732-7874 | M30: 서울 | N30: 중량구 | O30: 5년 | P30: APT/오피스텔 | Q30: =VLOOKUP(C30,'2-1. 인사고과표(기능)'!B:AS,44,0) -> S | R30: =VLOOKUP(C30,'2-2. 인사고과표(안전)'!B:AO,40,0) -> S | S30: 초급 | U30: 초급 | W30: 롯대건설 | X30: 구리 인창 C구역 아파트 신축공사 | Y30: APT/오피스텔
B31: 24033 | C31: =ROW()-5 -> 26 | D31: =IFERROR(" "&VLOOKUP(B31,현장리스트!$B:$C,2,0),"-") -> [1.대우건설] 장위6구역 주택재개발 정비사업아파트 신축공사 | E31: 정 권 | F31: =IFERROR(DATEDIF(MID(G31,1,2)&"-"&MID(G31,3,2)&"-"&MID(G31,5,2),TODAY(),"y")&"세","") -> 60세 | G31: 650324-1653018 | H31: =IF(G31="","",IF(LEN(G31)<14,"에러",IF(LEN(G31)<14,"에러",IF(ISODD(MID(G31,8,1)),"남","여")))) -> 남 | I31: 공사 | J31: 차장 | K31: 200000 | L31: 010-5391-0859 | M31: 서울 | N31: 노원구 | O31: 35 | P31: APT/오피스텔 | Q31: =VLOOKUP(C31,'2-1. 인사고과표(기능)'!B:AS,44,0) -> S | R31: =VLOOKUP(C31,'2-2. 인사고과표(안전)'!B:AO,40,0) -> S | W31: 범양 건영 | X31: 구미 범양 레우스 신축공사 | Y31: APT/오피스텔
B32: 24033 | C32: =ROW()-5 -> 27 | D32: =IFERROR(" "&VLOOKUP(B32,현장리스트!$B:$C,2,0),"-") -> [1.대우건설] 장위6구역 주택재개발 정비사업아파트 신축공사 | E32: 성경웅 | F32: =IFERROR(DATEDIF(MID(G32,1,2)&"-"&MID(G32,3,2)&"-"&MID(G32,5,2),TODAY(),"y")&"세","") -> 56세 | G32: 690424-1805212 | H32: =IF(G32="","",IF(LEN(G32)<14,"에러",IF(LEN(G32)<14,"에러",IF(ISODD(MID(G32,8,1)),"남","여")))) -> 남 | I32: 공사 | J32: 차장 | K32: 200000 | L32: 010-5099-9847 | M32: 인천 | N32: 계양구 | O32: 15년 | P32: APT/오피스텔 | Q32: =VLOOKUP(C32,'2-1. 인사고과표(기능)'!B:AS,44,0) -> S | R32: =VLOOKUP(C32,'2-2. 인사고과표(안전)'!B:AO,40,0) -> S | W32: 대광 건영 | X32: 내포 신도시 대광 건영 신축공사 | Y32: APT/오피스텔
B33: 24033 | C33: =ROW()-5 -> 28 | D33: =IFERROR(" "&VLOOKUP(B33,현장리스트!$B:$C,2,0),"-") -> [1.대우건설] 장위6구역 주택재개발 정비사업아파트 신축공사 | E33: 용효중 | F33: =IFERROR(DATEDIF(MID(G33,1,2)&"-"&MID(G33,3,2)&"-"&MID(G33,5,2),TODAY(),"y")&"세","") -> 49세 | G33: 760607-1912615 | H33: =IF(G33="","",IF(LEN(G33)<14,"에러",IF(LEN(G33)<14,"에러",IF(ISODD(MID(G33,8,1)),"남","여")))) -> 남 | I33: 기능공 | J33: 전공 | K33: 220000 | L33: 010-8898-5892 | M33: 경남 | N33: 거제 | O33: 13 | P33: APT/오피스텔 | Q33: =VLOOKUP(C33,'2-1. 인사고과표(기능)'!B:AS,44,0) -> S | R33: =VLOOKUP(C33,'2-2. 인사고과표(안전)'!B:AO,40,0) -> S | W33: 범양 건영 | X33: 구미 범양 레우스 신축공사 | Y33: APT/오피스텔
B34: 24033 | C34: =ROW()-5 -> 29 | D34: =IFERROR(" "&VLOOKUP(B34,현장리스트!$B:$C,2,0),"-") -> [1.대우건설] 장위6구역 주택재개발 정비사업아파트 신축공사 | E34: 서경배 | F34: =IFERROR(DATEDIF(MID(G34,1,2)&"-"&MID(G34,3,2)&"-"&MID(G34,5,2),TODAY(),"y")&"세","") -> 62세 | G34: 630914-1559926 | H34: =IF(G34="","",IF(LEN(G34)<14,"에러",IF(LEN(G34)<14,"에러",IF(ISODD(MID(G34,8,1)),"남","여")))) -> 남 | I34: 기능공 | J34: 전공 | K34: 190000 | L34: 010-4117-5500 | M34: 경기 | N34: 화성 | O34: 20 | P34: APT/오피스텔 | Q34: =VLOOKUP(C34,'2-1. 인사고과표(기능)'!B:AS,44,0) -> S | R34: =VLOOKUP(C34,'2-2. 인사고과표(안전)'!B:AO,40,0) -> S | W34: 범양 건영 | X34: 구미 범양 레우스 신축공사 | Y34: APT/오피스텔
B35: 24033 | C35: =ROW()-5 -> 30 | D35: =IFERROR(" "&VLOOKUP(B35,현장리스트!$B:$C,2,0),"-") -> [1.대우건설] 장위6구역 주택재개발 정비사업아파트 신축공사 | E35: 장대용 | F35: =IFERROR(DATEDIF(MID(G35,1,2)&"-"&MID(G35,3,2)&"-"&MID(G35,5,2),TODAY(),"y")&"세","") -> 42세 | G35: 831231-1400317 | H35: =IF(G35="","",IF(LEN(G35)<14,"에러",IF(LEN(G35)<14,"에러",IF(ISODD(MID(G35,8,1)),"남","여")))) -> 남 | I35: 기능공 | J35: 전공 | K35: 200000 | L35: 010-8391-1570 | M35: 경기 | N35: 남양주시 | O35: 11 | P35: APT/오피스텔 | Q35: =VLOOKUP(C35,'2-1. 인사고과표(기능)'!B:AS,44,0) -> S | R35: =VLOOKUP(C35,'2-2. 인사고과표(안전)'!B:AO,40,0) -> S | W35: 대우건설 | X35: 태봉 공원 내 공동주택 신축공사 | Y35: APT/오피스텔
B36: 24033 | C36: =ROW()-5 -> 31 | D36: =IFERROR(" "&VLOOKUP(B36,현장리스트!$B:$C,2,0),"-") -> [1.대우건설] 장위6구역 주택재개발 정비사업아파트 신축공사 | E36: 석준수 | F36: =IFERROR(DATEDIF(MID(G36,1,2)&"-"&MID(G36,3,2)&"-"&MID(G36,5,2),TODAY(),"y")&"세","") -> 50세 | G36: 750925-1183413 | H36: =IF(G36="","",IF(LEN(G36)<14,"에러",IF(LEN(G36)<14,"에러",IF(ISODD(MID(G36,8,1)),"남","여")))) -> 남 | I36: 기능공 | J36: 전공 | K36: 200000 | L36: 010-2259-6816 | M36: 서울 | N36: 은평구 | O36: 8 | P36: APT/오피스텔 | Q36: =VLOOKUP(C36,'2-1. 인사고과표(기능)'!B:AS,44,0) -> A | R36: =VLOOKUP(C36,'2-2. 인사고과표(안전)'!B:AO,40,0) -> S | W36: 대우건설 | X36: 태봉 공원 내 공동주택 신축공사 | Y36: APT/오피스텔
B37: 24033 | C37: =ROW()-5 -> 32 | D37: =IFERROR(" "&VLOOKUP(B37,현장리스트!$B:$C,2,0),"-") -> [1.대우건설] 장위6구역 주택재개발 정비사업아파트 신축공사 | E37: 배기정 | F37: =IFERROR(DATEDIF(MID(G37,1,2)&"-"&MID(G37,3,2)&"-"&MID(G37,5,2),TODAY(),"y")&"세","") -> 32세 | G37: 930828-1218726 | H37: =IF(G37="","",IF(LEN(G37)<14,"에러",IF(LEN(G37)<14,"에러",IF(ISODD(MID(G37,8,1)),"남","여")))) -> 남 | I37: 기능공 | J37: 조공 | K37: 155000 | L37: 010-3708-0838 | M37: 경기 | N37: 남양주시 | O37: 3년 | P37: APT/오피스텔 | Q37: =VLOOKUP(C37,'2-1. 인사고과표(기능)'!B:AS,44,0) -> A | R37: =VLOOKUP(C37,'2-2. 인사고과표(안전)'!B:AO,40,0) -> A | W37: 현대 엔지니어링 | X37: 시흥 지식산업센터 | Y37: APT/오피스텔
B38: 24033 | C38: =ROW()-5 -> 33 | D38: =IFERROR(" "&VLOOKUP(B38,현장리스트!$B:$C,2,0),"-") -> [1.대우건설] 장위6구역 주택재개발 정비사업아파트 신축공사 | E38: 김기현 | F38: =IFERROR(DATEDIF(MID(G38,1,2)&"-"&MID(G38,3,2)&"-"&MID(G38,5,2),TODAY(),"y")&"세","") -> 55세 | G38: 710105-1010912 | H38: =IF(G38="","",IF(LEN(G38)<14,"에러",IF(LEN(G38)<14,"에러",IF(ISODD(MID(G38,8,1)),"남","여")))) -> 남 | I38: 기능공 | J38: 전공 | K38: 200000 | L38: 010-0000-0000 | M38: 경기 | N38: 의정부 | O38: 10년 | P38: APT/오피스텔 | Q38: =VLOOKUP(C38,'2-1. 인사고과표(기능)'!B:AS,44,0) -> S | R38: =VLOOKUP(C38,'2-2. 인사고과표(안전)'!B:AO,40,0) -> S | W38: 현대 산업개발 | X38: 잠실 진주아파트 재개발 | Y38: APT/오피스텔
B39: 24033 | C39: =ROW()-5 -> 34 | D39: =IFERROR(" "&VLOOKUP(B39,현장리스트!$B:$C,2,0),"-") -> [1.대우건설] 장위6구역 주택재개발 정비사업아파트 신축공사 | E39: 문원규 | F39: =IFERROR(DATEDIF(MID(G39,1,2)&"-"&MID(G39,3,2)&"-"&MID(G39,5,2),TODAY(),"y")&"세","") -> 35세 | G39: 910219-1170321 | H39: =IF(G39="","",IF(LEN(G39)<14,"에러",IF(LEN(G39)<14,"에러",IF(ISODD(MID(G39,8,1)),"남","여")))) -> 남 | I39: 기능공 | J39: 조공 | K39: 180000 | L39: 010-0000-0000 | M39: 경기 | N39: 용인 | O39: 7 | P39: APT/오피스텔 | Q39: =VLOOKUP(C39,'2-1. 인사고과표(기능)'!B:AS,44,0) -> S | R39: =VLOOKUP(C39,'2-2. 인사고과표(안전)'!B:AO,40,0) -> S | W39: 대우 건설 | X39: 탕정 푸르지오 리버파크 | Y39: APT/오피스텔
B40: 24025 | C40: =ROW()-5 -> 35 | D40: =IFERROR(" "&VLOOKUP(B40,현장리스트!$B:$C,2,0),"-") -> [1.대우건설] 청라C18BL 오피스텔 신축공사 | E40: 양규성 | F40: =IFERROR(DATEDIF(MID(G40,1,2)&"-"&MID(G40,3,2)&"-"&MID(G40,5,2),TODAY(),"y")&"세","") -> 42세 | G40: 840111-1075229 | H40: =IF(G40="","",IF(LEN(G40)<14,"에러",IF(LEN(G40)<14,"에러",IF(ISODD(MID(G40,8,1)),"남","여")))) -> 남 | I40: 공무 | J40: 과장 | K40: 5400000 | L40: 010-9138-7004 | M40: 서울 | N40: 구로구 | O40: 13 | P40: APT/오피스텔 | Q40: =VLOOKUP(C40,'2-1. 인사고과표(기능)'!B:AS,44,0) -> S | R40: =VLOOKUP(C40,'2-2. 인사고과표(안전)'!B:AO,40,0) -> S | S40: 중급 | U40: 특급 | AA40: 포스코건설 | AB40: 송도E5블록 주상복합현장 | AC40: 중선ITC | AD40: APT/오피스텔
B41: 24025 | C41: =ROW()-5 -> 36 | D41: =IFERROR(" "&VLOOKUP(B41,현장리스트!$B:$C,2,0),"-") -> [1.대우건설] 청라C18BL 오피스텔 신축공사 | E41: 박규철 | F41: =IFERROR(DATEDIF(MID(G41,1,2)&"-"&MID(G41,3,2)&"-"&MID(G41,5,2),TODAY(),"y")&"세","") -> 30세 | G41: 950410-1555011 | H41: =IF(G41="","",IF(LEN(G41)<14,"에러",IF(LEN(G41)<14,"에러",IF(ISODD(MID(G41,8,1)),"남","여")))) -> 남 | I41: 공무 | J41: 과장 | K41: 4500000 | L41: 010-5140-4391 | M41: 광주(전) | N41: 남구 | O41: 8 | P41: APT/오피스텔 | Q41: =VLOOKUP(C41,'2-1. 인사고과표(기능)'!B:AS,44,0) -> S | R41: =VLOOKUP(C41,'2-2. 인사고과표(안전)'!B:AO,40,0) -> S | T41: 초급 | W41: 까뮤이엔씨 | X41: 안성성은지구물류센터 | Y41: 물류센터
B42: 24025 | C42: =ROW()-5 -> 37 | D42: =IFERROR(" "&VLOOKUP(B42,현장리스트!$B:$C,2,0),"-") -> [1.대우건설] 청라C18BL 오피스텔 신축공사 | E42: 차광식 | F42: =IFERROR(DATEDIF(MID(G42,1,2)&"-"&MID(G42,3,2)&"-"&MID(G42,5,2),TODAY(),"y")&"세","") -> 64세 | G42: 620305-1332919 | H42: =IF(G42="","",IF(LEN(G42)<14,"에러",IF(LEN(G42)<14,"에러",IF(ISODD(MID(G42,8,1)),"남","여")))) -> 남 | I42: 공사 | J42: 차장 | K42: 5500000 | L42: 010-9639-1364 | M42: 안산 | N42: 상록구 | O42: 30 | P42: APT/오피스텔 | Q42: =VLOOKUP(C42,'2-1. 인사고과표(기능)'!B:AS,44,0) -> S | R42: =VLOOKUP(C42,'2-2. 인사고과표(안전)'!B:AO,40,0) -> S | AA42: 현대엔지니어링 | AB42: 과천 스마트허브현장 | AC42: 태성산업사 | AD42: 일반건축물
B43: 24025 | C43: =ROW()-5 -> 38 | D43: =IFERROR(" "&VLOOKUP(B43,현장리스트!$B:$C,2,0),"-") -> [1.대우건설] 청라C18BL 오피스텔 신축공사 | E43: 김 동 석 | F43: =IFERROR(DATEDIF(MID(G43,1,2)&"-"&MID(G43,3,2)&"-"&MID(G43,5,2),TODAY(),"y")&"세","") -> 53세 | G43: 730218-1058027 | H43: =IF(G43="","",IF(LEN(G43)<14,"에러",IF(LEN(G43)<14,"에러",IF(ISODD(MID(G43,8,1)),"남","여")))) -> 남 | I43: 공사 | J43: 차장 | K43: 5900000 | L43: 010-3239-6737 | M43: 서울 | N43: 구로구 | O43: 25 | P43: APT/오피스텔 | Q43: =VLOOKUP(C43,'2-1. 인사고과표(기능)'!B:AS,44,0) -> S | R43: =VLOOKUP(C43,'2-2. 인사고과표(안전)'!B:AO,40,0) -> S | S43: 고급 | U43: 특급 | W43: 두산건설 | X43: 송림동 A6BL APT현장 | Y43: APT/오피스텔
...

Sheet Sheet1

Sheet 2-1. 인사고과표(기능)
B1: 현장 사원 인사고과표 - 기능
B2: 순번 | C2: 현장명 | D2: 이름 | E2: 생년월일 | F2: 직책 | G2: 직급 | H2: 업무능력 | X2: 의욕 | AJ2: 인간관계 | AR2: 점수 | AS2: 등급
H3: 전문지식(숙련도) | L3: 정확성, 신속성 | P3: 이해력 | T3: 창의력 | X3: 규율성 | AB3: 책임감 | AF3: 적극성 | AJ3: 기본자세 | AN3: 출결상태
H4: 우수 | I4: 보통 | J4: 부족 | K4: 문제 | L4: 우수 | M4: 보통 | N4: 부족 | O4: 문제 | P4: 우수 | Q4: 보통 | R4: 부족 | S4: 문제 | T4: 우수 | U4: 보통 | V4: 부족 | W4: 문제 | X4: 우수 | Y4: 보통 | Z4: 부족 | AA4: 문제 | AB4: 우수 | AC4: 보통 | AD4: 부족 | AE4: 문제 | AF4: 우수 | AG4: 보통 | AH4: 부족 | AI4: 문제 | AJ4: 우수 | AK4: 보통 | AL4: 부족 | AM4: 문제 | AN4: 우수 | AO4: 보통 | AP4: 부족 | AQ4: 문제
H5: 12 | I5: 9 | J5: 6 | K5: 3 | L5: 12 | M5: 9 | N5: 6 | O5: 3 | P5: 12 | Q5: 9 | R5: 6 | S5: 3 | T5: 10 | U5: 8 | V5: 6 | W5: 4 | X5: 10 | Y5: 8 | Z5: 6 | AA5: 4 | AB5: 10 | AC5: 8 | AD5: 6 | AE5: 4 | AF5: 10 | AG5: 8 | AH5: 6 | AI5: 4 | AJ5: 12 | AK5: 9 | AL5: 6 | AM5: 3 | AN5: 12 | AO5: 9 | AP5: 6 | AQ5: 3
A7: =MID(C7,3,1)&"팀" -> 1팀 | B7: =ROW()-6 -> 1 | C7: =IF(VLOOKUP($B7,'1. 현장별 인원현황'!$C:$J,2,0)=0,"",VLOOKUP($B7,'1. 현장별 인원현황'!$C:$J,2,0)) -> [1.DL건설] 전도관구역 주택재개발 정비사업조합(01공구) | D7: =IF(VLOOKUP($B7,'1. 현장별 인원현황'!$C:$J,3,0)=0,"",VLOOKUP($B7,'1. 현장별 인원현황'!$C:$J,3,0)) -> 강민 | E7: =IF(VLOOKUP($B7,'1. 현장별 인원현황'!$C:$J,4,0)=0,"",VLOOKUP($B7,'1. 현장별 인원현황'!$C:$J,4,0)) -> 37세 | F7: =IF(VLOOKUP($B7,'1. 현장별 인원현황'!$C:$J,7,0)=0,"",VLOOKUP($B7,'1. 현장별 인원현황'!$C:$J,7,0)) -> 공무 | G7: =IF(VLOOKUP($B7,'1. 현장별 인원현황'!$C:$J,8,0)=0,"",VLOOKUP($B7,'1. 현장별 인원현황'!$C:$J,8,0)) -> 과장 | H7: O | L7: O | P7: O | T7: O | X7: O | AB7: O | AF7: O | AJ7: O | AN7: O | AR7: =SUMPRODUCT($H$5:$AQ$5,AV7:CE7) -> 100 | AS7: =IF(AR7>85,"S",IF(AR7>70,"A",IF(AR7>50,"B",IF(AR7>0,"C","")))) -> S | AV7: =IF(H7>0,1,0) -> 1 | AW7: =IF(I7>0,1,0) -> 0 | AX7: =IF(J7>0,1,0) -> 0 | AY7: =IF(K7>0,1,0) -> 0 | AZ7: =IF(L7>0,1,0) -> 1 | BA7: =IF(M7>0,1,0) -> 0 | BB7: =IF(N7>0,1,0) -> 0 | BC7: =IF(O7>0,1,0) -> 0 | ... CE7: =IF(AQ7>0,1,0) -> 0
A8: =MID(C8,3,1)&"팀" -> 1팀 | B8: =ROW()-6 -> 2 | C8: =IF(VLOOKUP($B8,'1. 현장별 인원현황'!$C:$J,2,0)=0,"",VLOOKUP($B8,'1. 현장별 인원현황'!$C:$J,2,0)) -> [1.DL건설] 전도관구역 주택재개발 정비사업조합(01공구) | D8: =IF(VLOOKUP($B8,'1. 현장별 인원현황'!$C:$J,3,0)=0,"",VLOOKUP($B8,'1. 현장별 인원현황'!$C:$J,3,0)) -> 오재욱 | E8: =IF(VLOOKUP($B8,'1. 현장별 인원현황'!$C:$J,4,0)=0,"",VLOOKUP($B8,'1. 현장별 인원현황'!$C:$J,4,0)) -> 32세 | F8: =IF(VLOOKUP($B8,'1. 현장별 인원현황'!$C:$J,7,0)=0,"",VLOOKUP($B8,'1. 현장별 인원현황'!$C:$J,7,0)) -> 안전관리자 | G8: =IF(VLOOKUP($B8,'1. 현장별 인원현황'!$C:$J,8,0)=0,"",VLOOKUP($B8,'1. 현장별 인원현황'!$C:$J,8,0)) -> 대리 | I8: O | M8: O | Q8: O | U8: O | Y8: O | AC8: O | AG8: O | AK8: O | AN8: O | AR8: =SUMPRODUCT($H$5:$AQ$5,AV8:CE8) -> 80 | AS8: =IF(AR8>85,"S",IF(AR8>70,"A",IF(AR8>50,"B",IF(AR8>0,"C","")))) -> A | AV8: =IF(H8>0,1,0) -> 0 | AW8: =IF(I8>0,1,0) -> 1 | AX8: =IF(J8>0,1,0) -> 0 | AY8: =IF(K8>0,1,0) -> 0 | AZ8: =IF(L8>0,1,0) -> 0 | BA8: =IF(M8>0,1,0) -> 1 | BB8: =IF(N8>0,1,0) -> 0 | BC8: =IF(O8>0,1,0) -> 0 | ... CE8: =IF(AQ8>0,1,0) -> 0
A9: =MID(C9,3,1)&"팀" -> 1팀 | B9: =ROW()-6 -> 3 | C9: =IF(VLOOKUP($B9,'1. 현장별 인원현황'!$C:$J,2,0)=0,"",VLOOKUP($B9,'1. 현장별 인원현황'!$C:$J,2,0)) -> [1.DL건설] 전도관구역 주택재개발 정비사업조합(01공구) | D9: =IF(VLOOKUP($B9,'1. 현장별 인원현황'!$C:$J,3,0)=0,"",VLOOKUP($B9,'1. 현장별 인원현황'!$C:$J,3,0)) -> 조경호 | E9: =IF(VLOOKUP($B9,'1. 현장별 인원현황'!$C:$J,4,0)=0,"",VLOOKUP($B9,'1. 현장별 인원현황'!$C:$J,4,0)) -> 57세 | F9: =IF(VLOOKUP($B9,'1. 현장별 인원현황'!$C:$J,7,0)=0,"",VLOOKUP($B9,'1. 현장별 인원현황'!$C:$J,7,0)) -> 공사 | G9: =IF(VLOOKUP($B9,'1. 현장별 인원현황'!$C:$J,8,0)=0,"",VLOOKUP($B9,'1. 현장별 인원현황'!$C:$J,8,0)) -> 차장 | H9: O | L9: O | P9: O | T9: O | X9: O | AB9: O | AF9: O | AJ9: O | AN9: O | AR9: =SUMPRODUCT($H$5:$AQ$5,AV9:CE9) -> 100 | AS9: =IF(AR9>85,"S",IF(AR9>70,"A",IF(AR9>50,"B",IF(AR9>0,"C","")))) -> S | AV9: =IF(H9>0,1,0) -> 1 | AW9: =IF(I9>0,1,0) -> 0 | AX9: =IF(J9>0,1,0) -> 0 | AY9: =IF(K9>0,1,0) -> 0 | AZ9: =IF(L9>0,1,0) -> 1 | BA9: =IF(M9>0,1,0) -> 0 | BB9: =IF(N9>0,1,0) -> 0 | BC9: =IF(O9>0,1,0) -> 0 | ... CE9: =IF(AQ9>0,1,0) -> 0
A10: =MID(C10,3,1)&"팀" -> 1팀 | B10: =ROW()-6 -> 4 | C10: =IF(VLOOKUP($B10,'1. 현장별 인원현황'!$C:$J,2,0)=0,"",VLOOKUP($B10,'1. 현장별 인원현황'!$C:$J,2,0)) -> [1.DL건설] 전도관구역 주택재개발 정비사업조합(01공구) | D10: =IF(VLOOKUP($B10,'1. 현장별 인원현황'!$C:$J,3,0)=0,"",VLOOKUP($B10,'1. 현장별 인원현황'!$C:$J,3,0)) -> 남춘섭 | E10: =IF(VLOOKUP($B10,'1. 현장별 인원현황'!$C:$J,4,0)=0,"",VLOOKUP($B10,'1. 현장별 인원현황'!$C:$J,4,0)) -> 62세 | F10: =IF(VLOOKUP($B10,'1. 현장별 인원현황'!$C:$J,7,0)=0,"",VLOOKUP($B10,'1. 현장별 인원현황'!$C:$J,7,0)) -> 공사 | G10: =IF(VLOOKUP($B10,'1. 현장별 인원현황'!$C:$J,8,0)=0,"",VLOOKUP($B10,'1. 현장별 인원현황'!$C:$J,8,0)) -> 과장 | H10: O | M10: O | P10: O | U10: O | Y10: O | AC10: O | AG10: O | AK10: O | AN10: O | AR10: =SUMPRODUCT($H$5:$AQ$5,AV10:CE10) -> 86 | AS10: =IF(AR10>85,"S",IF(AR10>70,"A",IF(AR10>50,"B",IF(AR10>0,"C","")))) -> S | AV10: =IF(H10>0,1,0) -> 1 | AW10: =IF(I10>0,1,0) -> 0 | AX10: =IF(J10>0,1,0) -> 0 | AY10: =IF(K10>0,1,0) -> 0 | AZ10: =IF(L10>0,1,0) -> 0 | BA10: =IF(M10>0,1,0) -> 1 | BB10: =IF(N10>0,1,0) -> 0 | BC10: =IF(O10>0,1,0) -> 0 | ... CE10: =IF(AQ10>0,1,0) -> 0
A11: =MID(C11,3,1)&"팀" -> 1팀 | B11: =ROW()-6 -> 5 | C11: =IF(VLOOKUP($B11,'1. 현장별 인원현황'!$C:$J,2,0)=0,"",VLOOKUP($B11,'1. 현장별 인원현황'!$C:$J,2,0)) -> [1.DL건설] 전도관구역 주택재개발 정비사업조합(01공구) | D11: =IF(VLOOKUP($B11,'1. 현장별 인원현황'!$C:$J,3,0)=0,"",VLOOKUP($B11,'1. 현장별 인원현황'!$C:$J,3,0)) -> 김옥수 | E11: =IF(VLOOKUP($B11,'1. 현장별 인원현황'!$C:$J,4,0)=0,"",VLOOKUP($B11,'1. 현장별 인원현황'!$C:$J,4,0)) -> 57세 | F11: =IF(VLOOKUP($B11,'1. 현장별 인원현황'!$C:$J,7,0)=0,"",VLOOKUP($B11,'1. 현장별 인원현황'!$C:$J,7,0)) -> 기능공 | G11: =IF(VLOOKUP($B11,'1. 현장별 인원현황'!$C:$J,8,0)=0,"",VLOOKUP($B11,'1. 현장별 인원현황'!$C:$J,8,0)) -> 전공 | H11: O | M11: O | P11: O | T11: O | Y11: O | AC11: O | AG11: O | AK11: O | AN11: O | AR11: =SUMPRODUCT($H$5:$AQ$5,AV11:CE11) -> 88 | AS11: =IF(AR11>85,"S",IF(AR11>70,"A",IF(AR11>50,"B",IF(AR11>0,"C","")))) -> S | AV11: =IF(H11>0,1,0) -> 1 | AW11: =IF(I11>0,1,0) -> 0 | AX11: =IF(J11>0,1,0) -> 0 | AY11: =IF(K11>0,1,0) -> 0 | AZ11: =IF(L11>0,1,0) -> 0 | BA11: =IF(M11>0,1,0) -> 1 | BB11: =IF(N11>0,1,0) -> 0 | BC11: =IF(O11>0,1,0) -> 0 | ... CE11: =IF(AQ11>0,1,0) -> 0
A12: =MID(C12,3,1)&"팀" -> 1팀 | B12: =ROW()-6 -> 6 | C12: =IF(VLOOKUP($B12,'1. 현장별 인원현황'!$C:$J,2,0)=0,"",VLOOKUP($B12,'1. 현장별 인원현황'!$C:$J,2,0)) -> [1.DL건설] 전도관구역 주택재개발 정비사업조합(01공구) | D12: =IF(VLOOKUP($B12,'1. 현장별 인원현황'!$C:$J,3,0)=0,"",VLOOKUP($B12,'1. 현장별 인원현황'!$C:$J,3,0)) -> 박예만 | E12: =IF(VLOOKUP($B12,'1. 현장별 인원현황'!$C:$J,4,0)=0,"",VLOOKUP($B12,'1. 현장별 인원현황'!$C:$J,4,0)) -> 37세 | F12: =IF(VLOOKUP($B12,'1. 현장별 인원현황'!$C:$J,7,0)=0,"",VLOOKUP($B12,'1. 현장별 인원현황'!$C:$J,7,0)) -> 기능공 | G12: =IF(VLOOKUP($B12,'1. 현장별 인원현황'!$C:$J,8,0)=0,"",VLOOKUP($B12,'1. 현장별 인원현황'!$C:$J,8,0)) -> 전공 | I12: O | M12: O | Q12: O | U12: O | Y12: O | AC12: O | AG12: O | AK12: O | AN12: O | AR12: =SUMPRODUCT($H$5:$AQ$5,AV12:CE12) -> 80 | AS12: =IF(AR12>85,"S",IF(AR12>70,"A",IF(AR12>50,"B",IF(AR12>0,"C","")))) -> A | AV12: =IF(H12>0,1,0) -> 0 | AW12: =IF(I12>0,1,0) -> 1 | AX12: =IF(J12>0,1,0) -> 0 | AY12: =IF(K12>0,1,0) -> 0 | AZ12: =IF(L12>0,1,0) -> 0 | BA12: =IF(M12>0,1,0) -> 1 | BB12: =IF(N12>0,1,0) -> 0 | BC12: =IF(O12>0,1,0) -> 0 | ... CE12: =IF(AQ12>0,1,0) -> 0
A13: =MID(C13,3,1)&"팀" -> 1팀 | B13: =ROW()-6 -> 7 | C13: =IF(VLOOKUP($B13,'1. 현장별 인원현황'!$C:$J,2,0)=0,"",VLOOKUP($B13,'1. 현장별 인원현황'!$C:$J,2,0)) -> [1.DL건설] 전도관구역 주택재개발 정비사업조합(01공구) | D13: =IF(VLOOKUP($B13,'1. 현장별 인원현황'!$C:$J,3,0)=0,"",VLOOKUP($B13,'1. 현장별 인원현황'!$C:$J,3,0)) -> 유동민 | E13: =IF(VLOOKUP($B13,'1. 현장별 인원현황'!$C:$J,4,0)=0,"",VLOOKUP($B13,'1. 현장별 인원현황'!$C:$J,4,0)) -> 54세 | F13: =IF(VLOOKUP($B13,'1. 현장별 인원현황'!$C:$J,7,0)=0,"",VLOOKUP($B13,'1. 현장별 인원현황'!$C:$J,7,0)) -> 기능공 | G13: =IF(VLOOKUP($B13,'1. 현장별 인원현황'!$C:$J,8,0)=0,"",VLOOKUP($B13,'1. 현장별 인원현황'!$C:$J,8,0)) -> 전공 | H13: O | L13: O | P13: O | T13: O | Y13: O | AC13: O | AG13: O | AJ13: O | AN13: O | AR13: =SUMPRODUCT($H$5:$AQ$5,AV13:CE13) -> 94 | AS13: =IF(AR13>85,"S",IF(AR13>70,"A",IF(AR13>50,"B",IF(AR13>0,"C","")))) -> S | AV13: =IF(H13>0,1,0) -> 1 | AW13: =IF(I13>0,1,0) -> 0 | AX13: =IF(J13>0,1,0) -> 0 | AY13: =IF(K13>0,1,0) -> 0 | AZ13: =IF(L13>0,1,0) -> 1 | BA13: =IF(M13>0,1,0) -> 0 | BB13: =IF(N13>0,1,0) -> 0 | BC13: =IF(O13>0,1,0) -> 0 | ... CE13: =IF(AQ13>0,1,0) -> 0
A14: =MID(C14,3,1)&"팀" -> 1팀 | B14: =ROW()-6 -> 8 | C14: =IF(VLOOKUP($B14,'1. 현장별 인원현황'!$C:$J,2,0)=0,"",VLOOKUP($B14,'1. 현장별 인원현황'!$C:$J,2,0)) -> [1.DL건설] 전도관구역 주택재개발 정비사업조합(01공구) | D14: =IF(VLOOKUP($B14,'1. 현장별 인원현황'!$C:$J,3,0)=0,"",VLOOKUP($B14,'1. 현장별 인원현황'!$C:$J,3,0)) -> 윤효상 | E14: =IF(VLOOKUP($B14,'1. 현장별 인원현황'!$C:$J,4,0)=0,"",VLOOKUP($B14,'1. 현장별 인원현황'!$C:$J,4,0)) -> 56세 | F14: =IF(VLOOKUP($B14,'1. 현장별 인원현황'!$C:$J,7,0)=0,"",VLOOKUP($B14,'1. 현장별 인원현황'!$C:$J,7,0)) -> 기능공 | G14: =IF(VLOOKUP($B14,'1. 현장별 인원현황'!$C:$J,8,0)=0,"",VLOOKUP($B14,'1. 현장별 인원현황'!$C:$J,8,0)) -> 전공 | I14: O | M14: O | Q14: O | U14: O | Y14: O | AC14: O | AG14: O | AK14: O | AN14: O | AR14: =SUMPRODUCT($H$5:$AQ$5,AV14:CE14) -> 80 | AS14: =IF(AR14>85,"S",IF(AR14>70,"A",IF(AR14>50,"B",IF(AR14>0,"C","")))) -> A | AV14: =IF(H14>0,1,0) -> 0 | AW14: =IF(I14>0,1,0) -> 1 | AX14: =IF(J14>0,1,0) -> 0 | AY14: =IF(K14>0,1,0) -> 0 | AZ14: =IF(L14>0,1,0) -> 0 | BA14: =IF(M14>0,1,0) -> 1 | BB14: =IF(N14>0,1,0) -> 0 | BC14: =IF(O14>0,1,0) -> 0 | ... CE14: =IF(AQ14>0,1,0) -> 0
A15: =MID(C15,3,1)&"팀" -> 1팀 | B15: =ROW()-6 -> 9 | C15: =IF(VLOOKUP($B15,'1. 현장별 인원현황'!$C:$J,2,0)=0,"",VLOOKUP($B15,'1. 현장별 인원현황'!$C:$J,2,0)) -> [1.DL건설] 전도관구역 주택재개발 정비사업조합(01공구) | D15: =IF(VLOOKUP($B15,'1. 현장별 인원현황'!$C:$J,3,0)=0,"",VLOOKUP($B15,'1. 현장별 인원현황'!$C:$J,3,0)) -> 이봉운 | E15: =IF(VLOOKUP($B15,'1. 현장별 인원현황'!$C:$J,4,0)=0,"",VLOOKUP($B15,'1. 현장별 인원현황'!$C:$J,4,0)) -> 44세 | F15: =IF(VLOOKUP($B15,'1. 현장별 인원현황'!$C:$J,7,0)=0,"",VLOOKUP($B15,'1. 현장별 인원현황'!$C:$J,7,0)) -> 기능공 | G15: =IF(VLOOKUP($B15,'1. 현장별 인원현황'!$C:$J,8,0)=0,"",VLOOKUP($B15,'1. 현장별 인원현황'!$C:$J,8,0)) -> 전공 | I15: O | M15: O | Q15: O | U15: O | Y15: O | AC15: O | AG15: O | AK15: O | AN15: O | AR15: =SUMPRODUCT($H$5:$AQ$5,AV15:CE15) -> 80 | AS15: =IF(AR15>85,"S",IF(AR15>70,"A",IF(AR15>50,"B",IF(AR15>0,"C","")))) -> A | AV15: =IF(H15>0,1,0) -> 0 | AW15: =IF(I15>0,1,0) -> 1 | AX15: =IF(J15>0,1,0) -> 0 | AY15: =IF(K15>0,1,0) -> 0 | AZ15: =IF(L15>0,1,0) -> 0 | BA15: =IF(M15>0,1,0) -> 1 | BB15: =IF(N15>0,1,0) -> 0 | BC15: =IF(O15>0,1,0) -> 0 | ... CE15: =IF(AQ15>0,1,0) -> 0
A16: =MID(C16,3,1)&"팀" -> 1팀 | B16: =ROW()-6 -> 10 | C16: =IF(VLOOKUP($B16,'1. 현장별 인원현황'!$C:$J,2,0)=0,"",VLOOKUP($B16,'1. 현장별 인원현황'!$C:$J,2,0)) -> [1.DL건설] 전도관구역 주택재개발 정비사업조합(01공구) | D16: =IF(VLOOKUP($B16,'1. 현장별 인원현황'!$C:$J,3,0)=0,"",VLOOKUP($B16,'1. 현장별 인원현황'!$C:$J,3,0)) -> 이상열 | E16: =IF(VLOOKUP($B16,'1. 현장별 인원현황'!$C:$J,4,0)=0,"",VLOOKUP($B16,'1. 현장별 인원현황'!$C:$J,4,0)) -> 53세 | F16: =IF(VLOOKUP($B16,'1. 현장별 인원현황'!$C:$J,7,0)=0,"",VLOOKUP($B16,'1. 현장별 인원현황'!$C:$J,7,0)) -> 기능공 | G16: =IF(VLOOKUP($B16,'1. 현장별 인원현황'!$C:$J,8,0)=0,"",VLOOKUP($B16,'1. 현장별 인원현황'!$C:$J,8,0)) -> 전공 | H16: O | L16: O | P16: O | T16: O | X16: O | AB16: O | AF16: O | AJ16: O | AN16: O | AR16: =SUMPRODUCT($H$5:$AQ$5,AV16:CE16) -> 100 | AS16: =IF(AR16>85,"S",IF(AR16>70,"A",IF(AR16>50,"B",IF(AR16>0,"C","")))) -> S | AV16: =IF(H16>0,1,0) -> 1 | AW16: =IF(I16>0,1,0) -> 0 | AX16: =IF(J16>0,1,0) -> 0 | AY16: =IF(K16>0,1,0) -> 0 | AZ16: =IF(L16>0,1,0) -> 1 | BA16: =IF(M16>0,1,0) -> 0 | BB16: =IF(N16>0,1,0) -> 0 | BC16: =IF(O16>0,1,0) -> 0 | ... CE16: =IF(AQ16>0,1,0) -> 0
A17: =MID(C17,3,1)&"팀" -> 1팀 | B17: =ROW()-6 -> 11 | C17: =IF(VLOOKUP($B17,'1. 현장별 인원현황'!$C:$J,2,0)=0,"",VLOOKUP($B17,'1. 현장별 인원현황'!$C:$J,2,0)) -> [1.DL건설] 전도관구역 주택재개발 정비사업조합(01공구) | D17: =IF(VLOOKUP($B17,'1. 현장별 인원현황'!$C:$J,3,0)=0,"",VLOOKUP($B17,'1. 현장별 인원현황'!$C:$J,3,0)) -> 이후승 | E17: =IF(VLOOKUP($B17,'1. 현장별 인원현황'!$C:$J,4,0)=0,"",VLOOKUP($B17,'1. 현장별 인원현황'!$C:$J,4,0)) -> 27세 | F17: =IF(VLOOKUP($B17,'1. 현장별 인원현황'!$C:$J,7,0)=0,"",VLOOKUP($B17,'1. 현장별 인원현황'!$C:$J,7,0)) -> 기능공 | G17: =IF(VLOOKUP($B17,'1. 현장별 인원현황'!$C:$J,8,0)=0,"",VLOOKUP($B17,'1. 현장별 인원현황'!$C:$J,8,0)) -> 전공 | I17: O | L17: O | P17: O | U17: O | X17: O | AB17: O | AF17: O | AJ17: O | AN17: O | AR17: =SUMPRODUCT($H$5:$AQ$5,AV17:CE17) -> 95 | AS17: =IF(AR17>85,"S",IF(AR17>70,"A",IF(AR17>50,"B",IF(AR17>0,"C","")))) -> S | AV17: =IF(H17>0,1,0) -> 0 | AW17: =IF(I17>0,1,0) -> 1 | AX17: =IF(J17>0,1,0) -> 0 | AY17: =IF(K17>0,1,0) -> 0 | AZ17: =IF(L17>0,1,0) -> 1 | BA17: =IF(M17>0,1,0) -> 0 | BB17: =IF(N17>0,1,0) -> 0 | BC17: =IF(O17>0,1,0) -> 0 | ... CE17: =IF(AQ17>0,1,0) -> 0
A18: =MID(C18,3,1)&"팀" -> 1팀 | B18: =ROW()-6 -> 12 | C18: =IF(VLOOKUP($B18,'1. 현장별 인원현황'!$C:$J,2,0)=0,"",VLOOKUP($B18,'1. 현장별 인원현황'!$C:$J,2,0)) -> [1.DL건설] 전도관구역 주택재개발 정비사업조합(01공구) | D18: =IF(VLOOKUP($B18,'1. 현장별 인원현황'!$C:$J,3,0)=0,"",VLOOKUP($B18,'1. 현장별 인원현황'!$C:$J,3,0)) -> 조해제 | E18: =IF(VLOOKUP($B18,'1. 현장별 인원현황'!$C:$J,4,0)=0,"",VLOOKUP($B18,'1. 현장별 인원현황'!$C:$J,4,0)) -> 62세 | F18: =IF(VLOOKUP($B18,'1. 현장별 인원현황'!$C:$J,7,0)=0,"",VLOOKUP($B18,'1. 현장별 인원현황'!$C:$J,7,0)) -> 기능공 | G18: =IF(VLOOKUP($B18,'1. 현장별 인원현황'!$C:$J,8,0)=0,"",VLOOKUP($B18,'1. 현장별 인원현황'!$C:$J,8,0)) -> 전공 | H18: O | M18: O | P18: O | U18: O | X18: O | AB18: O | AF18: O | AJ18: O | AN18: O | AR18: =SUMPRODUCT($H$5:$AQ$5,AV18:CE18) -> 95 | AS18: =IF(AR18>85,"S",IF(AR18>70,"A",IF(AR18>50,"B",IF(AR18>0,"C","")))) -> S | AV18: =IF(H18>0,1,0) -> 1 | AW18: =IF(I18>0,1,0) -> 0 | AX18: =IF(J18>0,1,0) -> 0 | AY18: =IF(K18>0,1,0) -> 0 | AZ18: =IF(L18>0,1,0) -> 0 | BA18: =IF(M18>0,1,0) -> 1 | BB18: =IF(N18>0,1,0) -> 0 | BC18: =IF(O18>0,1,0) -> 0 | ... CE18: =IF(AQ18>0,1,0) -> 0
A19: =MID(C19,3,1)&"팀" -> 1팀 | B19: =ROW()-6 -> 13 | C19: =IF(VLOOKUP($B19,'1. 현장별 인원현황'!$C:$J,2,0)=0,"",VLOOKUP($B19,'1. 현장별 인원현황'!$C:$J,2,0)) -> [1.대우건설] 고양향동 지원1BL 지식산업센터 신축공사 | D19: =IF(VLOOKUP($B19,'1. 현장별 인원현황'!$C:$J,3,0)=0,"",VLOOKUP($B19,'1. 현장별 인원현황'!$C:$J,3,0)) -> 홍병수 | E19: =IF(VLOOKUP($B19,'1. 현장별 인원현황'!$C:$J,4,0)=0,"",VLOOKUP($B19,'1. 현장별 인원현황'!$C:$J,4,0)) -> 44세 | F19: =IF(VLOOKUP($B19,'1. 현장별 인원현황'!$C:$J,7,0)=0,"",VLOOKUP($B19,'1. 현장별 인원현황'!$C:$J,7,0)) -> 공무 | G19: =IF(VLOOKUP($B19,'1. 현장별 인원현황'!$C:$J,8,0)=0,"",VLOOKUP($B19,'1. 현장별 인원현황'!$C:$J,8,0)) -> 과장 | H19: O | L19: O | P19: O | T19: O | X19: O | AB19: O | AF19: O | AJ19: O | AN19: O | AR19: =SUMPRODUCT($H$5:$AQ$5,AV19:CE19) -> 100 | AS19: =IF(AR19>85,"S",IF(AR19>70,"A",IF(AR19>50,"B",IF(AR19>0,"C","")))) -> S | AV19: =IF(H19>0,1,0) -> 1 | AW19: =IF(I19>0,1,0) -> 0 | AX19: =IF(J19>0,1,0) -> 0 | AY19: =IF(K19>0,1,0) -> 0 | AZ19: =IF(L19>0,1,0) -> 1 | BA19: =IF(M19>0,1,0) -> 0 | BB19: =IF(N19>0,1,0) -> 0 | BC19: =IF(O19>0,1,0) -> 0 | ... CE19: =IF(AQ19>0,1,0) -> 0
A20: =MID(C20,3,1)&"팀" -> 1팀 | B20: =ROW()-6 -> 14 | C20: =IF(VLOOKUP($B20,'1. 현장별 인원현황'!$C:$J,2,0)=0,"",VLOOKUP($B20,'1. 현장별 인원현황'!$C:$J,2,0)) -> [1.대우건설] 고양향동 지원1BL 지식산업센터 신축공사 | D20: =IF(VLOOKUP($B20,'1. 현장별 인원현황'!$C:$J,3,0)=0,"",VLOOKUP($B20,'1. 현장별 인원현황'!$C:$J,3,0)) -> 남치원 | E20: =IF(VLOOKUP($B20,'1. 현장별 인원현황'!$C:$J,4,0)=0,"",VLOOKUP($B20,'1. 현장별 인원현황'!$C:$J,4,0)) -> 63세 | F20: =IF(VLOOKUP($B20,'1. 현장별 인원현황'!$C:$J,7,0)=0,"",VLOOKUP($B20,'1. 현장별 인원현황'!$C:$J,7,0)) -> 공사 | G20: =IF(VLOOKUP($B20,'1. 현장별 인원현황'!$C:$J,8,0)=0,"",VLOOKUP($B20,'1. 현장별 인원현황'!$C:$J,8,0)) -> 차장 | H20: O | L20: O | P20: O | T20: O | X20: O | AB20: O | AF20: O | AJ20: O | AN20: O | AR20: =SUMPRODUCT($H$5:$AQ$5,AV20:CE20) -> 100 | AS20: =IF(AR20>85,"S",IF(AR20>70,"A",IF(AR20>50,"B",IF(AR20>0,"C","")))) -> S | AV20: =IF(H20>0,1,0) -> 1 | AW20: =IF(I20>0,1,0) -> 0 | AX20: =IF(J20>0,1,0) -> 0 | AY20: =IF(K20>0,1,0) -> 0 | AZ20: =IF(L20>0,1,0) -> 1 | BA20: =IF(M20>0,1,0) -> 0 | BB20: =IF(N20>0,1,0) -> 0 | BC20: =IF(O20>0,1,0) -> 0 | ... CE20: =IF(AQ20>0,1,0) -> 0
A21: =MID(C21,3,1)&"팀" -> 1팀 | B21: =ROW()-6 -> 15 | C21: =IF(VLOOKUP($B21,'1. 현장별 인원현황'!$C:$J,2,0)=0,"",VLOOKUP($B21,'1. 현장별 인원현황'!$C:$J,2,0)) -> [1.대우건설] 고양향동 지원1BL 지식산업센터 신축공사 | D21: =IF(VLOOKUP($B21,'1. 현장별 인원현황'!$C:$J,3,0)=0,"",VLOOKUP($B21,'1. 현장별 인원현황'!$C:$J,3,0)) -> 문대준 | E21: =IF(VLOOKUP($B21,'1. 현장별 인원현황'!$C:$J,4,0)=0,"",VLOOKUP($B21,'1. 현장별 인원현황'!$C:$J,4,0)) -> 58세 | F21: =IF(VLOOKUP($B21,'1. 현장별 인원현황'!$C:$J,7,0)=0,"",VLOOKUP($B21,'1. 현장별 인원현황'!$C:$J,7,0)) -> 공사 | G21: =IF(VLOOKUP($B21,'1. 현장별 인원현황'!$C:$J,8,0)=0,"",VLOOKUP($B21,'1. 현장별 인원현황'!$C:$J,8,0)) -> 차장 | I21: O | L21: O | Q21: O | U21: O | Y21: O | AB21: O | AG21: O | AJ21: O | AN21: O | AR21: =SUMPRODUCT($H$5:$AQ$5,AV21:CE21) -> 88 | AS21: =IF(AR21>85,"S",IF(AR21>70,"A",IF(AR21>50,"B",IF(AR21>0,"C","")))) -> S | AV21: =IF(H21>0,1,0) -> 0 | AW21: =IF(I21>0,1,0) -> 1 | AX21: =IF(J21>0,1,0) -> 0 | AY21: =IF(K21>0,1,0) -> 0 | AZ21: =IF(L21>0,1,0) -> 1 | BA21: =IF(M21>0,1,0) -> 0 | BB21: =IF(N21>0,1,0) -> 0 | BC21: =IF(O21>0,1,0) -> 0 | ... CE21: =IF(AQ21>0,1,0) -> 0
A22: =MID(C22,3,1)&"팀" -> 1팀 | B22: =ROW()-6 -> 16 | C22: =IF(VLOOKUP($B22,'1. 현장별 인원현황'!$C:$J,2,0)=0,"",VLOOKUP($B22,'1. 현장별 인원현황'!$C:$J,2,0)) -> [1.대우건설] 고양향동 지원1BL 지식산업센터 신축공사 | D22: =IF(VLOOKUP($B22,'1. 현장별 인원현황'!$C:$J,3,0)=0,"",VLOOKUP($B22,'1. 현장별 인원현황'!$C:$J,3,0)) -> 김인철 | E22: =IF(VLOOKUP($B22,'1. 현장별 인원현황'!$C:$J,4,0)=0,"",VLOOKUP($B22,'1. 현장별 인원현황'!$C:$J,4,0)) -> 68세 | F22: =IF(VLOOKUP($B22,'1. 현장별 인원현황'!$C:$J,7,0)=0,"",VLOOKUP($B22,'1. 현장별 인원현황'!$C:$J,7,0)) -> 기능공 | G22: =IF(VLOOKUP($B22,'1. 현장별 인원현황'!$C:$J,8,0)=0,"",VLOOKUP($B22,'1. 현장별 인원현황'!$C:$J,8,0)) -> 전공 | I22: O | L22: O | Q22: O | U22: O | Y22: O | AC22: O | AG22: O | AJ22: O | AN22: O | AR22: =SUMPRODUCT($H$5:$AQ$5,AV22:CE22) -> 86 | AS22: =IF(AR22>85,"S",IF(AR22>70,"A",IF(AR22>50,"B",IF(AR22>0,"C","")))) -> S | AV22: =IF(H22>0,1,0) -> 0 | AW22: =IF(I22>0,1,0) -> 1 | AX22: =IF(J22>0,1,0) -> 0 | AY22: =IF(K22>0,1,0) -> 0 | AZ22: =IF(L22>0,1,0) -> 1 | BA22: =IF(M22>0,1,0) -> 0 | BB22: =IF(N22>0,1,0) -> 0 | BC22: =IF(O22>0,1,0) -> 0 | ... CE22: =IF(AQ22>0,1,0) -> 0
A23: =MID(C23,3,1)&"팀" -> 1팀 | B23: =ROW()-6 -> 17 | C23: =IF(VLOOKUP($B23,'1. 현장별 인원현황'!$C:$J,2,0)=0,"",VLOOKUP($B23,'1. 현장별 인원현황'!$C:$J,2,0)) -> [1.대우건설] 고양향동 지원1BL 지식산업센터 신축공사 | D23: =IF(VLOOKUP($B23,'1. 현장별 인원현황'!$C:$J,3,0)=0,"",VLOOKUP($B23,'1. 현장별 인원현황'!$C:$J,3,0)) -> 엄관영 | E23: =IF(VLOOKUP($B23,'1. 현장별 인원현황'!$C:$J,4,0)=0,"",VLOOKUP($B23,'1. 현장별 인원현황'!$C:$J,4,0)) -> 64세 | F23: =IF(VLOOKUP($B23,'1. 현장별 인원현황'!$C:$J,7,0)=0,"",VLOOKUP($B23,'1. 현장별 인원현황'!$C:$J,7,0)) -> 기능공 | G23: =IF(VLOOKUP($B23,'1. 현장별 인원현황'!$C:$J,8,0)=0,"",VLOOKUP($B23,'1. 현장별 인원현황'!$C:$J,8,0)) -> 전공 | J23: O | M23: O | R23: O | U23: O | Y23: O | AC23: O | AG23: O | AJ23: O | AN23: O | AR23: =SUMPRODUCT($H$5:$AQ$5,AV23:CE23) -> 77 | AS23: =IF(AR23>85,"S",IF(AR23>70,"A",IF(AR23>50,"B",IF(AR23>0,"C","")))) -> A | AV23: =IF(H23>0,1,0) -> 0 | AW23: =IF(I23>0,1,0) -> 0 | AX23: =IF(J23>0,1,0) -> 1 | AY23: =IF(K23>0,1,0) -> 0 | AZ23: =IF(L23>0,1,0) -> 0 | BA23: =IF(M23>0,1,0) -> 1 | BB23: =IF(N23>0,1,0) -> 0 | BC23: =IF(O23>0,1,0) -> 0 | ... CE23: =IF(AQ23>0,1,0) -> 0
A24: =MID(C24,3,1)&"팀" -> 1팀 | B24: =ROW()-6 -> 18 | C24: =IF(VLOOKUP($B24,'1. 현장별 인원현황'!$C:$J,2,0)=0,"",VLOOKUP($B24,'1. 현장별 인원현황'!$C:$J,2,0)) -> [1.대우건설] 인천검단 신도시 AA28BL 공동주택 신축공사 | D24: =IF(VLOOKUP($B24,'1. 현장별 인원현황'!$C:$J,3,0)=0,"",VLOOKUP($B24,'1. 현장별 인원현황'!$C:$J,3,0)) -> 윤홍식 | E24: =IF(VLOOKUP($B24,'1. 현장별 인원현황'!$C:$J,4,0)=0,"",VLOOKUP($B24,'1. 현장별 인원현황'!$C:$J,4,0)) -> 49세 | F24: =IF(VLOOKUP($B24,'1. 현장별 인원현황'!$C:$J,7,0)=0,"",VLOOKUP($B24,'1. 현장별 인원현황'!$C:$J,7,0)) -> 공무 | G24: =IF(VLOOKUP($B24,'1. 현장별 인원현황'!$C:$J,8,0)=0,"",VLOOKUP($B24,'1. 현장별 인원현황'!$C:$J,8,0)) -> 차장 | H24: O | L24: O | P24: O | T24: O | X24: O | AB24: O | AF24: O | AJ24: O | AN24: O | AR24: =SUMPRODUCT($H$5:$AQ$5,AV24:CE24) -> 100 | AS24: =IF(AR24>85,"S",IF(AR24>70,"A",IF(AR24>50,"B",IF(AR24>0,"C","")))) -> S | AV24: =IF(H24>0,1,0) -> 1 | AW24: =IF(I24>0,1,0) -> 0 | AX24: =IF(J24>0,1,0) -> 0 | AY24: =IF(K24>0,1,0) -> 0 | AZ24: =IF(L24>0,1,0) -> 1 | BA24: =IF(M24>0,1,0) -> 0 | BB24: =IF(N24>0,1,0) -> 0 | BC24: =IF(O24>0,1,0) -> 0 | ... CE24: =IF(AQ24>0,1,0) -> 0
A25: =MID(C25,3,1)&"팀" -> 1팀 | B25: =ROW()-6 -> 19 | C25: =IF(VLOOKUP($B25,'1. 현장별 인원현황'!$C:$J,2,0)=0,"",VLOOKUP($B25,'1. 현장별 인원현황'!$C:$J,2,0)) -> [1.대우건설] 인천검단 신도시 AA28BL 공동주택 신축공사 | D25: =IF(VLOOKUP($B25,'1. 현장별 인원현황'!$C:$J,3,0)=0,"",VLOOKUP($B25,'1. 현장별 인원현황'!$C:$J,3,0)) -> 김지호 | E25: =IF(VLOOKUP($B25,'1. 현장별 인원현황'!$C:$J,4,0)=0,"",VLOOKUP($B25,'1. 현장별 인원현황'!$C:$J,4,0)) -> 31세 | F25: =IF(VLOOKUP($B25,'1. 현장별 인원현황'!$C:$J,7,0)=0,"",VLOOKUP($B25,'1. 현장별 인원현황'!$C:$J,7,0)) -> 안전관리자 | G25: =IF(VLOOKUP($B25,'1. 현장별 인원현황'!$C:$J,8,0)=0,"",VLOOKUP($B25,'1. 현장별 인원현황'!$C:$J,8,0)) -> 대리 | I25: O | M25: O | Q25: O | U25: O | Y25: O | AC25: O | AF25: O | AK25: O | AN25: O | AR25: =SUMPRODUCT($H$5:$AQ$5,AV25:CE25) -> 82 | AS25: =IF(AR25>85,"S",IF(AR25>70,"A",IF(AR25>50,"B",IF(AR25>0,"C","")))) -> A | AV25: =IF(H25>0,1,0) -> 0 | AW25: =IF(I25>0,1,0) -> 1 | AX25: =IF(J25>0,1,0) -> 0 | AY25: =IF(K25>0,1,0) -> 0 | AZ25: =IF(L25>0,1,0) -> 0 | BA25: =IF(M25>0,1,0) -> 1 | BB25: =IF(N25>0,1,0) -> 0 | BC25: =IF(O25>0,1,0) -> 0 | ... CE25: =IF(AQ25>0,1,0) -> 0
A26: =MID(C26,3,1)&"팀" -> 1팀 | B26: =ROW()-6 -> 20 | C26: =IF(VLOOKUP($B26,'1. 현장별 인원현황'!$C:$J,2,0)=0,"",VLOOKUP($B26,'1. 현장별 인원현황'!$C:$J,2,0)) -> [1.대우건설] 인천검단 신도시 AA28BL 공동주택 신축공사 | D26: =IF(VLOOKUP($B26,'1. 현장별 인원현황'!$C:$J,3,0)=0,"",VLOOKUP($B26,'1. 현장별 인원현황'!$C:$J,3,0)) -> 차성철 | E26: =IF(VLOOKUP($B26,'1. 현장별 인원현황'!$C:$J,4,0)=0,"",VLOOKUP($B26,'1. 현장별 인원현황'!$C:$J,4,0)) -> 51세 | F26: =IF(VLOOKUP($B26,'1. 현장별 인원현황'!$C:$J,7,0)=0,"",VLOOKUP($B26,'1. 현장별 인원현황'!$C:$J,7,0)) -> 기능공 | G26: =IF(VLOOKUP($B26,'1. 현장별 인원현황'!$C:$J,8,0)=0,"",VLOOKUP($B26,'1. 현장별 인원현황'!$C:$J,8,0)) -> 전공 | H26: O | L26: O | P26: O | T26: O | X26: O | AB26: O | AF26: O | AJ26: O | AN26: O | AR26: =SUMPRODUCT($H$5:$AQ$5,AV26:CE26) -> 100 | AS26: =IF(AR26>85,"S",IF(AR26>70,"A",IF(AR26>50,"B",IF(AR26>0,"C","")))) -> S | AV26: =IF(H26>0,1,0) -> 1 | AW26: =IF(I26>0,1,0) -> 0 | AX26: =IF(J26>0,1,0) -> 0 | AY26: =IF(K26>0,1,0) -> 0 | AZ26: =IF(L26>0,1,0) -> 1 | BA26: =IF(M26>0,1,0) -> 0 | BB26: =IF(N26>0,1,0) -> 0 | BC26: =IF(O26>0,1,0) -> 0 | ... CE26: =IF(AQ26>0,1,0) -> 0
A27: =MID(C27,3,1)&"팀" -> 1팀 | B27: =ROW()-6 -> 21 | C27: =IF(VLOOKUP($B27,'1. 현장별 인원현황'!$C:$J,2,0)=0,"",VLOOKUP($B27,'1. 현장별 인원현황'!$C:$J,2,0)) -> [1.대우건설] 인천검단 신도시 AA28BL 공동주택 신축공사 | D27: =IF(VLOOKUP($B27,'1. 현장별 인원현황'!$C:$J,3,0)=0,"",VLOOKUP($B27,'1. 현장별 인원현황'!$C:$J,3,0)) -> 박상걸 | E27: =IF(VLOOKUP($B27,'1. 현장별 인원현황'!$C:$J,4,0)=0,"",VLOOKUP($B27,'1. 현장별 인원현황'!$C:$J,4,0)) -> 46세 | F27: =IF(VLOOKUP($B27,'1. 현장별 인원현황'!$C:$J,7,0)=0,"",VLOOKUP($B27,'1. 현장별 인원현황'!$C:$J,7,0)) -> 기능공 | G27: =IF(VLOOKUP($B27,'1. 현장별 인원현황'!$C:$J,8,0)=0,"",VLOOKUP($B27,'1. 현장별 인원현황'!$C:$J,8,0)) -> 전공 | I27: O | M27: O | Q27: O | U27: O | Y27: O | AC27: O | AG27: O | AK27: O | AN27: O | AR27: =SUMPRODUCT($H$5:$AQ$5,AV27:CE27) -> 80 | AS27: =IF(AR27>85,"S",IF(AR27>70,"A",IF(AR27>50,"B",IF(AR27>0,"C","")))) -> A | AV27: =IF(H27>0,1,0) -> 0 | AW27: =IF(I27>0,1,0) -> 1 | AX27: =IF(J27>0,1,0) -> 0 | AY27: =IF(K27>0,1,0) -> 0 | AZ27: =IF(L27>0,1,0) -> 0 | BA27: =IF(M27>0,1,0) -> 1 | BB27: =IF(N27>0,1,0) -> 0 | BC27: =IF(O27>0,1,0) -> 0 | ... CE27: =IF(AQ27>0,1,0) -> 0
A28: =MID(C28,3,1)&"팀" -> 1팀 | B28: =ROW()-6 -> 22 | C28: =IF(VLOOKUP($B28,'1. 현장별 인원현황'!$C:$J,2,0)=0,"",VLOOKUP($B28,'1. 현장별 인원현황'!$C:$J,2,0)) -> [1.대우건설] 인천검단 신도시 AA28BL 공동주택 신축공사 | D28: =IF(VLOOKUP($B28,'1. 현장별 인원현황'!$C:$J,3,0)=0,"",VLOOKUP($B28,'1. 현장별 인원현황'!$C:$J,3,0)) -> 이세열 | E28: =IF(VLOOKUP($B28,'1. 현장별 인원현황'!$C:$J,4,0)=0,"",VLOOKUP($B28,'1. 현장별 인원현황'!$C:$J,4,0)) -> 42세 | F28: =IF(VLOOKUP($B28,'1. 현장별 인원현황'!$C:$J,7,0)=0,"",VLOOKUP($B28,'1. 현장별 인원현황'!$C:$J,7,0)) -> 기능공 | G28: =IF(VLOOKUP($B28,'1. 현장별 인원현황'!$C:$J,8,0)=0,"",VLOOKUP($B28,'1. 현장별 인원현황'!$C:$J,8,0)) -> 전공 | I28: O | L28: O | P28: O | T28: O | X28: O | AB28: O | AF28: O | AJ28: O | AN28: O | AR28: =SUMPRODUCT($H$5:$AQ$5,AV28:CE28) -> 97 | AS28: =IF(AR28>85,"S",IF(AR28>70,"A",IF(AR28>50,"B",IF(AR28>0,"C","")))) -> S | AV28: =IF(H28>0,1,0) -> 0 | AW28: =IF(I28>0,1,0) -> 1 | AX28: =IF(J28>0,1,0) -> 0 | AY28: =IF(K28>0,1,0) -> 0 | AZ28: =IF(L28>0,1,0) -> 1 | BA28: =IF(M28>0,1,0) -> 0 | BB28: =IF(N28>0,1,0) -> 0 | BC28: =IF(O28>0,1,0) -> 0 | ... CE28: =IF(AQ28>0,1,0) -> 0
A29: =MID(C29,3,1)&"팀" -> 1팀 | B29: =ROW()-6 -> 23 | C29: =IF(VLOOKUP($B29,'1. 현장별 인원현황'!$C:$J,2,0)=0,"",VLOOKUP($B29,'1. 현장별 인원현황'!$C:$J,2,0)) -> [1.대우건설] 인천검단 신도시 AA28BL 공동주택 신축공사 | D29: =IF(VLOOKUP($B29,'1. 현장별 인원현황'!$C:$J,3,0)=0,"",VLOOKUP($B29,'1. 현장별 인원현황'!$C:$J,3,0)) -> 한성필 | E29: =IF(VLOOKUP($B29,'1. 현장별 인원현황'!$C:$J,4,0)=0,"",VLOOKUP($B29,'1. 현장별 인원현황'!$C:$J,4,0)) -> 53세 | F29: =IF(VLOOKUP($B29,'1. 현장별 인원현황'!$C:$J,7,0)=0,"",VLOOKUP($B29,'1. 현장별 인원현황'!$C:$J,7,0)) -> 기능공 | G29: =IF(VLOOKUP($B29,'1. 현장별 인원현황'!$C:$J,8,0)=0,"",VLOOKUP($B29,'1. 현장별 인원현황'!$C:$J,8,0)) -> 전공 | H29: O | L29: O | P29: O | T29: O | X29: O | AB29: O | AF29: O | AJ29: O | AN29: O | AR29: =SUMPRODUCT($H$5:$AQ$5,AV29:CE29) -> 100 | AS29: =IF(AR29>85,"S",IF(AR29>70,"A",IF(AR29>50,"B",IF(AR29>0,"C","")))) -> S | AV29: =IF(H29>0,1,0) -> 1 | AW29: =IF(I29>0,1,0) -> 0 | AX29: =IF(J29>0,1,0) -> 0 | AY29: =IF(K29>0,1,0) -> 0 | AZ29: =IF(L29>0,1,0) -> 1 | BA29: =IF(M29>0,1,0) -> 0 | BB29: =IF(N29>0,1,0) -> 0 | BC29: =IF(O29>0,1,0) -> 0 | ... CE29: =IF(AQ29>0,1,0) -> 0
A30: =MID(C30,3,1)&"팀" -> 1팀 | B30: =ROW()-6 -> 24 | C30: =IF(VLOOKUP($B30,'1. 현장별 인원현황'!$C:$J,2,0)=0,"",VLOOKUP($B30,'1. 현장별 인원현황'!$C:$J,2,0)) -> [1.대우건설] 장위6구역 주택재개발 정비사업아파트 신축공사 | D30: =IF(VLOOKUP($B30,'1. 현장별 인원현황'!$C:$J,3,0)=0,"",VLOOKUP($B30,'1. 현장별 인원현황'!$C:$J,3,0)) -> 강지성 | E30: =IF(VLOOKUP($B30,'1. 현장별 인원현황'!$C:$J,4,0)=0,"",VLOOKUP($B30,'1. 현장별 인원현황'!$C:$J,4,0)) -> 50세 | F30: =IF(VLOOKUP($B30,'1. 현장별 인원현황'!$C:$J,7,0)=0,"",VLOOKUP($B30,'1. 현장별 인원현황'!$C:$J,7,0)) -> 공무 | G30: =IF(VLOOKUP($B30,'1. 현장별 인원현황'!$C:$J,8,0)=0,"",VLOOKUP($B30,'1. 현장별 인원현황'!$C:$J,8,0)) -> 차장 | H30: O | L30: O | P30: O | T30: O | AA30: O | AD30: O | AH30: O | AK30: O | AQ30: O | AR30: =SUMPRODUCT($H$5:$AQ$5,AV30:CE30) -> 74 | AS30: =IF(AR30>85,"S",IF(AR30>70,"A",IF(AR30>50,"B",IF(AR30>0,"C","")))) -> A | AV30: =IF(H30>0,1,0) -> 1 | AW30: =IF(I30>0,1,0) -> 0 | AX30: =IF(J30>0,1,0) -> 0 | AY30: =IF(K30>0,1,0) -> 0 | AZ30: =IF(L30>0,1,0) -> 1 | BA30: =IF(M30>0,1,0) -> 0 | BB30: =IF(N30>0,1,0) -> 0 | BC30: =IF(O30>0,1,0) -> 0 | ... CE30: =IF(AQ30>0,1,0) -> 1
A31: =MID(C31,3,1)&"팀" -> 1팀 | B31: =ROW()-6 -> 25 | C31: =IF(VLOOKUP($B31,'1. 현장별 인원현황'!$C:$J,2,0)=0,"",VLOOKUP($B31,'1. 현장별 인원현황'!$C:$J,2,0)) -> [1.대우건설] 장위6구역 주택재개발 정비사업아파트 신축공사 | D31: =IF(VLOOKUP($B31,'1. 현장별 인원현황'!$C:$J,3,0)=0,"",VLOOKUP($B31,'1. 현장별 인원현황'!$C:$J,3,0)) -> 이시우 | E31: =IF(VLOOKUP($B31,'1. 현장별 인원현황'!$C:$J,4,0)=0,"",VLOOKUP($B31,'1. 현장별 인원현황'!$C:$J,4,0)) -> 24세 | F31: =IF(VLOOKUP($B31,'1. 현장별 인원현황'!$C:$J,7,0)=0,"",VLOOKUP($B31,'1. 현장별 인원현황'!$C:$J,7,0)) -> 공무 | G31: =IF(VLOOKUP($B31,'1. 현장별 인원현황'!$C:$J,8,0)=0,"",VLOOKUP($B31,'1. 현장별 인원현황'!$C:$J,8,0)) -> 대리 | H31: O | L31: O | P31: O | U31: O | X31: O | AB31: O | AG31: O | AJ31: O | AN31: O | AR31: =SUMPRODUCT($H$5:$AQ$5,AV31:CE31) -> 96 | AS31: =IF(AR31>85,"S",IF(AR31>70,"A",IF(AR31>50,"B",IF(AR31>0,"C","")))) -> S | AV31: =IF(H31>0,1,0) -> 1 | AW31: =IF(I31>0,1,0) -> 0 | AX31: =IF(J31>0,1,0) -> 0 | AY31: =IF(K31>0,1,0) -> 0 | AZ31: =IF(L31>0,1,0) -> 1 | BA31: =IF(M31>0,1,0) -> 0 | BB31: =IF(N31>0,1,0) -> 0 | BC31: =IF(O31>0,1,0) -> 0 | ... CE31: =IF(AQ31>0,1,0) -> 0
A32: =MID(C32,3,1)&"팀" -> 1팀 | B32: =ROW()-6 -> 26 | C32: =IF(VLOOKUP($B32,'1. 현장별 인원현황'!$C:$J,2,0)=0,"",VLOOKUP($B32,'1. 현장별 인원현황'!$C:$J,2,0)) -> [1.대우건설] 장위6구역 주택재개발 정비사업아파트 신축공사 | D32: =IF(VLOOKUP($B32,'1. 현장별 인원현황'!$C:$J,3,0)=0,"",VLOOKUP($B32,'1. 현장별 인원현황'!$C:$J,3,0)) -> 정 권 | E32: =IF(VLOOKUP($B32,'1. 현장별 인원현황'!$C:$J,4,0)=0,"",VLOOKUP($B32,'1. 현장별 인원현황'!$C:$J,4,0)) -> 60세 | F32: =IF(VLOOKUP($B32,'1. 현장별 인원현황'!$C:$J,7,0)=0,"",VLOOKUP($B32,'1. 현장별 인원현황'!$C:$J,7,0)) -> 공사 | G32: =IF(VLOOKUP($B32,'1. 현장별 인원현황'!$C:$J,8,0)=0,"",VLOOKUP($B32,'1. 현장별 인원현황'!$C:$J,8,0)) -> 차장 | H32: O | L32: O | P32: O | T32: O | X32: O | AB32: O | AG32: O | AJ32: O | AO32: O | AR32: =SUMPRODUCT($H$5:$AQ$5,AV32:CE32) -> 95 | AS32: =IF(AR32>85,"S",IF(AR32>70,"A",IF(AR32>50,"B",IF(AR32>0,"C","")))) -> S | AV32: =IF(H32>0,1,0) -> 1 | AW32: =IF(I32>0,1,0) -> 0 | AX32: =IF(J32>0,1,0) -> 0 | AY32: =IF(K32>0,1,0) -> 0 | AZ32: =IF(L32>0,1,0) -> 1 | BA32: =IF(M32>0,1,0) -> 0 | BB32: =IF(N32>0,1,0) -> 0 | BC32: =IF(O32>0,1,0) -> 0 | ... CE32: =IF(AQ32>0,1,0) -> 0
A33: =MID(C33,3,1)&"팀" -> 1팀 | B33: =ROW()-6 -> 27 | C33: =IF(VLOOKUP($B33,'1. 현장별 인원현황'!$C:$J,2,0)=0,"",VLOOKUP($B33,'1. 현장별 인원현황'!$C:$J,2,0)) -> [1.대우건설] 장위6구역 주택재개발 정비사업아파트 신축공사 | D33: =IF(VLOOKUP($B33,'1. 현장별 인원현황'!$C:$J,3,0)=0,"",VLOOKUP($B33,'1. 현장별 인원현황'!$C:$J,3,0)) -> 성경웅 | E33: =IF(VLOOKUP($B33,'1. 현장별 인원현황'!$C:$J,4,0)=0,"",VLOOKUP($B33,'1. 현장별 인원현황'!$C:$J,4,0)) -> 56세 | F33: =IF(VLOOKUP($B33,'1. 현장별 인원현황'!$C:$J,7,0)=0,"",VLOOKUP($B33,'1. 현장별 인원현황'!$C:$J,7,0)) -> 공사 | G33: =IF(VLOOKUP($B33,'1. 현장별 인원현황'!$C:$J,8,0)=0,"",VLOOKUP($B33,'1. 현장별 인원현황'!$C:$J,8,0)) -> 차장 | H33: O | L33: O | P33: O | T33: O | X33: O | AB33: O | AF33: O | AJ33: O | AN33: O | AR33: =SUMPRODUCT($H$5:$AQ$5,AV33:CE33) -> 100 | AS33: =IF(AR33>85,"S",IF(AR33>70,"A",IF(AR33>50,"B",IF(AR33>0,"C","")))) -> S | AV33: =IF(H33>0,1,0) -> 1 | AW33: =IF(I33>0,1,0) -> 0 | AX33: =IF(J33>0,1,0) -> 0 | AY33: =IF(K33>0,1,0) -> 0 | AZ33: =IF(L33>0,1,0) -> 1 | BA33: =IF(M33>0,1,0) -> 0 | BB33: =IF(N33>0,1,0) -> 0 | BC33: =IF(O33>0,1,0) -> 0 | ... CE33: =IF(AQ33>0,1,0) -> 0
A34: =MID(C34,3,1)&"팀" -> 1팀 | B34: =ROW()-6 -> 28 | C34: =IF(VLOOKUP($B34,'1. 현장별 인원현황'!$C:$J,2,0)=0,"",VLOOKUP($B34,'1. 현장별 인원현황'!$C:$J,2,0)) -> [1.대우건설] 장위6구역 주택재개발 정비사업아파트 신축공사 | D34: =IF(VLOOKUP($B34,'1. 현장별 인원현황'!$C:$J,3,0)=0,"",VLOOKUP($B34,'1. 현장별 인원현황'!$C:$J,3,0)) -> 용효중 | E34: =IF(VLOOKUP($B34,'1. 현장별 인원현황'!$C:$J,4,0)=0,"",VLOOKUP($B34,'1. 현장별 인원현황'!$C:$J,4,0)) -> 49세 | F34: =IF(VLOOKUP($B34,'1. 현장별 인원현황'!$C:$J,7,0)=0,"",VLOOKUP($B34,'1. 현장별 인원현황'!$C:$J,7,0)) -> 기능공 | G34: =IF(VLOOKUP($B34,'1. 현장별 인원현황'!$C:$J,8,0)=0,"",VLOOKUP($B34,'1. 현장별 인원현황'!$C:$J,8,0)) -> 전공 | H34: O | M34: O | P34: O | T34: O | X34: O | AC34: O | AG34: O | AJ34: O | AN34: O | AR34: =SUMPRODUCT($H$5:$AQ$5,AV34:CE34) -> 93 | AS34: =IF(AR34>85,"S",IF(AR34>70,"A",IF(AR34>50,"B",IF(AR34>0,"C","")))) -> S | AV34: =IF(H34>0,1,0) -> 1 | AW34: =IF(I34>0,1,0) -> 0 | AX34: =IF(J34>0,1,0) -> 0 | AY34: =IF(K34>0,1,0) -> 0 | AZ34: =IF(L34>0,1,0) -> 0 | BA34: =IF(M34>0,1,0) -> 1 | BB34: =IF(N34>0,1,0) -> 0 | BC34: =IF(O34>0,1,0) -> 0 | ... CE34: =IF(AQ34>0,1,0) -> 0
A35: =MID(C35,3,1)&"팀" -> 1팀 | B35: =ROW()-6 -> 29 | C35: =IF(VLOOKUP($B35,'1. 현장별 인원현황'!$C:$J,2,0)=0,"",VLOOKUP($B35,'1. 현장별 인원현황'!$C:$J,2,0)) -> [1.대우건설] 장위6구역 주택재개발 정비사업아파트 신축공사 | D35: =IF(VLOOKUP($B35,'1. 현장별 인원현황'!$C:$J,3,0)=0,"",VLOOKUP($B35,'1. 현장별 인원현황'!$C:$J,3,0)) -> 서경배 | E35: =IF(VLOOKUP($B35,'1. 현장별 인원현황'!$C:$J,4,0)=0,"",VLOOKUP($B35,'1. 현장별 인원현황'!$C:$J,4,0)) -> 62세 | F35: =IF(VLOOKUP($B35,'1. 현장별 인원현황'!$C:$J,7,0)=0,"",VLOOKUP($B35,'1. 현장별 인원현황'!$C:$J,7,0)) -> 기능공 | G35: =IF(VLOOKUP($B35,'1. 현장별 인원현황'!$C:$J,8,0)=0,"",VLOOKUP($B35,'1. 현장별 인원현황'!$C:$J,8,0)) -> 전공 | I35: O | L35: O | P35: O | T35: O | X35: O | AB35: O | AG35: O | AJ35: O | AN35: O | AR35: =SUMPRODUCT($H$5:$AQ$5,AV35:CE35) -> 95 | AS35: =IF(AR35>85,"S",IF(AR35>70,"A",IF(AR35>50,"B",IF(AR35>0,"C","")))) -> S | AV35: =IF(H35>0,1,0) -> 0 | AW35: =IF(I35>0,1,0) -> 1 | AX35: =IF(J35>0,1,0) -> 0 | AY35: =IF(K35>0,1,0) -> 0 | AZ35: =IF(L35>0,1,0) -> 1 | BA35: =IF(M35>0,1,0) -> 0 | BB35: =IF(N35>0,1,0) -> 0 | BC35: =IF(O35>0,1,0) -> 0 | ... CE35: =IF(AQ35>0,1,0) -> 0
A36: =MID(C36,3,1)&"팀" -> 1팀 | B36: =ROW()-6 -> 30 | C36: =IF(VLOOKUP($B36,'1. 현장별 인원현황'!$C:$J,2,0)=0,"",VLOOKUP($B36,'1. 현장별 인원현황'!$C:$J,2,0)) -> [1.대우건설] 장위6구역 주택재개발 정비사업아파트 신축공사 | D36: =IF(VLOOKUP($B36,'1. 현장별 인원현황'!$C:$J,3,0)=0,"",VLOOKUP($B36,'1. 현장별 인원현황'!$C:$J,3,0)) -> 장대용 | E36: =IF(VLOOKUP($B36,'1. 현장별 인원현황'!$C:$J,4,0)=0,"",VLOOKUP($B36,'1. 현장별 인원현황'!$C:$J,4,0)) -> 42세 | F36: =IF(VLOOKUP($B36,'1. 현장별 인원현황'!$C:$J,7,0)=0,"",VLOOKUP($B36,'1. 현장별 인원현황'!$C:$J,7,0)) -> 기능공 | G36: =IF(VLOOKUP($B36,'1. 현장별 인원현황'!$C:$J,8,0)=0,"",VLOOKUP($B36,'1. 현장별 인원현황'!$C:$J,8,0)) -> 전공 | H36: O | L36: O | P36: O | T36: O | X36: O | AB36: O | AF36: O | AJ36: O | AN36: O | AR36: =SUMPRODUCT($H$5:$AQ$5,AV36:CE36) -> 100 | AS36: =IF(AR36>85,"S",IF(AR36>70,"A",IF(AR36>50,"B",IF(AR36>0,"C","")))) -> S | AV36: =IF(H36>0,1,0) -> 1 | AW36: =IF(I36>0,1,0) -> 0 | AX36: =IF(J36>0,1,0) -> 0 | AY36: =IF(K36>0,1,0) -> 0 | AZ36: =IF(L36>0,1,0) -> 1 | BA36: =IF(M36>0,1,0) -> 0 | BB36: =IF(N36>0,1,0) -> 0 | BC36: =IF(O36>0,1,0) -> 0 | ... CE36: =IF(AQ36>0,1,0) -> 0
A37: =MID(C37,3,1)&"팀" -> 1팀 | B37: =ROW()-6 -> 31 | C37: =IF(VLOOKUP($B37,'1. 현장별 인원현황'!$C:$J,2,0)=0,"",VLOOKUP($B37,'1. 현장별 인원현황'!$C:$J,2,0)) -> [1.대우건설] 장위6구역 주택재개발 정비사업아파트 신축공사 | D37: =IF(VLOOKUP($B37,'1. 현장별 인원현황'!$C:$J,3,0)=0,"",VLOOKUP($B37,'1. 현장별 인원현황'!$C:$J,3,0)) -> 석준수 | E37: =IF(VLOOKUP($B37,'1. 현장별 인원현황'!$C:$J,4,0)=0,"",VLOOKUP($B37,'1. 현장별 인원현황'!$C:$J,4,0)) -> 50세 | F37: =IF(VLOOKUP($B37,'1. 현장별 인원현황'!$C:$J,7,0)=0,"",VLOOKUP($B37,'1. 현장별 인원현황'!$C:$J,7,0)) -> 기능공 | G37: =IF(VLOOKUP($B37,'1. 현장별 인원현황'!$C:$J,8,0)=0,"",VLOOKUP($B37,'1. 현장별 인원현황'!$C:$J,8,0)) -> 전공 | I37: O | M37: O | Q37: O | T37: O | X37: O | AC37: O | AG37: O | AJ37: O | AO37: O | AR37: =SUMPRODUCT($H$5:$AQ$5,AV37:CE37) -> 84 | AS37: =IF(AR37>85,"S",IF(AR37>70,"A",IF(AR37>50,"B",IF(AR37>0,"C","")))) -> A | AV37: =IF(H37>0,1,0) -> 0 | AW37: =IF(I37>0,1,0) -> 1 | AX37: =IF(J37>0,1,0) -> 0 | AY37: =IF(K37>0,1,0) -> 0 | AZ37: =IF(L37>0,1,0) -> 0 | BA37: =IF(M37>0,1,0) -> 1 | BB37: =IF(N37>0,1,0) -> 0 | BC37: =IF(O37>0,1,0) -> 0 | ... CE37: =IF(AQ37>0,1,0) -> 0
A38: =MID(C38,3,1)&"팀" -> 1팀 | B38: =ROW()-6 -> 32 | C38: =IF(VLOOKUP($B38,'1. 현장별 인원현황'!$C:$J,2,0)=0,"",VLOOKUP($B38,'1. 현장별 인원현황'!$C:$J,2,0)) -> [1.대우건설] 장위6구역 주택재개발 정비사업아파트 신축공사 | D38: =IF(VLOOKUP($B38,'1. 현장별 인원현황'!$C:$J,3,0)=0,"",VLOOKUP($B38,'1. 현장별 인원현황'!$C:$J,3,0)) -> 배기정 | E38: =IF(VLOOKUP($B38,'1. 현장별 인원현황'!$C:$J,4,0)=0,"",VLOOKUP($B38,'1. 현장별 인원현황'!$C:$J,4,0)) -> 32세 | F38: =IF(VLOOKUP($B38,'1. 현장별 인원현황'!$C:$J,7,0)=0,"",VLOOKUP($B38,'1. 현장별 인원현황'!$C:$J,7,0)) -> 기능공 | G38: =IF(VLOOKUP($B38,'1. 현장별 인원현황'!$C:$J,8,0)=0,"",VLOOKUP($B38,'1. 현장별 인원현황'!$C:$J,8,0)) -> 조공 | J38: O | M38: O | Q38: O | V38: O | Y38: O | AC38: O | AG38: O | AK38: O | AO38: O | AR38: =SUMPRODUCT($H$5:$AQ$5,AV38:CE38) -> 72 | AS38: =IF(AR38>85,"S",IF(AR38>70,"A",IF(AR38>50,"B",IF(AR38>0,"C","")))) -> A | AV38: =IF(H38>0,1,0) -> 0 | AW38: =IF(I38>0,1,0) -> 0 | AX38: =IF(J38>0,1,0) -> 1 | AY38: =IF(K38>0,1,0) -> 0 | AZ38: =IF(L38>0,1,0) -> 0 | BA38: =IF(M38>0,1,0) -> 1 | BB38: =IF(N38>0,1,0) -> 0 | BC38: =IF(O38>0,1,0) -> 0 | ... CE38: =IF(AQ38>0,1,0) -> 0
